<?xml version="1.0" encoding="utf-8"?>
<!-- This URDF was automatically created by SolidWorks to URDF Exporter! Originally created by Stephen Brawner (brawner@gmail.com) 
     Commit Version: 1.6.0-4-g7f85cfe  Build Version: 1.6.7995.38578
     For more information, please see http://wiki.ros.org/sw_urdf_exporter -->
<robot
  name="rewr1_1">
  <mujoco>
    <compiler meshdir="../../meshes/rewr1_1" discardvisual="false" />
  </mujoco>
  <link
    name="base_link">
    <inertial>
      <origin
        xyz="-0.014012 0.00040987 0.030551"
        rpy="0 0 0" />
      <mass
        value="42.709" />
      <inertia
        ixx="0.74568"
        ixy="-0.012746"
        ixz="0.03077048"
        iyy="0.9261"
        iyz="-0.0023537"
        izz="1.528" />
    </inertial>
    <visual>
      <origin
        xyz="0 0 0"
        rpy="0 0 0" />
      <geometry>
        <mesh
          filename="../../meshes/rewr1_1/base_link.STL" />
      </geometry>
      <material
        name="">
        <color
          rgba="0.79216 0.81961 0.93333 1" />
      </material>
    </visual>
    <collision>
      <origin
        xyz="0 0 0"
        rpy="0 0 0" />
      <geometry>
        <mesh
          filename="../../meshes/rewr1_1/base_link.STL" />
      </geometry>
    </collision>
  </link>
  <link
    name="ankle_link">
    <inertial>
      <origin
        xyz="-0.00047994 0.0023115 0.21619"
        rpy="0 0 0" />
      <mass
        value="7.3164" />
      <inertia
        ixx="0.29033"
        ixy="-1.703E-05"
        ixz="-0.0011346"
        iyy="0.28932"
        iyz="0.00055054"
        izz="0.01489" />
    </inertial>
    <visual>
      <origin
        xyz="0 0 0"
        rpy="0 0 0" />
      <geometry>
        <mesh
          filename="../../meshes/rewr1_1/ankle_link.STL" />
      </geometry>
      <material
        name="">
        <color
          rgba="0.69804 0.69804 0.69804 1" />
      </material>
    </visual>
    <collision>
      <origin
        xyz="0 0 0"
        rpy="0 0 0" />
      <geometry>
        <mesh
          filename="../../meshes/rewr1_1/ankle_link.STL" />
      </geometry>
    </collision>
  </link>
  <joint
    name="ankle_joint"
    type="revolute">
    <origin
      xyz="-0.085 0 0.155"
      rpy="0 0 0" />
    <parent
      link="base_link" />
    <child
      link="ankle_link" />
    <axis
      xyz="0 1 0" />
    <limit
      lower="0"
      upper="1.61"
      effort="240"
      velocity="4.15" />
    <dynamics
      damping="0.0"
      friction="0.0" />
  </joint>
  <link
    name="knee_link">
    <inertial>
      <origin
        xyz="0.0026878 0.00070792 0.17911"
        rpy="0 0 0" />
      <mass
        value="2.474" />
      <inertia
        ixx="0.040172"
        ixy="-0.00010309"
        ixz="2.653E-05"
        iyy="0.033469"
        iyz="0.0002539"
        izz="0.011865" />
    </inertial>
    <visual>
      <origin
        xyz="0 0 0"
        rpy="0 0 0" />
      <geometry>
        <mesh
          filename="../../meshes/rewr1_1/knee_link.STL" />
      </geometry>
      <material
        name="">
        <color
          rgba="0.69804 0.69804 0.69804 1" />
      </material>
    </visual>
    <collision>
      <origin
        xyz="0 0 0"
        rpy="0 0 0" />
      <geometry>
        <mesh
          filename="../../meshes/rewr1_1/knee_link.STL" />
      </geometry>
    </collision>
  </link>
  <joint
    name="knee_joint"
    type="revolute">
    <origin
      xyz="0 0 0.43"
      rpy="0 0 0" />
    <parent
      link="ankle_link" />
    <child
      link="knee_link" />
    <axis
      xyz="0 1 0" />
    <limit
      lower="-2.53"
      upper="0.52"
      effort="240"
      velocity="4.15" />
    <dynamics
      damping="0.0"
      friction="0.0" />
  </joint>
  <link
    name="hip_link">
    <inertial>
      <origin
        xyz="-0.00103764 0.00304417 0.00598232"
        rpy="0 0 0" />
      <mass
        value="3.02066694" />
      <inertia
        ixx="0.00752688"
        ixy="2.878E-05"
        ixz="6.943E-05"
        iyy="0.00749045"
        iyz="-0.00018464"
        izz="0.00709671" />
    </inertial>
    <visual>
      <origin
        xyz="0 0 0"
        rpy="0 0 0" />
      <geometry>
        <mesh
          filename="../../meshes/rewr1_1/hip_link.STL" />
      </geometry>
      <material
        name="">
        <color
          rgba="1 1 1 1" />
      </material>
    </visual>
    <collision>
      <origin
        xyz="0 0 0"
        rpy="0 0 0" />
      <geometry>
        <mesh
          filename="../../meshes/rewr1_1/hip_link.STL" />
      </geometry>
    </collision>
  </link>
  <joint
    name="hip_joint"
    type="revolute">
    <origin
      xyz="0 0 0.34"
      rpy="0 0 0" />
    <parent
      link="knee_link" />
    <child
      link="hip_link" />
    <axis
      xyz="0 1 0" />
    <limit
      lower="-0.52"
      upper="1.57"
      effort="240"
      velocity="4.15" />
    <dynamics
      damping="0.0"
      friction="0.0" />
  </joint>
  <link
    name="waist_yaw_link">
    <inertial>
      <origin
        xyz="-0.0046601 0.00016974 0.0042368"
        rpy="0 0 0" />
      <mass
        value="3.9422" />
      <inertia
        ixx="0.049848"
        ixy="-3.37E-06"
        ixz="0.0040885"
        iyy="0.047071"
        iyz="-2.801E-05"
        izz="0.0093816" />
    </inertial>
    <visual>
      <origin
        xyz="0 0 0"
        rpy="0 0 0" />
      <geometry>
        <mesh
          filename="../../meshes/rewr1_1/waist_yaw_link.STL" />
      </geometry>
      <material
        name="">
        <color
          rgba="0.86667 0.86667 0.86667 1" />
      </material>
    </visual>
    <collision>
      <origin
        xyz="0 0 0"
        rpy="0 0 0" />
      <geometry>
        <mesh
          filename="../../meshes/rewr1_1/waist_yaw_link.STL" />
      </geometry>
    </collision>
  </link>
  <joint
    name="waist_yaw_joint"
    type="revolute">
    <origin
      xyz="0 0 0.225"
      rpy="0 0 0" />
    <parent
      link="hip_link" />
    <child
      link="waist_yaw_link" />
    <axis
      xyz="0 0 1" />
    <limit
      lower="-1.57"
      upper="1.57"
      effort="95"
      velocity="4.19" />
    <dynamics
      damping="0.0"
      friction="0.0" />
  </joint>
  <link
    name="neck_yaw_link">
    <inertial>
      <origin
        xyz="0.01307119 -0.00282636 0.05747981"
        rpy="0 0 0" />
      <mass
        value="0.32337325" />
      <inertia
        ixx="0.00025001"
        ixy="1.71E-06"
        ixz="-2.819E-05"
        iyy="0.00019688"
        iyz="5.34E-06"
        izz="0.00015654" />
    </inertial>
    <visual>
      <origin
        xyz="0 0 0"
        rpy="0 0 0" />
      <geometry>
        <mesh
          filename="../../meshes/rewr1_1/neck_yaw_link.STL" />
      </geometry>
      <material
        name="">
        <color
          rgba="0.42745 0.45882 0.49412 1" />
      </material>
    </visual>
    <collision>
      <origin
        xyz="0 0 0"
        rpy="0 0 0" />
      <geometry>
        <mesh
          filename="../../meshes/rewr1_1/neck_yaw_link.STL" />
      </geometry>
    </collision>
  </link>
  <joint
    name="neck_yaw_joint"
    type="revolute">
    <origin
      xyz="-0.042 0 0.217"
      rpy="0 0 0" />
    <parent
      link="waist_yaw_link" />
    <child
      link="neck_yaw_link" />
    <axis
      xyz="0 0 1" />
    <limit
      lower="-0.79"
      upper="0.79"
      effort="7.5"
      velocity="6.28" />
    <dynamics
      damping="0.0"
      friction="0.0" />
  </joint>
  <link
    name="neck_pitch_link">
    <inertial>
      <origin
        xyz="0.01342226 -9.647E-05 0.06023734"
        rpy="0 0 0" />
      <mass
        value="0.33670814" />
      <inertia
        ixx="0.00111361"
        ixy="8.1E-07"
        ixz="0.00017683"
        iyy="0.00148315"
        iyz="4.3E-07"
        izz="0.001444" />
    </inertial>
    <visual>
      <origin
        xyz="0 0 0"
        rpy="0 0 0" />
      <geometry>
        <mesh
          filename="../../meshes/rewr1_1/neck_pitch_link.STL" />
      </geometry>
      <material
        name="">
        <color
          rgba="0.79216 0.81961 0.93333 1" />
      </material>
    </visual>
    <collision>
      <origin
        xyz="0 0 0"
        rpy="0 0 0" />
      <geometry>
        <mesh
          filename="../../meshes/rewr1_1/neck_pitch_link.STL" />
      </geometry>
    </collision>
  </link>
  <joint
    name="neck_pitch_joint"
    type="revolute">
    <origin
      xyz="0.015 0 0.0625"
      rpy="0 0 0" />
    <parent
      link="neck_yaw_link" />
    <child
      link="neck_pitch_link" />
    <axis
      xyz="0 1 0" />
    <limit
      lower="-0.26"
      upper="0.7"
      effort="7.5"
      velocity="6.28" />
    <dynamics
      damping="0.0"
      friction="0.0" />
  </joint>
  <link
    name="head_rs_link">
    <inertial>
      <origin
        xyz="0.0054453 0.00017197 -2.1745E-05"
        rpy="0 0 0" />
      <mass
        value="0.01069" />
      <inertia
        ixx="9.1126E-06"
        ixy="-1.617E-08"
        ixz="4.1847E-09"
        iyy="9.2791E-07"
        iyz="1.7295E-08"
        izz="9.3011E-06" />
    </inertial>
    <visual>
      <origin
        xyz="0 0 0"
        rpy="0 0 0" />
      <geometry>
        <mesh
          filename="../../meshes/rewr1_1/head_rs_link.STL" />
      </geometry>
      <material
        name="">
        <color
          rgba="0.79216 0.81961 0.93333 1" />
      </material>
    </visual>
    <collision>
      <origin
        xyz="0 0 0"
        rpy="0 0 0" />
      <geometry>
        <mesh
          filename="../../meshes/rewr1_1/head_rs_link.STL" />
      </geometry>
    </collision>
  </link>
  <joint
    name="head_rs_joint"
    type="fixed">
    <origin
      xyz="0.059257 0 0.065296"
      rpy="0 0.14655 0" />
    <parent
      link="neck_pitch_link" />
    <child
      link="head_rs_link" />
    <axis
      xyz="0 0 0" />
  </joint>
  <link
    name="left_arm_base_link">
    <inertial>
      <origin
        xyz="0.0003073 0.076315 2.644E-05"
        rpy="0 0 0" />
      <mass
        value="0.99002" />
      <inertia
        ixx="0.00090157"
        ixy="-3.17E-06"
        ixz="2.16E-06"
        iyy="0.00079998"
        iyz="1.81E-06"
        izz="0.00089799" />
    </inertial>
    <visual>
      <origin
        xyz="0 0 0"
        rpy="0 0 0" />
      <geometry>
        <mesh
          filename="../../meshes/rewr1_1/left_arm_base_link.STL" />
      </geometry>
      <material
        name="">
        <color
          rgba="0.86667 0.86667 0.8902 1" />
      </material>
    </visual>
    <collision>
      <origin
        xyz="0 0 0"
        rpy="0 0 0" />
      <geometry>
        <mesh
          filename="../../meshes/rewr1_1/left_arm_base_link.STL" />
      </geometry>
    </collision>
  </link>
  <joint
    name="left_arm_base_joint"
    type="fixed">
    <origin
      xyz="-0.0385 0 0.128"
      rpy="0 0 0" />
    <parent
      link="waist_yaw_link" />
    <child
      link="left_arm_base_link" />
    <axis
      xyz="0 0 0" />
  </joint>
  <link
    name="left_shoulder_pitch_link">
    <inertial>
      <origin
        xyz="-0.0050043 0.06894435 -0.0013023"
        rpy="0 0 0" />
      <mass
        value="0.64146" />
      <inertia
        ixx="0.00051593"
        ixy="1.04E-05"
        ixz="-8.15E-06"
        iyy="0.00044936"
        iyz="3.92E-05"
        izz="0.00046479" />
    </inertial>
    <visual>
      <origin
        xyz="0 0 0"
        rpy="0 0 0" />
      <geometry>
        <mesh
          filename="../../meshes/rewr1_1/left_shoulder_pitch_link.STL" />
      </geometry>
      <material
        name="">
        <color
          rgba="0.86667 0.86667 0.8902 1" />
      </material>
    </visual>
    <collision>
      <origin
        xyz="0 0 0"
        rpy="0 0 0" />
      <geometry>
        <mesh
          filename="../../meshes/rewr1_1/left_shoulder_pitch_link.STL" />
      </geometry>
    </collision>
  </link>
  <joint
    name="left_shoulder_pitch_joint"
    type="revolute">
    <origin
      xyz="0 0.09 0"
      rpy="0 0 0" />
    <parent
      link="left_arm_base_link" />
    <child
      link="left_shoulder_pitch_link" />
    <axis
      xyz="0 1 0" />
    <limit
      lower="-2.79"
      upper="2.79"
      effort="95"
      velocity="4.19" />
    <dynamics
      damping="0.0"
      friction="0.0" />
  </joint>
  <link
    name="left_shoulder_roll_link">
    <inertial>
      <origin
        xyz="-0.00211885 -0.00158378 -0.03534224"
        rpy="0 0 0" />
      <mass
        value="0.17226343" />
      <inertia
        ixx="0.00020011"
        ixy="-0.00000061"
        ixz="-1.223E-05"
        iyy="0.0002504"
        iyz="0.00000224"
        izz="0.00018541" />
    </inertial>
    <visual>
      <origin
        xyz="0 0 0"
        rpy="0 0 0" />
      <geometry>
        <mesh
          filename="../../meshes/rewr1_1/left_shoulder_roll_link.STL" />
      </geometry>
      <material
        name="">
        <color
          rgba="0.86667 0.86667 0.8902 1" />
      </material>
    </visual>
    <collision>
      <origin
        xyz="0 0 0"
        rpy="0 0 0" />
      <geometry>
        <mesh
          filename="../../meshes/rewr1_1/left_shoulder_roll_link.STL" />
      </geometry>
    </collision>
  </link>
  <joint
    name="left_shoulder_roll_joint"
    type="revolute">
    <origin
      xyz="0 0.0725 -0.004"
      rpy="0 0 0" />
    <parent
      link="left_shoulder_pitch_link" />
    <child
      link="left_shoulder_roll_link" />
    <axis
      xyz="1 0 0" />
    <limit
      lower="-0.24"
      upper="1.83"
      effort="32"
      velocity="4.19" />
    <dynamics
      damping="0.0"
      friction="0.0" />
  </joint>
  <link
    name="left_arm_yaw_link">
    <inertial>
      <origin
        xyz="-0.00113597 -0.0016386 -0.11233"
        rpy="0 0 0" />
      <mass
        value="1.2101" />
      <inertia
        ixx="0.0085327"
        ixy="-6E-08"
        ixz="-8.854E-05"
        iyy="0.0084923"
        iyz="-0.00016489"
        izz="0.00077091" />
    </inertial>
    <visual>
      <origin
        xyz="0 0 0"
        rpy="0 0 0" />
      <geometry>
        <mesh
          filename="../../meshes/rewr1_1/left_arm_yaw_link.STL" />
      </geometry>
      <material
        name="">
        <color
          rgba="0.86667 0.86667 0.8902 1" />
      </material>
    </visual>
    <collision>
      <origin
        xyz="0 0 0"
        rpy="0 0 0" />
      <geometry>
        <mesh
          filename="../../meshes/rewr1_1/left_arm_yaw_link.STL" />
      </geometry>
    </collision>
  </link>
  <joint
    name="left_arm_yaw_joint"
    type="revolute">
    <origin
      xyz="0 0.002 -0.0635"
      rpy="0 0 0" />
    <parent
      link="left_shoulder_roll_link" />
    <child
      link="left_arm_yaw_link" />
    <axis
      xyz="0 0 1" />
    <limit
      lower="-2.62"
      upper="2.62"
      effort="32"
      velocity="4.19" />
    <dynamics
      damping="0.0"
      friction="0.0" />
  </joint>
  <link
    name="left_elbow_pitch_link">
    <inertial>
      <origin
        xyz="-0.00880355 -0.00323495 -0.0334867"
        rpy="0 0 0" />
      <mass
        value="0.18069981" />
      <inertia
        ixx="0.00027414"
        ixy="7.37E-06"
        ixz="-1.252E-05"
        iyy="0.00020754"
        iyz="3.39E-05"
        izz="0.00018765" />
    </inertial>
    <visual>
      <origin
        xyz="0 0 0"
        rpy="0 0 0" />
      <geometry>
        <mesh
          filename="../../meshes/rewr1_1/left_elbow_pitch_link.STL" />
      </geometry>
      <material
        name="">
        <color
          rgba="0.86667 0.86667 0.8902 1" />
      </material>
    </visual>
    <collision>
      <origin
        xyz="0 0 0"
        rpy="0 0 0" />
      <geometry>
        <mesh
          filename="../../meshes/rewr1_1/left_elbow_pitch_link.STL" />
      </geometry>
    </collision>
  </link>
  <joint
    name="left_elbow_pitch_joint"
    type="revolute">
    <origin
      xyz="-0.001 0 -0.1965"
      rpy="0 0 0" />
    <parent
      link="left_arm_yaw_link" />
    <child
      link="left_elbow_pitch_link" />
    <axis
      xyz="0 1 0" />
    <limit
      lower="-2.27"
      upper="0.09"
      effort="32"
      velocity="4.19" />
    <dynamics
      damping="0.0"
      friction="0.0" />
  </joint>
  <link
    name="left_elbow_yaw_link">
    <inertial>
      <origin
        xyz="-0.00025009 -0.000948427 -0.06098779"
        rpy="0 0 0" />
      <mass
        value="0.6617336" />
      <inertia
        ixx=" 0.00129245"
        ixy="-4.87E-06"
        ixz="-1.904E-05"
        iyy="0.00124108"
        iyz="-3.408E-05"
        izz="0.00034324" />
    </inertial>
    <visual>
      <origin
        xyz="0 0 0"
        rpy="0 0 0" />
      <geometry>
        <mesh
          filename="../../meshes/rewr1_1/left_elbow_yaw_link.STL" />
      </geometry>
      <material
        name="">
        <color
          rgba="0.86667 0.86667 0.8902 1" />
      </material>
    </visual>
    <collision>
      <origin
        xyz="0 0 0"
        rpy="0 0 0" />
      <geometry>
        <mesh
          filename="../../meshes/rewr1_1/left_elbow_yaw_link.STL" />
      </geometry>
    </collision>
  </link>
  <joint
    name="left_elbow_yaw_joint"
    type="revolute">
    <origin
      xyz="-0.0055 0 -0.0723"
      rpy="0 0 0" />
    <parent
      link="left_elbow_pitch_link" />
    <child
      link="left_elbow_yaw_link" />
    <axis
      xyz="0 0 1" />
    <limit
      lower="-2.62"
      upper="2.62"
      effort="7.5"
      velocity="6.28" />
    <dynamics
      damping="0.0"
      friction="0.0" />
  </joint>
  <link
    name="left_wrist_pitch_link">
    <inertial>
      <origin
        xyz="0.0034386 -0.00062599 -5.68E-06"
        rpy="0 0 0" />
      <mass
        value="0.27757" />
      <inertia
        ixx="9.253E-05"
        ixy="-1.51E-06"
        ixz="-1.14E-06"
        iyy="9.898E-05"
        iyz="2.8E-07"
        izz="0.00010201" />
    </inertial>
    <visual>
      <origin
        xyz="0 0 0"
        rpy="0 0 0" />
      <geometry>
        <mesh
          filename="../../meshes/rewr1_1/left_wrist_pitch_link.STL" />
      </geometry>
      <material
        name="">
        <color
          rgba="1 1 1 1" />
      </material>
    </visual>
    <collision>
      <origin
        xyz="0 0 0"
        rpy="0 0 0" />
      <geometry>
        <mesh
          filename="../../meshes/rewr1_1/left_wrist_pitch_link.STL" />
      </geometry>
    </collision>
  </link>
  <joint
    name="left_wrist_pitch_joint"
    type="revolute">
    <origin
      xyz="0 0 -0.1492"
      rpy="0 0 0" />
    <parent
      link="left_elbow_yaw_link" />
    <child
      link="left_wrist_pitch_link" />
    <axis
      xyz="0 1 0" />
    <limit
      lower="-1.05"
      upper="1.05"
      effort="7.5"
      velocity="6.28" />
    <dynamics
      damping="0.0"
      friction="0.0" />
  </joint>
  <link
    name="left_wrist_roll_link">
    <inertial>
      <origin
        xyz="0.01134998 0 -0.0250322"
        rpy="0 0 0" />
      <mass
        value="0.04286878" />
      <inertia
        ixx="2.059E-05"
        ixy="0"
        ixz="-8.09E-06"
        iyy="2.546E-05"
        iyz="0"
        izz="1.718E-05" />
    </inertial>
    <visual>
      <origin
        xyz="0 0 0"
        rpy="0 0 0" />
      <geometry>
        <mesh
          filename="../../meshes/rewr1_1/left_wrist_roll_link.STL" />
      </geometry>
      <material
        name="">
        <color
          rgba="0.8902 0.8902 0.91373 1" />
      </material>
    </visual>
    <collision>
      <origin
        xyz="0 0 0"
        rpy="0 0 0" />
      <geometry>
        <mesh
          filename="../../meshes/rewr1_1/left_wrist_roll_link.STL" />
      </geometry>
    </collision>
  </link>
  <joint
    name="left_wrist_roll_joint"
    type="revolute">
    <origin
      xyz="0 0 0"
      rpy="0 0 0" />
    <parent
      link="left_wrist_pitch_link" />
    <child
      link="left_wrist_roll_link" />
    <axis
      xyz="1 0 0" />
    <limit
      lower="-1.05"
      upper="1.05"
      effort="7.5"
      velocity="6.28" />
    <dynamics
      damping="0.0"
      friction="0.0" />
  </joint>
  <link
    name="left_arm_flange_link">
    <inertial>
      <origin
        xyz="-1.8041E-15 1.471E-15 0.064"
        rpy="0 0 0" />
      <mass
        value="1E-06" />
      <inertia
        ixx="1.6667E-13"
        ixy="3.8622E-30"
        ixz="3.3658E-30"
        iyy="1.6667E-13"
        iyz="-1.333E-45"
        izz="1.6667E-13" />
    </inertial>
    <visual>
      <origin
        xyz="0 0 0"
        rpy="0 0 0" />
      <geometry>
        <mesh
          filename="../../meshes/rewr1_1/left_arm_flange_link.STL" />
      </geometry>
      <material
        name="">
        <color
          rgba="0.79216 0.81961 0.93333 1" />
      </material>
    </visual>
    <collision>
      <origin
        xyz="0 0 0"
        rpy="0 0 0" />
      <geometry>
        <mesh
          filename="../../meshes/rewr1_1/left_arm_flange_link.STL" />
      </geometry>
    </collision>
  </link>
  <joint
    name="left_arm_flange_joint"
    type="fixed">
    <origin
      xyz="0 0 -0.039"
      rpy="-3.1416 0 0" />
    <parent
      link="left_wrist_roll_link" />
    <child
      link="left_arm_flange_link" />
    <axis
      xyz="0 0 0" />
  </joint>
  <link
    name="left_hand_ee_link">
    <inertial>
      <origin
        xyz="-1.8319E-15 1.4988E-15 -3.3307E-16"
        rpy="0 0 0" />
      <mass
        value="1E-06" />
      <inertia
        ixx="1.6667E-13"
        ixy="3.8622E-30"
        ixz="3.3658E-30"
        iyy="1.6667E-13"
        iyz="2.6187E-40"
        izz="1.6667E-13" />
    </inertial>
    <visual>
      <origin
        xyz="0 0 0"
        rpy="0 0 0" />
      <geometry>
        <mesh
          filename="../../meshes/rewr1_1/left_hand_ee_link.STL" />
      </geometry>
      <material
        name="">
        <color
          rgba="0.79216 0.81961 0.93333 1" />
      </material>
    </visual>
    <collision>
      <origin
        xyz="0 0 0"
        rpy="0 0 0" />
      <geometry>
        <mesh
          filename="../../meshes/rewr1_1/left_hand_ee_link.STL" />
      </geometry>
    </collision>
  </link>
  <joint
    name="left_hand_ee_joint"
    type="fixed">
    <origin
      xyz="0 0 -0.103"
      rpy="3.1416 0 0" />
    <parent
      link="left_wrist_roll_link" />
    <child
      link="left_hand_ee_link" />
    <axis
      xyz="0 0 0" />
  </joint>
  <link
    name="right_arm_base_link">
    <inertial>
      <origin
        xyz="0.0003073 -0.076315 -2.644E-05"
        rpy="0 0 0" />
      <mass
        value="0.99002" />
      <inertia
        ixx="0.00090157"
        ixy="3.17E-06"
        ixz="-2.16E-06"
        iyy="0.00079998"
        iyz="1.81E-06"
        izz="0.00089799" />
    </inertial>
    <visual>
      <origin
        xyz="0 0 0"
        rpy="0 0 0" />
      <geometry>
        <mesh
          filename="../../meshes/rewr1_1/right_arm_base_link.STL" />
      </geometry>
      <material
        name="">
        <color
          rgba="0.86667 0.86667 0.8902 1" />
      </material>
    </visual>
    <collision>
      <origin
        xyz="0 0 0"
        rpy="0 0 0" />
      <geometry>
        <mesh
          filename="../../meshes/rewr1_1/right_arm_base_link.STL" />
      </geometry>
    </collision>
  </link>
  <joint
    name="right_arm_base_joint"
    type="fixed">
    <origin
      xyz="-0.0385 0 0.128"
      rpy="0 0 0" />
    <parent
      link="waist_yaw_link" />
    <child
      link="right_arm_base_link" />
    <axis
      xyz="0 0 0" />
  </joint>
  <link
    name="right_shoulder_pitch_link">
    <inertial>
      <origin
        xyz="-0.0050037 -0.068922 -0.0013416"
        rpy="0 0 0" />
      <mass
        value="0.64146" />
      <inertia
        ixx="0.00051596"
        ixy="-1.076E-05"
        ixz="-7.55E-06"
        iyy="0.00044914"
        iyz="-3.905E-05"
        izz="0.00046504" />
    </inertial>
    <visual>
      <origin
        xyz="0 0 0"
        rpy="0 0 0" />
      <geometry>
        <mesh
          filename="../../meshes/rewr1_1/right_shoulder_pitch_link.STL" />
      </geometry>
      <material
        name="">
        <color
          rgba="0.79216 0.81961 0.93333 1" />
      </material>
    </visual>
    <collision>
      <origin
        xyz="0 0 0"
        rpy="0 0 0" />
      <geometry>
        <mesh
          filename="../../meshes/rewr1_1/right_shoulder_pitch_link.STL" />
      </geometry>
    </collision>
  </link>
  <joint
    name="right_shoulder_pitch_joint"
    type="revolute">
    <origin
      xyz="0 -0.09 0"
      rpy="0 0 0" />
    <parent
      link="right_arm_base_link" />
    <child
      link="right_shoulder_pitch_link" />
    <axis
      xyz="0 1 0" />
    <limit
      lower="-2.79"
      upper="2.79"
      effort="95"
      velocity="4.19" />
    <dynamics
      damping="0.0"
      friction="0.0" />
  </joint>
  <link
    name="right_shoulder_roll_link">
    <inertial>
      <origin
        xyz="-0.0021219 -0.0015843 -0.035346"
        rpy="0 0 0" />
      <mass
        value="0.17223" />
      <inertia
        ixx="0.00020007"
        ixy="6.1E-07"
        ixz="1.224E-05"
        iyy="0.00025035"
        iyz="-2.28E-06"
        izz="0.00018537" />
    </inertial>
    <visual>
      <origin
        xyz="0 0 0"
        rpy="0 0 0" />
      <geometry>
        <mesh
          filename="../../meshes/rewr1_1/right_shoulder_roll_link.STL" />
      </geometry>
      <material
        name="">
        <color
          rgba="0.79216 0.81961 0.93333 1" />
      </material>
    </visual>
    <collision>
      <origin
        xyz="0 0 0"
        rpy="0 0 0" />
      <geometry>
        <mesh
          filename="../../meshes/rewr1_1/right_shoulder_roll_link.STL" />
      </geometry>
    </collision>
  </link>
  <joint
    name="right_shoulder_roll_joint"
    type="revolute">
    <origin
      xyz="0 -0.0725 -0.004"
      rpy="0 0 0" />
    <parent
      link="right_shoulder_pitch_link" />
    <child
      link="right_shoulder_roll_link" />
    <axis
      xyz="1 0 0" />
    <limit
      lower="-1.83"
      upper="0.24"
      effort="32"
      velocity="4.19" />
    <dynamics
      damping="0.0"
      friction="0.0" />
  </joint>
  <link
    name="right_arm_yaw_link">
    <inertial>
      <origin
        xyz="-0.0010977 0.0016198 -0.11231"
        rpy="0 0 0" />
      <mass
        value="1.2099" />
      <inertia
        ixx="0.0085309"
        ixy="5.5E-07"
        ixz="-8.727E-05"
        iyy="0.0084894"
        iyz="0.00016693"
        izz="0.00077047" />
    </inertial>
    <visual>
      <origin
        xyz="0 0 0"
        rpy="0 0 0" />
      <geometry>
        <mesh
          filename="../../meshes/rewr1_1/right_arm_yaw_link.STL" />
      </geometry>
      <material
        name="">
        <color
          rgba="0.79216 0.81961 0.93333 1" />
      </material>
    </visual>
    <collision>
      <origin
        xyz="0 0 0"
        rpy="0 0 0" />
      <geometry>
        <mesh
          filename="../../meshes/rewr1_1/right_arm_yaw_link.STL" />
      </geometry>
    </collision>
  </link>
  <joint
    name="right_arm_yaw_joint"
    type="revolute">
    <origin
      xyz="0 -0.002 -0.0635"
      rpy="0 0 0" />
    <parent
      link="right_shoulder_roll_link" />
    <child
      link="right_arm_yaw_link" />
    <axis
      xyz="0 0 1" />
    <limit
      lower="-2.62"
      upper="2.62"
      effort="32"
      velocity="4.19" />
    <dynamics
      damping="0.0"
      friction="0.0" />
  </joint>
  <link
    name="right_elbow_pitch_link">
    <inertial>
      <origin
        xyz="-0.00880547 0.0032133 -0.03349237"
        rpy="0 0 0" />
      <mass
        value="0.18066843" />
      <inertia
        ixx="0.00027375"
        ixy="-7.35E-06"
        ixz="-1.25E-05"
        iyy="0.00020747"
        iyz="-3.376E-05"
        izz="0.0001873" />
    </inertial>
    <visual>
      <origin
        xyz="0 0 0"
        rpy="0 0 0" />
      <geometry>
        <mesh
          filename="../../meshes/rewr1_1/right_elbow_pitch_link.STL" />
      </geometry>
      <material
        name="">
        <color
          rgba="0.79216 0.81961 0.93333 1" />
      </material>
    </visual>
    <collision>
      <origin
        xyz="0 0 0"
        rpy="0 0 0" />
      <geometry>
        <mesh
          filename="../../meshes/rewr1_1/right_elbow_pitch_link.STL" />
      </geometry>
    </collision>
  </link>
  <joint
    name="right_elbow_pitch_joint"
    type="revolute">
    <origin
      xyz="-0.001 0 -0.1965"
      rpy="0 0 0" />
    <parent
      link="right_arm_yaw_link" />
    <child
      link="right_elbow_pitch_link" />
    <axis
      xyz="0 1 0" />
    <limit
      lower="-2.27"
      upper="0.09"
      effort="32"
      velocity="4.19" />
    <dynamics
      damping="0.0"
      friction="0.0" />
  </joint>
  <link
    name="right_elbow_yaw_link">
    <inertial>
      <origin
        xyz="-0.00012227 0.0010776 -0.061048"
        rpy="0 0 0" />
      <mass
        value="0.66172" />
      <inertia
        ixx="0.0012945"
        ixy="6.53E-06"
        ixz="-1.644E-05"
        iyy="0.0012433"
        iyz="3.172E-05"
        izz="0.00034303" />
    </inertial>
    <visual>
      <origin
        xyz="0 0 0"
        rpy="0 0 0" />
      <geometry>
        <mesh
          filename="../../meshes/rewr1_1/right_elbow_yaw_link.STL" />
      </geometry>
      <material
        name="">
        <color
          rgba="0.79216 0.81961 0.93333 1" />
      </material>
    </visual>
    <collision>
      <origin
        xyz="0 0 0"
        rpy="0 0 0" />
      <geometry>
        <mesh
          filename="../../meshes/rewr1_1/right_elbow_yaw_link.STL" />
      </geometry>
    </collision>
  </link>
  <joint
    name="right_elbow_yaw_joint"
    type="revolute">
    <origin
      xyz="-0.0055 0 -0.0723"
      rpy="0 0 0" />
    <parent
      link="right_elbow_pitch_link" />
    <child
      link="right_elbow_yaw_link" />
    <axis
      xyz="0 0 1" />
    <limit
      lower="-2.62"
      upper="2.62"
      effort="7.5"
      velocity="6.28" />
    <dynamics
      damping="0.0"
      friction="0.0" />
  </joint>
  <link
    name="right_wrist_pitch_link">
    <inertial>
      <origin
        xyz="0.0034392 0.00095252 0.00011331"
        rpy="0 0 0" />
      <mass
        value="0.27757" />
      <inertia
        ixx="9.239E-05"
        ixy="3.32E-06"
        ixz="-4.7E-07"
        iyy="9.9E-05"
        iyz="-2.8E-07"
        izz="0.00010183" />
    </inertial>
    <visual>
      <origin
        xyz="0 0 0"
        rpy="0 0 0" />
      <geometry>
        <mesh
          filename="../../meshes/rewr1_1/right_wrist_pitch_link.STL" />
      </geometry>
      <material
        name="">
        <color
          rgba="0.79216 0.81961 0.93333 1" />
      </material>
    </visual>
    <collision>
      <origin
        xyz="0 0 0"
        rpy="0 0 0" />
      <geometry>
        <mesh
          filename="../../meshes/rewr1_1/right_wrist_pitch_link.STL" />
      </geometry>
    </collision>
  </link>
  <joint
    name="right_wrist_pitch_joint"
    type="revolute">
    <origin
      xyz="0 0 -0.1492"
      rpy="0 0 0" />
    <parent
      link="right_elbow_yaw_link" />
    <child
      link="right_wrist_pitch_link" />
    <axis
      xyz="0 1 0" />
    <limit
      lower="-1.05"
      upper="1.05"
      effort="7.5"
      velocity="6.28" />
    <dynamics
      damping="0.0"
      friction="0.0" />
  </joint>
  <link
    name="right_wrist_roll_link">
    <inertial>
      <origin
        xyz="0.01135 0 -0.025032"
        rpy="0 0 0" />
      <mass
        value="0.042869" />
      <inertia
        ixx="2.059E-05"
        ixy="0"
        ixz="0"
        iyy="2.546E-05"
        iyz="0"
        izz="1.718E-05" />
    </inertial>
    <visual>
      <origin
        xyz="0 0 0"
        rpy="0 0 0" />
      <geometry>
        <mesh
          filename="../../meshes/rewr1_1/right_wrist_roll_link.STL" />
      </geometry>
      <material
        name="">
        <color
          rgba="0.8902 0.8902 0.91373 1" />
      </material>
    </visual>
    <collision>
      <origin
        xyz="0 0 0"
        rpy="0 0 0" />
      <geometry>
        <mesh
          filename="../../meshes/rewr1_1/right_wrist_roll_link.STL" />
      </geometry>
    </collision>
  </link>
  <joint
    name="right_wrist_roll_joint"
    type="revolute">
    <origin
      xyz="0 0 0"
      rpy="0 0 0" />
    <parent
      link="right_wrist_pitch_link" />
    <child
      link="right_wrist_roll_link" />
    <axis
      xyz="1 0 0" />
    <limit
      lower="-1.05"
      upper="1.05"
      effort="7.5"
      velocity="6.28" />
    <dynamics
      damping="0.0"
      friction="0.0" />
  </joint>
  <link
    name="right_arm_flange_link">
    <inertial>
      <origin
        xyz="-1.27675647831893E-15 -6.10622663543836E-16 0.0640000000000044"
        rpy="0 0 0" />
      <mass
        value="9.99999999999892E-07" />
      <inertia
        ixx="1.6666666666663E-13"
        ixy="3.86220795429293E-30"
        ixz="3.36580652894299E-30"
        iyy="1.6666666666663E-13"
        iyz="9.10477526878529E-46"
        izz="1.66666666666649E-13" />
    </inertial>
    <visual>
      <origin
        xyz="0 0 0"
        rpy="0 0 0" />
      <geometry>
        <mesh
          filename="../../meshes/rewr1_1/right_arm_flange_link.STL" />
      </geometry>
      <material
        name="">
        <color
          rgba="0.792156862745098 0.819607843137255 0.933333333333333 1" />
      </material>
    </visual>
    <collision>
      <origin
        xyz="0 0 0"
        rpy="0 0 0" />
      <geometry>
        <mesh
          filename="../../meshes/rewr1_1/right_arm_flange_link.STL" />
      </geometry>
    </collision>
  </link>
  <joint
    name="right_arm_flange_joint"
    type="fixed">
    <origin
      xyz="0 0 -0.039"
      rpy="-3.1416 0 0" />
    <parent
      link="right_wrist_roll_link" />
    <child
      link="right_arm_flange_link" />
    <axis
      xyz="0 0 0" />
  </joint>
  <link
    name="right_hand_ee_link">
    <inertial>
      <origin
        xyz="-1.2490009027033E-15 -6.10622663543836E-16 4.44089209850063E-15"
        rpy="0 0 0" />
      <mass
        value="9.99999999999892E-07" />
      <inertia
        ixx="1.6666666666663E-13"
        ixy="3.86220795429325E-30"
        ixz="3.36580652894304E-30"
        iyy="1.6666666666663E-13"
        iyz="2.61515924606155E-40"
        izz="1.66666666666649E-13" />
    </inertial>
    <visual>
      <origin
        xyz="0 0 0"
        rpy="0 0 0" />
      <geometry>
        <mesh
          filename="../../meshes/rewr1_1/right_hand_ee_link.STL" />
      </geometry>
      <material
        name="">
        <color
          rgba="0.792156862745098 0.819607843137255 0.933333333333333 1" />
      </material>
    </visual>
    <collision>
      <origin
        xyz="0 0 0"
        rpy="0 0 0" />
      <geometry>
        <mesh
          filename="../../meshes/rewr1_1/right_hand_ee_link.STL" />
      </geometry>
    </collision>
  </link>
  <joint
    name="right_hand_ee_joint"
    type="fixed">
    <origin
      xyz="0 0 -0.103"
      rpy="3.1416 0 0" />
    <parent
      link="right_wrist_roll_link" />
    <child
      link="right_hand_ee_link" />
    <axis
      xyz="0 0 0" />
  </joint>
  <link
    name="mic_link">
    <inertial>
      <origin
        xyz="0.00407660233407253 1.14491805943333E-17 0.000354971122621617"
        rpy="0 0 0" />
      <mass
        value="0.0069649503648048" />
      <inertia
        ixx="1.02200387116195E-05"
        ixy="-1.1893354136703E-21"
        ixz="8.37908784860721E-09"
        iyy="1.63235847230747E-07"
        iyz="-7.9289543430323E-21"
        izz="1.0092859929658E-05" />
    </inertial>
    <visual>
      <origin
        xyz="0 0 0"
        rpy="0 0 0" />
      <geometry>
        <mesh
          filename="../../meshes/rewr1_1/mic_link.STL" />
      </geometry>
      <material
        name="">
        <color
          rgba="0.698039215686274 0.698039215686274 0.698039215686274 1" />
      </material>
    </visual>
    <collision>
      <origin
        xyz="0 0 0"
        rpy="0 0 0" />
      <geometry>
        <mesh
          filename="../../meshes/rewr1_1/mic_link.STL" />
      </geometry>
    </collision>
  </link>
  <joint
    name="mic_joint"
    type="fixed">
    <origin
      xyz="0.0206233260819667 0 0.147422863179956"
      rpy="3.14159265358978 0.256557223795542 -3.14159265358978" />
    <parent
      link="waist_yaw_link" />
    <child
      link="mic_link" />
    <axis
      xyz="0 0 0" />
  </joint>
  <link
    name="left_drv_hang_link">
    <inertial>
      <origin
        xyz="-0.092969 0 0.035633"
        rpy="0 0 0" />
      <mass
        value="0.88972" />
      <inertia
        ixx="0.00067332"
        ixy="0"
        ixz="0.00072199"
        iyy="0.0020012"
        iyz="0"
        izz="0.0014848" />
    </inertial>
    <visual>
      <origin
        xyz="0 0 0"
        rpy="0 0 0" />
      <geometry>
        <mesh
          filename="../../meshes/rewr1_1/left_drv_hang_link.STL" />
      </geometry>
      <material
        name="">
        <color
          rgba="0.77647 0.75686 0.73725 1" />
      </material>
    </visual>
    <collision>
      <origin
        xyz="0 0 0"
        rpy="0 0 0" />
      <geometry>
        <mesh
          filename="../../meshes/rewr1_1/left_drv_hang_link.STL" />
      </geometry>
    </collision>
  </link>
  <joint
    name="left_drv_hang_joint"
    type="revolute">
    <origin
      xyz="0.1 0.166 -0.02975"
      rpy="0 0 0" />
    <parent
      link="base_link" />
    <child
      link="left_drv_hang_link" />
    <axis
      xyz="0 1 0" />
    <limit
      lower="-0.35"
      upper="0.35"
      effort="50"
      velocity="50" />
    <dynamics
      damping="0.0"
      friction="0.0" />
  </joint>
  <link
    name="left_drv_wheel_link">
    <inertial>
      <origin
        xyz="1.8792E-06 0.21726 4.2798E-07"
        rpy="0 0 0" />
      <mass
        value="2.2035" />
      <inertia
        ixx="0.0030551"
        ixy="1.8E-07"
        ixz="0"
        iyy="0.0049881"
        iyz="4E-08"
        izz="0.0030551" />
    </inertial>
    <visual>
      <origin
        xyz="0 0 0"
        rpy="0 0 0" />
      <geometry>
        <mesh
          filename="../../meshes/rewr1_1/left_drv_wheel_link.STL" />
      </geometry>
      <material
        name="">
        <color
          rgba="0.86667 0.86667 0.8902 1" />
      </material>
    </visual>
    <collision>
      <origin
        xyz="0 0 0"
        rpy="0 0 0" />
      <geometry>
        <mesh
          filename="../../meshes/rewr1_1/left_drv_wheel_link.STL" />
      </geometry>
    </collision>
  </link>
  <joint
    name="left_drv_wheel_joint"
    type="continuous">
    <origin
      xyz="-0.1 -0.166 0.02975"
      rpy="0 0 0" />
    <parent
      link="left_drv_hang_link" />
    <child
      link="left_drv_wheel_link" />
    <axis
      xyz="0 1 0" />
    <limit
      effort="15"
      velocity="300" />
    <dynamics
      damping="0.0"
      friction="0.0" />
  </joint>
  <link
    name="right_drv_hang_link">
    <inertial>
      <origin
        xyz="-0.092969 0 0.035633"
        rpy="0 0 0" />
      <mass
        value="0.88972" />
      <inertia
        ixx="0.00067332"
        ixy="0"
        ixz="0.00072199"
        iyy="0.0020012"
        iyz="0"
        izz="0.0014848" />
    </inertial>
    <visual>
      <origin
        xyz="0 0 0"
        rpy="0 0 0" />
      <geometry>
        <mesh
          filename="../../meshes/rewr1_1/right_drv_hang_link.STL" />
      </geometry>
      <material
        name="">
        <color
          rgba="0.77647 0.75686 0.73725 1" />
      </material>
    </visual>
    <collision>
      <origin
        xyz="0 0 0"
        rpy="0 0 0" />
      <geometry>
        <mesh
          filename="../../meshes/rewr1_1/right_drv_hang_link.STL" />
      </geometry>
    </collision>
  </link>
  <joint
    name="right_drv_hang_joint"
    type="revolute">
    <origin
      xyz="0.1 -0.166 -0.02975"
      rpy="0 0 0" />
    <parent
      link="base_link" />
    <child
      link="right_drv_hang_link" />
    <axis
      xyz="0 1 0" />
    <limit
      lower="-0.35"
      upper="0.35"
      effort="50"
      velocity="50" />
    <dynamics
      damping="0.0"
      friction="0.0" />
  </joint>
  <link
    name="right_drv_wheel_link">
    <inertial>
      <origin
        xyz="1.4091E-06 -0.21726 1.93E-06"
        rpy="0 0 0" />
      <mass
        value="2.2035" />
      <inertia
        ixx="0.0030551"
        ixy="0"
        ixz="0"
        iyy="0.0049881"
        iyz="-1.9E-07"
        izz="0.0030551" />
    </inertial>
    <visual>
      <origin
        xyz="0 0 0"
        rpy="0 0 0" />
      <geometry>
        <mesh
          filename="../../meshes/rewr1_1/right_drv_wheel_link.STL" />
      </geometry>
      <material
        name="">
        <color
          rgba="0.86667 0.86667 0.8902 1" />
      </material>
    </visual>
    <collision>
      <origin
        xyz="0 0 0"
        rpy="0 0 0" />
      <geometry>
        <mesh
          filename="../../meshes/rewr1_1/right_drv_wheel_link.STL" />
      </geometry>
    </collision>
  </link>
  <joint
    name="right_drv_wheel_joint"
    type="continuous">
    <origin
      xyz="-0.1 0.166 0.02975"
      rpy="0 0 0" />
    <parent
      link="right_drv_hang_link" />
    <child
      link="right_drv_wheel_link" />
    <axis
      xyz="0 1 0" />
    <limit
      effort="15"
      velocity="300" />
    <dynamics
      damping="0.0"
      friction="0.0" />
  </joint>
  <link
    name="lidar_link">
    <inertial>
      <origin
        xyz="-0.00219018889931419 -0.000235783899037056 -0.0251240338300362"
        rpy="0 0 0" />
      <mass
        value="0.39641557484248" />
      <inertia
        ixx="0.000114254377245781"
        ixy="5.13153951596913E-07"
        ixz="-8.24873745804669E-07"
        iyy="0.000122667894009239"
        iyz="1.7706363712738E-09"
        izz="0.00018789631687675" />
    </inertial>
    <visual>
      <origin
        xyz="0 0 0"
        rpy="0 0 0" />
      <geometry>
        <mesh
          filename="../../meshes/rewr1_1/lidar_link.STL" />
      </geometry>
      <material
        name="">
        <color
          rgba="0.866666666666667 0.866666666666667 0.890196078431372 1" />
      </material>
    </visual>
    <collision>
      <origin
        xyz="0 0 0"
        rpy="0 0 0" />
      <geometry>
        <mesh
          filename="../../meshes/rewr1_1/lidar_link.STL" />
      </geometry>
    </collision>
  </link>
  <joint
    name="lidar_joint"
    type="fixed">
    <origin
      xyz="0.1875 0.1145 0.1089"
      rpy="0 0 0" />
    <parent
      link="base_link" />
    <child
      link="lidar_link" />
    <axis
      xyz="0 0 0" />
  </joint>





  <link
    name="right_hand_link">
    <inertial>
      <origin
        xyz="0.000344 0.000604 0.076362"
        rpy="0 0 0" />
      <mass
        value="0.487498" />
      <inertia
        ixx="0.000803"
        ixy="-0.000001"
        ixz="0.000034"
        iyy="0.000633"
        iyz="-0.000006"
        izz="0.000246" />
    </inertial>
    <visual>
      <origin
        xyz="0 0 0"
        rpy="0 0 0" />
      <geometry>
        <mesh
          filename="../../meshes/rewr1_1/right_hand_link.STL" />
      </geometry>
      <material
        name="">
        <color
          rgba="0.792156862745098 0.819607843137255 0.933333333333333 1" />
      </material>
    </visual>
    <collision>
      <origin
        xyz="0 0 0"
        rpy="0 0 0" />
      <geometry>
        <mesh
          filename="../../meshes/rewr1_1/right_hand_link.STL" />
      </geometry>
    </collision>
  </link>

  <joint
    name="right_hand_joint"
    type="fixed">
    <origin
      xyz="0 0 0"
      rpy="0 0 -1.57" />
    <parent
      link="right_arm_flange_link" />
    <child
      link="right_hand_link" />
    <axis
      xyz="0 0 0" />
  </joint>










  <link
    name="right_hand_light_link">
    <inertial>
      <origin
        xyz="-0.017473890857181 0.000279677992350016 -0.019711355162625"
        rpy="0 0 0" />
      <mass
        value="0.0001" />
      <inertia
        ixx="0.00000000001"
        ixy="0"
        ixz="0"
        iyy="0.00000000001"
        iyz="0"
        izz="0.00000000001" />
    </inertial>
    <visual>
      <origin
        xyz="0 0 0"
        rpy="0 0 0" />
      <geometry>
        <mesh
          filename="../../meshes/rewr1_1/right_hand_light_link.STL" />
      </geometry>
      <material
        name="">
        <color
          rgba="0.792156862745098 0.819607843137255 0.933333333333333 1" />
      </material>
    </visual>
    <collision>
      <origin
        xyz="0 0 0"
        rpy="0 0 0" />
      <geometry>
        <mesh
          filename="../../meshes/rewr1_1/right_hand_light_link.STL" />
      </geometry>
    </collision>
  </link>
  <joint
    name="right_hand_light_joint"
    type="fixed">
    <origin
      xyz="0 0 0.06"
      rpy="0 0 0" />
    <parent
      link="right_hand_link" />
    <child
      link="right_hand_light_link" />
    <axis
      xyz="0 0 0" />
    <dynamics
      damping="0"
      friction="0" />
  </joint>
  <link
    name="right_hand_dorsum_link">
    <inertial>
      <origin
        xyz="-0.0140628781080049 0.000884013469764316 0.020035963107997"
        rpy="0 0 0" />
      <mass
        value="0.0001" />
      <inertia
        ixx="0.00000000001"
        ixy="0"
        ixz="0"
        iyy="0.00000000001"
        iyz="0"
        izz="0.00000000001" />
    </inertial>
    <visual>
      <origin
        xyz="0 0 0"
        rpy="0 0 0" />
      <geometry>
        <mesh
          filename="../../meshes/rewr1_1/right_hand_dorsum_link.STL" />
      </geometry>
      <material
        name="">
        <color
          rgba="0.792156862745098 0.819607843137255 0.933333333333333 1" />
      </material>
    </visual>
    <collision>
      <origin
        xyz="0 0 0"
        rpy="0 0 0" />
      <geometry>
        <mesh
          filename="../../meshes/rewr1_1/right_hand_dorsum_link.STL" />
      </geometry>
    </collision>
  </link>
  <joint
    name="right_hand_dorsum_joint"
    type="fixed">
    <origin
      xyz="0 0 0.06"
      rpy="0 0 0" />
    <parent
      link="right_hand_link" />
    <child
      link="right_hand_dorsum_link" />
    <axis
      xyz="0 0 0" />
    <dynamics
      damping="0"
      friction="0" />
  </joint>
  <link
    name="right_hand_palm_link">
    <inertial>
      <origin
        xyz="0.00778792936569183 0.00117472937747376 0.0240870741819171"
        rpy="0 0 0" />
      <mass
        value="0.0001" />
      <inertia
        ixx="0.00000000001"
        ixy="0"
        ixz="0"
        iyy="0.00000000001"
        iyz="0"
        izz="0.00000000001" />
    </inertial>
    <visual>
      <origin
        xyz="0 0 0"
        rpy="0 0 0" />
      <geometry>
        <mesh
          filename="../../meshes/rewr1_1/right_hand_palm_link.STL" />
      </geometry>
      <material
        name="">
        <color
          rgba="0.792156862745098 0.819607843137255 0.933333333333333 1" />
      </material>
    </visual>
    <collision>
      <origin
        xyz="0 0 0"
        rpy="0 0 0" />
      <geometry>
        <mesh
          filename="../../meshes/rewr1_1/right_hand_palm_link.STL" />
      </geometry>
    </collision>
  </link>
  <joint
    name="right_hand_palm_joint"
    type="fixed">
    <origin
      xyz="0 0 0.06"
      rpy="0 0 0" />
    <parent
      link="right_hand_link" />
    <child
      link="right_hand_palm_link" />
    <axis
      xyz="0 0 0" />
    <dynamics
      damping="0"
      friction="0" />
  </joint>
  <link
    name="right_hand_thumb_bend_link">
    <inertial>
      <origin
        xyz="-0.000338924514166982 0.0131540255408617 -0.000118788072502624"
        rpy="0 0 0" />
      <mass
        value="0.01298991" />
      <inertia
        ixx="0.00000182"
        ixy="-0.00000001"
        ixz="0.00000002"
        iyy="0.00000092"
        iyz="0.00000003"
        izz="0.00000152" />
    </inertial>
    <visual>
      <origin
        xyz="0 0 0"
        rpy="0 0 0" />
      <geometry>
        <mesh
          filename="../../meshes/rewr1_1/right_hand_thumb_bend_link.STL" />
      </geometry>
      <material
        name="">
        <color
          rgba="0.792156862745098 0.819607843137255 0.933333333333333 1" />
      </material>
    </visual>
    <collision>
      <origin
        xyz="0 0 0"
        rpy="0 0 0" />
      <geometry>
        <mesh
          filename="../../meshes/rewr1_1/right_hand_thumb_bend_link.STL" />
      </geometry>
    </collision>
  </link>
  <joint
    name="right_hand_thumb_bend_joint"
    type="revolute">
    <origin
      xyz="0.011 0.02606 0.047668"
      rpy="0.17453 0 0" />
    <parent
      link="right_hand_link" />
    <child
      link="right_hand_thumb_bend_link" />
    <axis
      xyz="0 0 -1" />
    <limit
      lower="0"
      upper="1.919"
      effort="1.1"
      velocity="8.63" />
    <dynamics
      damping="0"
      friction="0" />
  </joint>
  <link
    name="right_hand_thumb_rota_link1">
    <inertial>
      <origin
        xyz="-4.7579847263314E-05 0.0200098736521791 0.00578656785183815"
        rpy="0 0 0" />
      <mass
        value="0.07256165" />
      <inertia
        ixx="0.00001937"
        ixy="-0.00000001"
        ixz="-0.00000001"
        iyy="0.00000545"
        iyz="-0.00000265"
        izz="0.00001869" />
    </inertial>
    <visual>
      <origin
        xyz="0 0 0"
        rpy="0 0 0" />
      <geometry>
        <mesh
          filename="../../meshes/rewr1_1/right_hand_thumb_rota_link1.STL" />
      </geometry>
      <material
        name="">
        <color
          rgba="0.698039215686274 0.698039215686274 0.698039215686274 1" />
      </material>
    </visual>
    <collision>
      <origin
        xyz="0 0 0"
        rpy="0 0 0" />
      <geometry>
        <mesh
          filename="../../meshes/rewr1_1/right_hand_thumb_rota_link1.STL" />
      </geometry>
    </collision>
  </link>
  <joint
    name="right_hand_thumb_rota_joint1"
    type="revolute">
    <origin
      xyz="-0.00056763 0.02906 -0.0018532"
      rpy="-0.17394 0.2618 -0.020711" />
    <parent
      link="right_hand_thumb_bend_link" />
    <child
      link="right_hand_thumb_rota_link1" />
    <axis
      xyz="1 0 0" />
    <limit
      lower="0"
      upper="1.291"
      effort="1.1"
      velocity="8.63" />
    <dynamics
      damping="0"
      friction="0" />
  </joint>
  <link
    name="right_hand_thumb_rotaback_link1">
    <inertial>
      <origin
        xyz="-1.9254881489239E-07 -0.0203974566855158 -0.0206197663353435"
        rpy="0 0 0" />
      <mass
        value="0.0001" />
      <inertia
        ixx="0.00000000001"
        ixy="0"
        ixz="0"
        iyy="0.00000000001"
        iyz="0"
        izz="0.00000000001" />
    </inertial>
    <visual>
      <origin
        xyz="0 0 0"
        rpy="0 0 0" />
      <geometry>
        <mesh
          filename="../../meshes/rewr1_1/right_hand_thumb_rotaback_link1.STL" />
      </geometry>
      <material
        name="">
        <color
          rgba="0.698039215686274 0.698039215686274 0.698039215686274 1" />
      </material>
    </visual>
    <collision>
      <origin
        xyz="0 0 0"
        rpy="0 0 0" />
      <geometry>
        <mesh
          filename="../../meshes/rewr1_1/right_hand_thumb_rotaback_link1.STL" />
      </geometry>
    </collision>
  </link>
  <joint
    name="right_hand_thumb_rotaback_joint1"
    type="fixed">
    <origin
      xyz="0 0.0477516316145998 0.0167671403245556"
      rpy="0 0 0" />
    <parent
      link="right_hand_thumb_rota_link1" />
    <child
      link="right_hand_thumb_rotaback_link1" />
    <axis
      xyz="0 0 0" />
    <dynamics
      damping="0"
      friction="0" />
  </joint>
  <link
    name="right_hand_thumb_rota_link2">
    <inertial>
      <origin
        xyz="7.1758545452591E-07 0.0123838099580665 0.00783535595252598"
        rpy="0 0 0" />
      <mass
        value="0.01140186" />
      <inertia
        ixx="0.00000172"
        ixy="0"
        ixz="0"
        iyy="0.00000146"
        iyz="-0.0000005"
        izz="0.00000118" />
    </inertial>
    <visual>
      <origin
        xyz="0 0 0"
        rpy="0 0 0" />
      <geometry>
        <mesh
          filename="../../meshes/rewr1_1/right_hand_thumb_rota_link2.STL" />
      </geometry>
      <material
        name="">
        <color
          rgba="0.698039215686274 0.698039215686274 0.698039215686274 1" />
      </material>
    </visual>
    <collision>
      <origin
        xyz="0 0 0"
        rpy="0 0 0" />
      <geometry>
        <mesh
          filename="../../meshes/rewr1_1/right_hand_thumb_rota_link2.STL" />
      </geometry>
    </collision>
  </link>
  <joint
    name="right_hand_thumb_rota_joint2"
    type="revolute">
    <origin
      xyz="0 0.047752 0.016767"
      rpy="0 0 0" />
    <parent
      link="right_hand_thumb_rota_link1" />
    <child
      link="right_hand_thumb_rota_link2" />
    <axis
      xyz="1 0 0" />
    <limit
      lower="0"
      upper="0.995"
      effort="1.1"
      velocity="8.63" />
    <dynamics
      damping="0"
      friction="0" />
  </joint>
  <link
    name="right_hand_thumb_rotaback_link2">
    <inertial>
      <origin
        xyz="1.30915331785289E-06 -0.018038597674028 -0.0211975153384117"
        rpy="0 0 0" />
      <mass
        value="0.0001" />
      <inertia
        ixx="0.00000000001"
        ixy="0"
        ixz="0"
        iyy="0.00000000001"
        iyz="0"
        izz="0.00000000001" />
    </inertial>
    <visual>
      <origin
        xyz="0 0 0"
        rpy="0 0 0" />
      <geometry>
        <mesh
          filename="../../meshes/rewr1_1/right_hand_thumb_rotaback_link2.STL" />
      </geometry>
      <material
        name="">
        <color
          rgba="0.698039215686274 0.698039215686274 0.698039215686274 1" />
      </material>
    </visual>
    <collision>
      <origin
        xyz="0 0 0"
        rpy="0 0 0" />
      <geometry>
        <mesh
          filename="../../meshes/rewr1_1/right_hand_thumb_rotaback_link2.STL" />
      </geometry>
    </collision>
  </link>
  <joint
    name="right_hand_thumb_rotaback_joint2"
    type="fixed">
    <origin
      xyz="0 0.030902 0.016947"
      rpy="0 0 0" />
    <parent
      link="right_hand_thumb_rota_link2" />
    <child
      link="right_hand_thumb_rotaback_link2" />
    <axis
      xyz="0 0 0" />
    <dynamics
      damping="0"
      friction="0" />
  </joint>
  <link
    name="right_hand_thumb_rota_tip">
    <inertial>
      <origin
        xyz="-2.08166817117217E-17 0 -1.38777878078145E-17"
        rpy="0 0 0" />
      <mass
        value="0.0001" />
      <inertia
        ixx="0.00000000001"
        ixy="0"
        ixz="0"
        iyy="0.00000000001"
        iyz="0"
        izz="0.00000000001" />
    </inertial>
    <visual>
      <origin
        xyz="0 0 0"
        rpy="0 0 0" />
      <geometry>
        <mesh
          filename="../../meshes/rewr1_1/right_hand_thumb_rota_tip.STL" />
      </geometry>
      <material
        name="">
        <color
          rgba="0.988235294117647 0.737254901960784 0.517647058823529 1" />
      </material>
    </visual>
    <collision>
      <origin
        xyz="0 0 0"
        rpy="0 0 0" />
      <geometry>
        <mesh
          filename="../../meshes/rewr1_1/right_hand_thumb_rota_tip.STL" />
      </geometry>
    </collision>
  </link>
  <joint
    name="right_hand_thumb_rota_joint3"
    type="fixed">
    <origin
      xyz="0 0.030902 0.016947"
      rpy="0 0 0" />
    <parent
      link="right_hand_thumb_rota_link2" />
    <child
      link="right_hand_thumb_rota_tip" />
    <axis
      xyz="0 0 0" />
    <dynamics
      damping="0"
      friction="0" />
  </joint>
  <link
    name="right_hand_index_rota_link1">
    <inertial>
      <origin
        xyz="0.00350127458755274 -8.29787530961905E-05 0.0220585492607402"
        rpy="0 0 0" />
      <mass
        value="0.00783143" />
      <inertia
        ixx="0.00000125"
        ixy="0"
        ixz="-0.00000005"
        iyy="0.0000012"
        iyz="-0.00000003"
        izz="0.00000047" />
    </inertial>
    <visual>
      <origin
        xyz="0 0 0"
        rpy="0 0 0" />
      <geometry>
        <mesh
          filename="../../meshes/rewr1_1/right_hand_index_rota_link1.STL" />
      </geometry>
      <material
        name="">
        <color
          rgba="0.698039215686274 0.698039215686274 0.698039215686274 1" />
      </material>
    </visual>
    <collision>
      <origin
        xyz="0 0 0"
        rpy="0 0 0" />
      <geometry>
        <mesh
          filename="../../meshes/rewr1_1/right_hand_index_rota_link1.STL" />
      </geometry>
    </collision>
  </link>
  <joint
    name="right_hand_index_rota_joint1"
    type="revolute">
    <origin
      xyz="-0.001 0.029 0.1228"
      rpy="0 0 0" />
    <parent
      link="right_hand_link" />
    <child
      link="right_hand_index_rota_link1" />
    <axis
      xyz="0 1 0" />
    <limit
      lower="0"
      upper="1.483"
      effort="1.1"
      velocity="8.63" />
    <dynamics
      damping="0"
      friction="0" />
  </joint>
  <link
    name="right_hand_index_rotaback_link1">
    <inertial>
      <origin
        xyz="-0.00715187464765425 -0.000333502539739478 -0.0215650094373729"
        rpy="0 0 0" />
      <mass
        value="0.0001" />
      <inertia
        ixx="0.00000000001"
        ixy="0"
        ixz="0"
        iyy="0.00000000001"
        iyz="0"
        izz="0.00000000001" />
    </inertial>
    <visual>
      <origin
        xyz="0 0 0"
        rpy="0 0 0" />
      <geometry>
        <mesh
          filename="../../meshes/rewr1_1/right_hand_index_rotaback_link1.STL" />
      </geometry>
      <material
        name="">
        <color
          rgba="0.698039215686274 0.698039215686274 0.698039215686274 1" />
      </material>
    </visual>
    <collision>
      <origin
        xyz="0 0 0"
        rpy="0 0 0" />
      <geometry>
        <mesh
          filename="../../meshes/rewr1_1/right_hand_index_rotaback_link1.STL" />
      </geometry>
    </collision>
  </link>
  <joint
    name="right_hand_index_rotaback_joint1"
    type="fixed">
    <origin
      xyz="0.0030281 0 0.032181"
      rpy="0 0 0" />
    <parent
      link="right_hand_index_rota_link1" />
    <child
      link="right_hand_index_rotaback_link1" />
    <axis
      xyz="0 0 0" />
    <dynamics
      damping="0"
      friction="0" />
  </joint>
  <link
    name="right_hand_index_rota_link2">
    <inertial>
      <origin
        xyz="-0.00264374308567867 -5.4625871503261E-08 0.0225017022301799"
        rpy="0 0 0" />
      <mass
        value="0.01179339" />
      <inertia
        ixx="0.00000227"
        ixy="0"
        ixz="-0.00000018"
        iyy="0.0000023"
        iyz="0"
        izz="0.00000025" />
    </inertial>
    <visual>
      <origin
        xyz="0 0 0"
        rpy="0 0 0" />
      <geometry>
        <mesh
          filename="../../meshes/rewr1_1/right_hand_index_rota_link2.STL" />
      </geometry>
      <material
        name="">
        <color
          rgba="0.698039215686274 0.698039215686274 0.698039215686274 1" />
      </material>
    </visual>
    <collision>
      <origin
        xyz="0 0 0"
        rpy="0 0 0" />
      <geometry>
        <mesh
          filename="../../meshes/rewr1_1/right_hand_index_rota_link2.STL" />
      </geometry>
    </collision>
  </link>
  <joint
    name="right_hand_index_rota_joint2"
    type="revolute">
    <origin
      xyz="0.0030281 0 0.032181"
      rpy="0 0 0" />
    <parent
      link="right_hand_index_rota_link1" />
    <child
      link="right_hand_index_rota_link2" />
    <axis
      xyz="0 1 0" />
    <limit
      lower="0"
      upper="1.919"
      effort="1.1"
      velocity="8.63" />
    <dynamics
      damping="0"
      friction="0" />
  </joint>
  <link
    name="right_hand_index_rotaback_link2">
    <inertial>
      <origin
        xyz="-0.000939110905108727 -1.17899385215087E-06 -0.0294816999899348"
        rpy="0 0 0" />
      <mass
        value="0.0001" />
      <inertia
        ixx="0.00000000001"
        ixy="0"
        ixz="0"
        iyy="0.00000000001"
        iyz="0"
        izz="0.00000000001" />
    </inertial>
    <visual>
      <origin
        xyz="0 0 0"
        rpy="0 0 0" />
      <geometry>
        <mesh
          filename="../../meshes/rewr1_1/right_hand_index_rotaback_link2.STL" />
      </geometry>
      <material
        name="">
        <color
          rgba="0.698039215686274 0.698039215686274 0.698039215686274 1" />
      </material>
    </visual>
    <collision>
      <origin
        xyz="0 0 0"
        rpy="0 0 0" />
      <geometry>
        <mesh
          filename="../../meshes/rewr1_1/right_hand_index_rotaback_link2.STL" />
      </geometry>
    </collision>
  </link>
  <joint
    name="right_hand_index_rotaback_joint2"
    type="fixed">
    <origin
      xyz="-0.0061488 0 0.045565"
      rpy="0 0 0" />
    <parent
      link="right_hand_index_rota_link2" />
    <child
      link="right_hand_index_rotaback_link2" />
    <axis
      xyz="0 0 0" />
    <dynamics
      damping="0"
      friction="0" />
  </joint>
  <link
    name="right_hand_index_rota_tip">
    <inertial>
      <origin
        xyz="-1.73472347597681E-17 -3.90312782094782E-15 -2.77555756156289E-17"
        rpy="0 0 0" />
      <mass
        value="0.0001" />
      <inertia
        ixx="0.00000000001"
        ixy="0"
        ixz="0"
        iyy="0.00000000001"
        iyz="0"
        izz="0.00000000001" />
    </inertial>
    <visual>
      <origin
        xyz="0 0 0"
        rpy="0 0 0" />
      <geometry>
        <mesh
          filename="../../meshes/rewr1_1/right_hand_index_rota_tip.STL" />
      </geometry>
      <material
        name="">
        <color
          rgba="0.988235294117647 0.737254901960784 0.517647058823529 1" />
      </material>
    </visual>
    <collision>
      <origin
        xyz="0 0 0"
        rpy="0 0 0" />
      <geometry>
        <mesh
          filename="../../meshes/rewr1_1/right_hand_index_rota_tip.STL" />
      </geometry>
    </collision>
  </link>
  <joint
    name="right_hand_index_rota_joint3"
    type="fixed">
    <origin
      xyz="-0.0061488 0 0.045565"
      rpy="0 0 0" />
    <parent
      link="right_hand_index_rota_link2" />
    <child
      link="right_hand_index_rota_tip" />
    <axis
      xyz="0 0 0" />
    <dynamics
      damping="0"
      friction="0" />
  </joint>
  <link
    name="right_hand_mid_link1">
    <inertial>
      <origin
        xyz="0.00357825181924768 -8.29788551007567E-05 0.022046191451614"
        rpy="0 0 0" />
      <mass
        value="0.00783143" />
      <inertia
        ixx="0.00000125"
        ixy="0"
        ixz="-0.00000005"
        iyy="0.0000012"
        iyz="-0.00000003"
        izz="0.00000047" />
    </inertial>
    <visual>
      <origin
        xyz="0 0 0"
        rpy="0 0 0" />
      <geometry>
        <mesh
          filename="../../meshes/rewr1_1/right_hand_mid_link1.STL" />
      </geometry>
      <material
        name="">
        <color
          rgba="0.698039215686274 0.698039215686274 0.698039215686274 1" />
      </material>
    </visual>
    <collision>
      <origin
        xyz="0 0 0"
        rpy="0 0 0" />
      <geometry>
        <mesh
          filename="../../meshes/rewr1_1/right_hand_mid_link1.STL" />
      </geometry>
    </collision>
  </link>
  <joint
    name="right_hand_mid_joint1"
    type="revolute">
    <origin
      xyz="-0.001 0.01 0.1248"
      rpy="0 0 0" />
    <parent
      link="right_hand_link" />
    <child
      link="right_hand_mid_link1" />
    <axis
      xyz="0 1 0" />
    <limit
      lower="0"
      upper="1.483"
      effort="1.1"
      velocity="8.63" />
    <dynamics
      damping="0"
      friction="0" />
  </joint>
  <link
    name="right_hand_midback_link1">
    <inertial>
      <origin
        xyz="-0.00722711252439805 -0.000333497644814452 -0.0215399223704975"
        rpy="0 0 0" />
      <mass
        value="0.0001" />
      <inertia
        ixx="0.00000000001"
        ixy="0"
        ixz="0"
        iyy="0.00000000001"
        iyz="0"
        izz="0.00000000001" />
    </inertial>
    <visual>
      <origin
        xyz="0 0 0"
        rpy="0 0 0" />
      <geometry>
        <mesh
          filename="../../meshes/rewr1_1/right_hand_midback_link1.STL" />
      </geometry>
      <material
        name="">
        <color
          rgba="0.698039215686274 0.698039215686274 0.698039215686274 1" />
      </material>
    </visual>
    <collision>
      <origin
        xyz="0 0 0"
        rpy="0 0 0" />
      <geometry>
        <mesh
          filename="../../meshes/rewr1_1/right_hand_midback_link1.STL" />
      </geometry>
    </collision>
  </link>
  <joint
    name="right_hand_midback_joint1"
    type="fixed">
    <origin
      xyz="0.0031404 0 0.03217"
      rpy="0 0 0" />
    <parent
      link="right_hand_mid_link1" />
    <child
      link="right_hand_midback_link1" />
    <axis
      xyz="0 0 0" />
    <dynamics
      damping="0"
      friction="0" />
  </joint>
  <link
    name="right_hand_mid_link2">
    <inertial>
      <origin
        xyz="-0.00267492453150783 3.02145438989612E-07 0.0251671461844696"
        rpy="0 0 0" />
      <mass
        value="0.01329645" />
      <inertia
        ixx="0.00000307"
        ixy="0"
        ixz="-0.00000023"
        iyy="0.00000311"
        iyz="0"
        izz="0.00000029" />
    </inertial>
    <visual>
      <origin
        xyz="0 0 0"
        rpy="0 0 0" />
      <geometry>
        <mesh
          filename="../../meshes/rewr1_1/right_hand_mid_link2.STL" />
      </geometry>
      <material
        name="">
        <color
          rgba="0.698039215686274 0.698039215686274 0.698039215686274 1" />
      </material>
    </visual>
    <collision>
      <origin
        xyz="0 0 0"
        rpy="0 0 0" />
      <geometry>
        <mesh
          filename="../../meshes/rewr1_1/right_hand_mid_link2.STL" />
      </geometry>
    </collision>
  </link>
  <joint
    name="right_hand_mid_joint2"
    type="revolute">
    <origin
      xyz="0.0031404 0 0.03217"
      rpy="0 0 0" />
    <parent
      link="right_hand_mid_link1" />
    <child
      link="right_hand_mid_link2" />
    <axis
      xyz="0 1 0" />
    <limit
      lower="0"
      upper="1.919"
      effort="1.1"
      velocity="8.63" />
    <dynamics
      damping="0"
      friction="0" />
  </joint>
  <link
    name="right_hand_midback_link2">
    <inertial>
      <origin
        xyz="-0.000154264993620144 -1.12460543594262E-06 -0.032258873011726"
        rpy="0 0 0" />
      <mass
        value="0.0001" />
      <inertia
        ixx="0.00000000001"
        ixy="0"
        ixz="0"
        iyy="0.00000000001"
        iyz="0"
        izz="0.00000000001" />
    </inertial>
    <visual>
      <origin
        xyz="0 0 0"
        rpy="0 0 0" />
      <geometry>
        <mesh
          filename="../../meshes/rewr1_1/right_hand_midback_link2.STL" />
      </geometry>
      <material
        name="">
        <color
          rgba="0.698039215686274 0.698039215686274 0.698039215686274 1" />
      </material>
    </visual>
    <collision>
      <origin
        xyz="0 0 0"
        rpy="0 0 0" />
      <geometry>
        <mesh
          filename="../../meshes/rewr1_1/right_hand_midback_link2.STL" />
      </geometry>
    </collision>
  </link>
  <joint
    name="right_hand_midback_joint2"
    type="fixed">
    <origin
      xyz="-0.007041 0 0.050914"
      rpy="0 0 0" />
    <parent
      link="right_hand_mid_link2" />
    <child
      link="right_hand_midback_link2" />
    <axis
      xyz="0 0 0" />
    <dynamics
      damping="0"
      friction="0" />
  </joint>
  <link
    name="right_hand_mid_tip">
    <inertial>
      <origin
        xyz="-8.67361737988404E-19 -2.91086599268908E-15 0"
        rpy="0 0 0" />
      <mass
        value="0.0001" />
      <inertia
        ixx="0.00000000001"
        ixy="0"
        ixz="0"
        iyy="0.00000000001"
        iyz="0"
        izz="0.00000000001" />
    </inertial>
    <visual>
      <origin
        xyz="0 0 0"
        rpy="0 0 0" />
      <geometry>
        <mesh
          filename="../../meshes/rewr1_1/right_hand_mid_tip.STL" />
      </geometry>
      <material
        name="">
        <color
          rgba="0.988235294117647 0.737254901960784 0.517647058823529 1" />
      </material>
    </visual>
    <collision>
      <origin
        xyz="0 0 0"
        rpy="0 0 0" />
      <geometry>
        <mesh
          filename="../../meshes/rewr1_1/right_hand_mid_tip.STL" />
      </geometry>
    </collision>
  </link>
  <joint
    name="right_hand_mid_joint3"
    type="fixed">
    <origin
      xyz="-0.007041 0 0.050914"
      rpy="0 0 0" />
    <parent
      link="right_hand_mid_link2" />
    <child
      link="right_hand_mid_tip" />
    <axis
      xyz="0 0 0" />
    <dynamics
      damping="0"
      friction="0" />
  </joint>
  <link
    name="right_hand_ring_link1">
    <inertial>
      <origin
        xyz="0.00350127461515757 -8.29787430194698E-05 0.0220585493234882"
        rpy="0 0 0" />
      <mass
        value="0.00783143" />
      <inertia
        ixx="0.00000125"
        ixy="0"
        ixz="-0.00000005"
        iyy="0.0000012"
        iyz="-0.00000003"
        izz="0.00000047" />
    </inertial>
    <visual>
      <origin
        xyz="0 0 0"
        rpy="0 0 0" />
      <geometry>
        <mesh
          filename="../../meshes/rewr1_1/right_hand_ring_link1.STL" />
      </geometry>
      <material
        name="">
        <color
          rgba="0.698039215686274 0.698039215686274 0.698039215686274 1" />
      </material>
    </visual>
    <collision>
      <origin
        xyz="0 0 0"
        rpy="0 0 0" />
      <geometry>
        <mesh
          filename="../../meshes/rewr1_1/right_hand_ring_link1.STL" />
      </geometry>
    </collision>
  </link>
  <joint
    name="right_hand_ring_joint1"
    type="revolute">
    <origin
      xyz="-0.001 -0.009 0.1228"
      rpy="0 0 0" />
    <parent
      link="right_hand_link" />
    <child
      link="right_hand_ring_link1" />
    <axis
      xyz="0 1 0" />
    <limit
      lower="0"
      upper="1.483"
      effort="1.1"
      velocity="8.63" />
    <dynamics
      damping="0"
      friction="0" />
  </joint>
  <link
    name="right_hand_ringback_link1">
    <inertial>
      <origin
        xyz="-0.00715187830609899 -0.000333506551853874 -0.0215650025172259"
        rpy="0 0 0" />
      <mass
        value="0.0001" />
      <inertia
        ixx="0.00000000001"
        ixy="0"
        ixz="0"
        iyy="0.00000000001"
        iyz="0"
        izz="0.00000000001" />
    </inertial>
    <visual>
      <origin
        xyz="0 0 0"
        rpy="0 0 0" />
      <geometry>
        <mesh
          filename="../../meshes/rewr1_1/right_hand_ringback_link1.STL" />
      </geometry>
      <material
        name="">
        <color
          rgba="0.698039215686274 0.698039215686274 0.698039215686274 1" />
      </material>
    </visual>
    <collision>
      <origin
        xyz="0 0 0"
        rpy="0 0 0" />
      <geometry>
        <mesh
          filename="../../meshes/rewr1_1/right_hand_ringback_link1.STL" />
      </geometry>
    </collision>
  </link>
  <joint
    name="right_hand_ringback_joint1"
    type="fixed">
    <origin
      xyz="0.0030281 0 0.032181"
      rpy="0 0 0" />
    <parent
      link="right_hand_ring_link1" />
    <child
      link="right_hand_ringback_link1" />
    <axis
      xyz="0 0 0" />
    <dynamics
      damping="0"
      friction="0" />
  </joint>
  <link
    name="right_hand_ring_link2">
    <inertial>
      <origin
        xyz="-0.0026437430856786 -5.46258713800957E-08 0.02250170223018"
        rpy="0 0 0" />
      <mass
        value="0.01179339" />
      <inertia
        ixx="0.00000227"
        ixy="0"
        ixz="-0.00000018"
        iyy="0.0000023"
        iyz="0"
        izz="0.00000025" />
    </inertial>
    <visual>
      <origin
        xyz="0 0 0"
        rpy="0 0 0" />
      <geometry>
        <mesh
          filename="../../meshes/rewr1_1/right_hand_ring_link2.STL" />
      </geometry>
      <material
        name="">
        <color
          rgba="0.698039215686274 0.698039215686274 0.698039215686274 1" />
      </material>
    </visual>
    <collision>
      <origin
        xyz="0 0 0"
        rpy="0 0 0" />
      <geometry>
        <mesh
          filename="../../meshes/rewr1_1/right_hand_ring_link2.STL" />
      </geometry>
    </collision>
  </link>
  <joint
    name="right_hand_ring_joint2"
    type="revolute">
    <origin
      xyz="0.0030281 0 0.032181"
      rpy="0 0 0" />
    <parent
      link="right_hand_ring_link1" />
    <child
      link="right_hand_ring_link2" />
    <axis
      xyz="0 1 0" />
    <limit
      lower="0"
      upper="1.919"
      effort="1.1"
      velocity="8.63" />
    <dynamics
      damping="0"
      friction="0" />
  </joint>
  <link
    name="right_hand_ringback_link2">
    <inertial>
      <origin
        xyz="-0.000939110909518823 -1.17912825695413E-06 -0.0294817004969203"
        rpy="0 0 0" />
      <mass
        value="0.0001" />
      <inertia
        ixx="0.00000000001"
        ixy="0"
        ixz="0"
        iyy="0.00000000001"
        iyz="0"
        izz="0.00000000001" />
    </inertial>
    <visual>
      <origin
        xyz="0 0 0"
        rpy="0 0 0" />
      <geometry>
        <mesh
          filename="../../meshes/rewr1_1/right_hand_ringback_link2.STL" />
      </geometry>
      <material
        name="">
        <color
          rgba="0.698039215686274 0.698039215686274 0.698039215686274 1" />
      </material>
    </visual>
    <collision>
      <origin
        xyz="0 0 0"
        rpy="0 0 0" />
      <geometry>
        <mesh
          filename="../../meshes/rewr1_1/right_hand_ringback_link2.STL" />
      </geometry>
    </collision>
  </link>
  <joint
    name="right_hand_ringback_joint2"
    type="fixed">
    <origin
      xyz="-0.0061488 0 0.045565"
      rpy="0 0 0" />
    <parent
      link="right_hand_ring_link2" />
    <child
      link="right_hand_ringback_link2" />
    <axis
      xyz="0 0 0" />
    <dynamics
      damping="0"
      friction="0" />
  </joint>
  <link
    name="right_hand_ring_tip">
    <inertial>
      <origin
        xyz="-1.21430643318376E-17 -3.82333054105288E-15 5.55111512312578E-17"
        rpy="0 0 0" />
      <mass
        value="0.0001" />
      <inertia
        ixx="0.00000000001"
        ixy="0"
        ixz="0"
        iyy="0.00000000001"
        iyz="0"
        izz="0.00000000001" />
    </inertial>
    <visual>
      <origin
        xyz="0 0 0"
        rpy="0 0 0" />
      <geometry>
        <mesh
          filename="../../meshes/rewr1_1/right_hand_ring_tip.STL" />
      </geometry>
      <material
        name="">
        <color
          rgba="0.988235294117647 0.737254901960784 0.517647058823529 1" />
      </material>
    </visual>
    <collision>
      <origin
        xyz="0 0 0"
        rpy="0 0 0" />
      <geometry>
        <mesh
          filename="../../meshes/rewr1_1/right_hand_ring_tip.STL" />
      </geometry>
    </collision>
  </link>
  <joint
    name="right_hand_ring_joint3"
    type="fixed">
    <origin
      xyz="-0.0061488 0 0.045565"
      rpy="0 0 0" />
    <parent
      link="right_hand_ring_link2" />
    <child
      link="right_hand_ring_tip" />
    <axis
      xyz="0 0 0" />
    <dynamics
      damping="0"
      friction="0" />
  </joint>
  <link
    name="right_hand_pinky_link1">
    <inertial>
      <origin
        xyz="0.00357825179936166 -8.29789125955417E-05 0.0220461913354498"
        rpy="0 0 0" />
      <mass
        value="0.00783143" />
      <inertia
        ixx="0.00000125"
        ixy="0"
        ixz="-0.00000005"
        iyy="0.0000012"
        iyz="-0.00000003"
        izz="0.00000047" />
    </inertial>
    <visual>
      <origin
        xyz="0 0 0"
        rpy="0 0 0" />
      <geometry>
        <mesh
          filename="../../meshes/rewr1_1/right_hand_pinky_link1.STL" />
      </geometry>
      <material
        name="">
        <color
          rgba="0.698039215686274 0.698039215686274 0.698039215686274 1" />
      </material>
    </visual>
    <collision>
      <origin
        xyz="0 0 0"
        rpy="0 0 0" />
      <geometry>
        <mesh
          filename="../../meshes/rewr1_1/right_hand_pinky_link1.STL" />
      </geometry>
    </collision>
  </link>
  <joint
    name="right_hand_pinky_joint1"
    type="revolute">
    <origin
      xyz="-0.001 -0.028 0.1208"
      rpy="0 0 0" />
    <parent
      link="right_hand_link" />
    <child
      link="right_hand_pinky_link1" />
    <axis
      xyz="0 1 0" />
    <limit
      lower="0"
      upper="1.483"
      effort="1.1"
      velocity="8.63" />
    <dynamics
      damping="0"
      friction="0" />
  </joint>
  <link
    name="right_hand_pinkyback_link1">
    <inertial>
      <origin
        xyz="-0.00722711252525076 -0.000333497616350521 -0.021539922397371"
        rpy="0 0 0" />
      <mass
        value="0.0001" />
      <inertia
        ixx="0.00000000001"
        ixy="0"
        ixz="0"
        iyy="0.00000000001"
        iyz="0"
        izz="0.00000000001" />
    </inertial>
    <visual>
      <origin
        xyz="0 0 0"
        rpy="0 0 0" />
      <geometry>
        <mesh
          filename="../../meshes/rewr1_1/right_hand_pinkyback_link1.STL" />
      </geometry>
      <material
        name="">
        <color
          rgba="0.698039215686274 0.698039215686274 0.698039215686274 1" />
      </material>
    </visual>
    <collision>
      <origin
        xyz="0 0 0"
        rpy="0 0 0" />
      <geometry>
        <mesh
          filename="../../meshes/rewr1_1/right_hand_pinkyback_link1.STL" />
      </geometry>
    </collision>
  </link>
  <joint
    name="right_hand_pinkyback_joint1"
    type="fixed">
    <origin
      xyz="0.0031404 0 0.03217"
      rpy="0 0 0" />
    <parent
      link="right_hand_pinky_link1" />
    <child
      link="right_hand_pinkyback_link1" />
    <axis
      xyz="0 0 0" />
    <dynamics
      damping="0"
      friction="0" />
  </joint>
  <link
    name="right_hand_pinky_link2">
    <inertial>
      <origin
        xyz="-0.00269385496678823 2.02040142886772E-07 0.0197558188914815"
        rpy="0 0 0" />
      <mass
        value="0.00959828" />
      <inertia
        ixx="0.00000148"
        ixy="0"
        ixz="-0.00000012"
        iyy="0.00000152"
        iyz="0"
        izz="0.00000020" />
    </inertial>
    <visual>
      <origin
        xyz="0 0 0"
        rpy="0 0 0" />
      <geometry>
        <mesh
          filename="../../meshes/rewr1_1/right_hand_pinky_link2.STL" />
      </geometry>
      <material
        name="">
        <color
          rgba="0.698039215686274 0.698039215686274 0.698039215686274 1" />
      </material>
    </visual>
    <collision>
      <origin
        xyz="0 0 0"
        rpy="0 0 0" />
      <geometry>
        <mesh
          filename="../../meshes/rewr1_1/right_hand_pinky_link2.STL" />
      </geometry>
    </collision>
  </link>
  <joint
    name="right_hand_pinky_joint2"
    type="revolute">
    <origin
      xyz="0.0031404 0 0.03217"
      rpy="0 0 0" />
    <parent
      link="right_hand_pinky_link1" />
    <child
      link="right_hand_pinky_link2" />
    <axis
      xyz="0 1 0" />
    <limit
      lower="0"
      upper="1.919"
      effort="1.1"
      velocity="8.63" />
    <dynamics
      damping="0"
      friction="0" />
  </joint>
  <link
    name="right_hand_pinkyback_link2">
    <inertial>
      <origin
        xyz="-0.000973026894518641 -1.44038201009208E-06 -0.0271599742037912"
        rpy="0 0 0" />
      <mass
        value="0.0001" />
      <inertia
        ixx="0.00000000001"
        ixy="0"
        ixz="0"
        iyy="0.00000000001"
        iyz="0"
        izz="0.00000000001" />
    </inertial>
    <visual>
      <origin
        xyz="0 0 0"
        rpy="0 0 0" />
      <geometry>
        <mesh
          filename="../../meshes/rewr1_1/right_hand_pinkyback_link2.STL" />
      </geometry>
      <material
        name="">
        <color
          rgba="0.698039215686274 0.698039215686274 0.698039215686274 1" />
      </material>
    </visual>
    <collision>
      <origin
        xyz="0 0 0"
        rpy="0 0 0" />
      <geometry>
        <mesh
          filename="../../meshes/rewr1_1/right_hand_pinkyback_link2.STL" />
      </geometry>
    </collision>
  </link>
  <joint
    name="right_hand_pinkyback_joint2"
    type="fixed">
    <origin
      xyz="-0.0059104 0 0.039847"
      rpy="0 0 0" />
    <parent
      link="right_hand_pinky_link2" />
    <child
      link="right_hand_pinkyback_link2" />
    <axis
      xyz="0 0 0" />
    <dynamics
      damping="0"
      friction="0" />
  </joint>
  <link
    name="right_hand_pinky_tip">
    <inertial>
      <origin
        xyz="-6.93889390390723E-18 -3.22658566531686E-15 5.55111512312578E-17"
        rpy="0 0 0" />
      <mass
        value="0.0001" />
      <inertia
        ixx="0.00000000001"
        ixy="0"
        ixz="0"
        iyy="0.00000000001"
        iyz="0"
        izz="0.00000000001" />
    </inertial>
    <visual>
      <origin
        xyz="0 0 0"
        rpy="0 0 0" />
      <geometry>
        <mesh
          filename="../../meshes/rewr1_1/right_hand_pinky_tip.STL" />
      </geometry>
      <material
        name="">
        <color
          rgba="0.988235294117647 0.737254901960784 0.517647058823529 1" />
      </material>
    </visual>
    <collision>
      <origin
        xyz="0 0 0"
        rpy="0 0 0" />
      <geometry>
        <mesh
          filename="../../meshes/rewr1_1/right_hand_pinky_tip.STL" />
      </geometry>
    </collision>
  </link>
  <joint
    name="right_hand_pinky_joint3"
    type="fixed">
    <origin
      xyz="-0.0059104 0 0.039847"
      rpy="0 0 0" />
    <parent
      link="right_hand_pinky_link2" />
    <child
      link="right_hand_pinky_tip" />
    <axis
      xyz="0 0 0" />
    <dynamics
      damping="0"
      friction="0" />
  </joint>








  <link
    name="left_hand_link">
    <inertial>
      <origin
        xyz="0.00031343 -0.00062202 0.07648588"
        rpy="0 0 0" />
      <mass
        value="0.48583147" />
      <inertia
        ixx="0.00080025"
        ixy="0.00000115"
        ixz="0.00003365"
        iyy="0.00063039"
        iyz="0.00000404"
        izz="0.00024512" />
    </inertial>
    <visual>
      <origin
        xyz="0 0 0"
        rpy="0 0 0" />
      <geometry>
        <mesh
          filename="../../meshes/rewr1_1/left_hand_link.STL" />
      </geometry>
      <material
        name="">
        <color
          rgba="0.698039215686274 0.698039215686274 0.698039215686274 1" />
      </material>
    </visual>
    <collision>
      <origin
        xyz="0 0 0"
        rpy="0 0 0" />
      <geometry>
        <mesh
          filename="../../meshes/rewr1_1/left_hand_link.STL" />
      </geometry>
    </collision>
  </link>






  <joint
    name="left_hand_joint"
    type="fixed">
    <origin
      xyz="0 0 0"
      rpy="0 0 1.57" />
    <parent
      link="left_arm_flange_link" />
    <child
      link="left_hand_link" />
    <axis
      xyz="0 0 0" />
  </joint>









  <link
    name="left_hand_light_link">
    <inertial>
      <origin
        xyz="-0.0174738563209964 -0.000279154025753265 -0.0198116123298085"
        rpy="0 0 0" />
      <mass
        value="0.0001" />
      <inertia
        ixx="0.00000000001"
        ixy="0"
        ixz="0"
        iyy="0.00000000001"
        iyz="0"
        izz="0.00000000001" />
    </inertial>
    <visual>
      <origin
        xyz="0 0 0"
        rpy="0 0 0" />
      <geometry>
        <mesh
          filename="../../meshes/rewr1_1/left_hand_light_link.STL" />
      </geometry>
      <material
        name="">
        <color
          rgba="0.698039215686274 0.698039215686274 0.698039215686274 1" />
      </material>
    </visual>
    <collision>
      <origin
        xyz="0 0 0"
        rpy="0 0 0" />
      <geometry>
        <mesh
          filename="../../meshes/rewr1_1/left_hand_light_link.STL" />
      </geometry>
    </collision>
  </link>
  <joint
    name="left_hand_light_joint"
    type="fixed">
    <origin
      xyz="0 0 0.06"
      rpy="0 0 0" />
    <parent
      link="left_hand_link" />
    <child
      link="left_hand_light_link" />
    <axis
      xyz="0 0 0" />
    <dynamics
      damping="0"
      friction="0" />
  </joint>
  <link
    name="left_hand_dorsum_link">
    <inertial>
      <origin
        xyz="-0.0140610771658481 -0.000854284665520327 0.0200216047104443"
        rpy="0 0 0" />
      <mass
        value="0.0001" />
      <inertia
        ixx="0.00000000001"
        ixy="0"
        ixz="0"
        iyy="0.00000000001"
        iyz="0"
        izz="0.00000000001" />
    </inertial>
    <visual>
      <origin
        xyz="0 0 0"
        rpy="0 0 0" />
      <geometry>
        <mesh
          filename="../../meshes/rewr1_1/left_hand_dorsum_link.STL" />
      </geometry>
      <material
        name="">
        <color
          rgba="0.698039215686274 0.698039215686274 0.698039215686274 1" />
      </material>
    </visual>
    <collision>
      <origin
        xyz="0 0 0"
        rpy="0 0 0" />
      <geometry>
        <mesh
          filename="../../meshes/rewr1_1/left_hand_dorsum_link.STL" />
      </geometry>
    </collision>
  </link>
  <joint
    name="left_hand_dorsum_joint"
    type="fixed">
    <origin
      xyz="0 0 0.06"
      rpy="0 0 0" />
    <parent
      link="left_hand_link" />
    <child
      link="left_hand_dorsum_link" />
    <axis
      xyz="0 0 0" />
    <dynamics
      damping="0"
      friction="0" />
  </joint>
  <link
    name="left_hand_palm_link">
    <inertial>
      <origin
        xyz="0.00769330542998632 -0.00103281202775335 0.0243505442723289"
        rpy="0 0 0" />
      <mass
        value="0.0001" />
      <inertia
        ixx="0.00000000001"
        ixy="0"
        ixz="0"
        iyy="0.00000000001"
        iyz="0"
        izz="0.00000000001" />
    </inertial>
    <visual>
      <origin
        xyz="0 0 0"
        rpy="0 0 0" />
      <geometry>
        <mesh
          filename="../../meshes/rewr1_1/left_hand_palm_link.STL" />
      </geometry>
      <material
        name="">
        <color
          rgba="0.698039215686274 0.698039215686274 0.698039215686274 1" />
      </material>
    </visual>
    <collision>
      <origin
        xyz="0 0 0"
        rpy="0 0 0" />
      <geometry>
        <mesh
          filename="../../meshes/rewr1_1/left_hand_palm_link.STL" />
      </geometry>
    </collision>
  </link>
  <joint
    name="left_hand_palm_joint"
    type="fixed">
    <origin
      xyz="0 0 0.06"
      rpy="0 0 0" />
    <parent
      link="left_hand_link" />
    <child
      link="left_hand_palm_link" />
    <axis
      xyz="0 0 0" />
    <dynamics
      damping="0"
      friction="0" />
  </joint>
  <link
    name="left_hand_thumb_bend_link">
    <inertial>
      <origin
        xyz="-0.000597616519015937 -0.0130399974912147 -2.46958592461516E-05"
        rpy="0 0 0" />
      <mass
        value="0.01310386" />
      <inertia
        ixx="0.00000185"
        ixy="-0.00000003"
        ixz="0.00000002"
        iyy="0.00000093"
        iyz="-0.00000001"
        izz="0.00000154" />
    </inertial>
    <visual>
      <origin
        xyz="0 0 0"
        rpy="0 0 0" />
      <geometry>
        <mesh
          filename="../../meshes/rewr1_1/left_hand_thumb_bend_link.STL" />
      </geometry>
      <material
        name="">
        <color
          rgba="0.698039215686274 0.698039215686274 0.698039215686274 1" />
      </material>
    </visual>
    <collision>
      <origin
        xyz="0 0 0"
        rpy="0 0 0" />
      <geometry>
        <mesh
          filename="../../meshes/rewr1_1/left_hand_thumb_bend_link.STL" />
      </geometry>
    </collision>
  </link>
  <joint
    name="left_hand_thumb_bend_joint"
    type="revolute">
    <origin
      xyz="0.0110000000000005 -0.0260604621844767 0.0476679820626826"
      rpy="-0.174532925199437 0 0" />
    <parent
      link="left_hand_link" />
    <child
      link="left_hand_thumb_bend_link" />
    <axis
      xyz="0 0 1" />
    <limit
      lower="0"
      upper="1.919"
      effort="1.1"
      velocity="8.63" />
    <dynamics
      damping="0"
      friction="0" />
  </joint>
  <link
    name="left_hand_thumb_rota_link1">
    <inertial>
      <origin
        xyz="4.75827577802231E-05 -0.0199703400176883 0.00592157006335431"
        rpy="0 0 0" />
      <mass
        value="0.07256165" />
      <inertia
        ixx="0.00001937"
        ixy="-0.00000001"
        ixz="0.00000001"
        iyy="0.00000549"
        iyz="0.00000274"
        izz="0.00001865" />
    </inertial>
    <visual>
      <origin
        xyz="0 0 0"
        rpy="0 0 0" />
      <geometry>
        <mesh
          filename="../../meshes/rewr1_1/left_hand_thumb_rota_link1.STL" />
      </geometry>
      <material
        name="">
        <color
          rgba="0.698039215686274 0.698039215686274 0.698039215686274 1" />
      </material>
    </visual>
    <collision>
      <origin
        xyz="0 0 0"
        rpy="0 0 0" />
      <geometry>
        <mesh
          filename="../../meshes/rewr1_1/left_hand_thumb_rota_link1.STL" />
      </geometry>
    </collision>
  </link>
  <joint
    name="left_hand_thumb_rota_joint1"
    type="revolute">
    <origin
      xyz="-0.000567852978880588 -0.0290602454068191 -0.00185316712450968"
      rpy="0.180694118078096 0.261799387799156 0.0207106059106637" />
    <parent
      link="left_hand_thumb_bend_link" />
    <child
      link="left_hand_thumb_rota_link1" />
    <axis
      xyz="-1 0 0" />
    <limit
      lower="0"
      upper="1.291"
      effort="1.1"
      velocity="8.63" />
    <dynamics
      damping="0"
      friction="0" />
  </joint>
  <link
    name="left_hand_thumb_rotaback_link1">
    <inertial>
      <origin
        xyz="1.94814817654557E-07 0.0202577373917579 -0.0207570478391004"
        rpy="0 0 0" />
      <mass
        value="0.0001" />
      <inertia
        ixx="0.00000000001"
        ixy="0"
        ixz="0"
        iyy="0.00000000001"
        iyz="0"
        izz="0.00000000001" />
    </inertial>
    <visual>
      <origin
        xyz="0 0 0"
        rpy="0 0 0" />
      <geometry>
        <mesh
          filename="../../meshes/rewr1_1/left_hand_thumb_rotaback_link1.STL" />
      </geometry>
      <material
        name="">
        <color
          rgba="0.698039215686274 0.698039215686274 0.698039215686274 1" />
      </material>
    </visual>
    <collision>
      <origin
        xyz="0 0 0"
        rpy="0 0 0" />
      <geometry>
        <mesh
          filename="../../meshes/rewr1_1/left_hand_thumb_rotaback_link1.STL" />
      </geometry>
    </collision>
  </link>
  <joint
    name="left_hand_thumb_rotaback_joint1"
    type="fixed">
    <origin
      xyz="0 -0.0476373076621294 0.017089243260701"
      rpy="0 0 0" />
    <parent
      link="left_hand_thumb_rota_link1" />
    <child
      link="left_hand_thumb_rotaback_link1" />
    <axis
      xyz="0 0 0" />
    <dynamics
      damping="0"
      friction="0" />
  </joint>
  <link
    name="left_hand_thumb_rota_link2">
    <inertial>
      <origin
        xyz="-7.56909790549515E-07 -0.0125680180198914 0.00753636626131848"
        rpy="0 0 0" />
      <mass
        value="0.01140186" />
      <inertia
        ixx="0.00000172"
        ixy="0"
        ixz="0"
        iyy="0.00000146"
        iyz="0.0000005"
        izz="0.00000117" />
    </inertial>
    <visual>
      <origin
        xyz="0 0 0"
        rpy="0 0 0" />
      <geometry>
        <mesh
          filename="../../meshes/rewr1_1/left_hand_thumb_rota_link2.STL" />
      </geometry>
      <material
        name="">
        <color
          rgba="0.698039215686274 0.698039215686274 0.698039215686274 1" />
      </material>
    </visual>
    <collision>
      <origin
        xyz="0 0 0"
        rpy="0 0 0" />
      <geometry>
        <mesh
          filename="../../meshes/rewr1_1/left_hand_thumb_rota_link2.STL" />
      </geometry>
    </collision>
  </link>
  <joint
    name="left_hand_thumb_rota_joint2"
    type="revolute">
    <origin
      xyz="0 -0.047637 0.017089"
      rpy="0 0 0" />
    <parent
      link="left_hand_thumb_rota_link1" />
    <child
      link="left_hand_thumb_rota_link2" />
    <axis
      xyz="-1 0 0" />
    <limit
      lower="0"
      upper="0.995"
      effort="1.1"
      velocity="8.63" />
    <dynamics
      damping="0"
      friction="0" />
  </joint>
  <link
    name="left_hand_thumb_rotaback_link2">
    <inertial>
      <origin
        xyz="-1.12424451327066E-06 0.0185421901503342 -0.0207600804272649"
        rpy="0 0 0" />
      <mass
        value="0.0001" />
      <inertia
        ixx="0.00000000001"
        ixy="0"
        ixz="0"
        iyy="0.00000000001"
        iyz="0"
        izz="0.00000000001" />
    </inertial>
    <visual>
      <origin
        xyz="0 0 0"
        rpy="0 0 0" />
      <geometry>
        <mesh
          filename="../../meshes/rewr1_1/left_hand_thumb_rotaback_link2.STL" />
      </geometry>
      <material
        name="">
        <color
          rgba="0.698039215686274 0.698039215686274 0.698039215686274 1" />
      </material>
    </visual>
    <collision>
      <origin
        xyz="0 0 0"
        rpy="0 0 0" />
      <geometry>
        <mesh
          filename="../../meshes/rewr1_1/left_hand_thumb_rotaback_link2.STL" />
      </geometry>
    </collision>
  </link>
  <joint
    name="left_hand_thumb_rotaback_joint2"
    type="fixed">
    <origin
      xyz="0 -0.031299 0.016202"
      rpy="0 0 0" />
    <parent
      link="left_hand_thumb_rota_link2" />
    <child
      link="left_hand_thumb_rotaback_link2" />
    <axis
      xyz="0 0 0" />
    <dynamics
      damping="0"
      friction="0" />
  </joint>
  <link
    name="left_hand_thumb_rota_tip">
    <inertial>
      <origin
        xyz="6.86950496486816E-15 1.47104550762833E-15 1.27675647831893E-15"
        rpy="0 0 0" />
      <mass
        value="0.0001" />
      <inertia
        ixx="0.00000000001"
        ixy="0"
        ixz="0"
        iyy="0.00000000001"
        iyz="0"
        izz="0.00000000001" />
    </inertial>
    <visual>
      <origin
        xyz="0 0 0"
        rpy="0 0 0" />
      <geometry>
        <mesh
          filename="../../meshes/rewr1_1/left_hand_thumb_rota_tip.STL" />
      </geometry>
      <material
        name="">
        <color
          rgba="0.988235294117647 0.737254901960784 0.517647058823529 1" />
      </material>
    </visual>
    <collision>
      <origin
        xyz="0 0 0"
        rpy="0 0 0" />
      <geometry>
        <mesh
          filename="../../meshes/rewr1_1/left_hand_thumb_rota_tip.STL" />
      </geometry>
    </collision>
  </link>
  <joint
    name="left_hand_thumb_rota_joint3"
    type="fixed">
    <origin
      xyz="0 -0.0312989190300074 0.0162020883701156"
      rpy="0 0 0" />
    <parent
      link="left_hand_thumb_rota_link2" />
    <child
      link="left_hand_thumb_rota_tip" />
    <axis
      xyz="0 0 0" />
    <dynamics
      damping="0"
      friction="0" />
  </joint>
  <link
    name="left_hand_index_rota_link1">
    <inertial>
      <origin
        xyz="0.00525903644348067 -8.29823749195421E-05 0.0217065867445151"
        rpy="0 0 0" />
      <mass
        value="0.00783143" />
      <inertia
        ixx="0.00000125"
        ixy="0"
        ixz="-0.00000005"
        iyy="0.0000012"
        iyz="-0.00000003"
        izz="0.00000047" />
    </inertial>
    <visual>
      <origin
        xyz="0 0 0"
        rpy="0 0 0" />
      <geometry>
        <mesh
          filename="../../meshes/rewr1_1/left_hand_index_rota_link1.STL" />
      </geometry>
      <material
        name="">
        <color
          rgba="0.698039215686274 0.698039215686274 0.698039215686274 1" />
      </material>
    </visual>
    <collision>
      <origin
        xyz="0 0 0"
        rpy="0 0 0" />
      <geometry>
        <mesh
          filename="../../meshes/rewr1_1/left_hand_index_rota_link1.STL" />
      </geometry>
    </collision>
  </link>
  <joint
    name="left_hand_index_rota_joint1"
    type="revolute">
    <origin
      xyz="-0.001 -0.029 0.1228"
      rpy="0 0 0" />
    <parent
      link="left_hand_link" />
    <child
      link="left_hand_index_rota_link1" />
    <axis
      xyz="0 1 0" />
    <limit
      lower="0"
      upper="1.483"
      effort="1.1"
      velocity="8.63" />
    <dynamics
      damping="0"
      friction="0" />
  </joint>
  <link
    name="left_hand_index_rotaback_link1">
    <inertial>
      <origin
        xyz="-0.00885840310869083 -0.000333466522424296 -0.0209216594507088"
        rpy="0 0 0" />
      <mass
        value="0.0001" />
      <inertia
        ixx="0.00000000001"
        ixy="0"
        ixz="0"
        iyy="0.00000000001"
        iyz="0"
        izz="0.00000000001" />
    </inertial>
    <visual>
      <origin
        xyz="0 0 0"
        rpy="0 0 0" />
      <geometry>
        <mesh
          filename="../../meshes/rewr1_1/left_hand_index_rotaback_link1.STL" />
      </geometry>
      <material
        name="">
        <color
          rgba="0.698039215686274 0.698039215686274 0.698039215686274 1" />
      </material>
    </visual>
    <collision>
      <origin
        xyz="0 0 0"
        rpy="0 0 0" />
      <geometry>
        <mesh
          filename="../../meshes/rewr1_1/left_hand_index_rotaback_link1.STL" />
      </geometry>
    </collision>
  </link>
  <joint
    name="left_hand_index_rotaback_joint1"
    type="fixed">
    <origin
      xyz="0.00559923231216017 0 0.0318346069162864"
      rpy="0 0 0" />
    <parent
      link="left_hand_index_rota_link1" />
    <child
      link="left_hand_index_rotaback_link1" />
    <axis
      xyz="0 0 0" />
    <dynamics
      damping="0"
      friction="0" />
  </joint>
  <link
    name="left_hand_index_rota_link2">
    <inertial>
      <origin
        xyz="-0.00102030585762565 1.53218688431211E-08 0.022633068390612"
        rpy="0 0 0" />
      <mass
        value="0.01179339" />
      <inertia
        ixx="0.00000227"
        ixy="0"
        ixz="-0.00000018"
        iyy="0.0000023"
        iyz="0"
        izz="0.00000025" />
    </inertial>
    <visual>
      <origin
        xyz="0 0 0"
        rpy="0 0 0" />
      <geometry>
        <mesh
          filename="../../meshes/rewr1_1/left_hand_index_rota_link2.STL" />
      </geometry>
      <material
        name="">
        <color
          rgba="0.698039215686274 0.698039215686274 0.698039215686274 1" />
      </material>
    </visual>
    <collision>
      <origin
        xyz="0 0 0"
        rpy="0 0 0" />
      <geometry>
        <mesh
          filename="../../meshes/rewr1_1/left_hand_index_rota_link2.STL" />
      </geometry>
    </collision>
  </link>
  <joint
    name="left_hand_index_rota_joint2"
    type="revolute">
    <origin
      xyz="0.00559923231216017 0 0.0318346069162864"
      rpy="0 0 0" />
    <parent
      link="left_hand_index_rota_link1" />
    <child
      link="left_hand_index_rota_link2" />
    <axis
      xyz="0 1 0" />
    <limit
      lower="0"
      upper="1.919"
      effort="1.1"
      velocity="8.63" />
    <dynamics
      damping="0"
      friction="0" />
  </joint>
  <link
    name="left_hand_index_rotaback_link2">
    <inertial>
      <origin
        xyz="-0.00305488876217329 -1.26530987214213E-06 -0.0293382053802545"
        rpy="0 0 0" />
      <mass
        value="0.0001" />
      <inertia
        ixx="0.00000000001"
        ixy="0"
        ixz="0"
        iyy="0.00000000001"
        iyz="0"
        izz="0.00000000001" />
    </inertial>
    <visual>
      <origin
        xyz="0 0 0"
        rpy="0 0 0" />
      <geometry>
        <mesh
          filename="../../meshes/rewr1_1/left_hand_index_rotaback_link2.STL" />
      </geometry>
      <material
        name="">
        <color
          rgba="0.698039215686274 0.698039215686274 0.698039215686274 1" />
      </material>
    </visual>
    <collision>
      <origin
        xyz="0 0 0"
        rpy="0 0 0" />
      <geometry>
        <mesh
          filename="../../meshes/rewr1_1/left_hand_index_rotaback_link2.STL" />
      </geometry>
    </collision>
  </link>
  <joint
    name="left_hand_index_rotaback_joint2"
    type="fixed">
    <origin
      xyz="-0.00285920316139965 0 0.0458891753290683"
      rpy="0 0 0" />
    <parent
      link="left_hand_index_rota_link2" />
    <child
      link="left_hand_index_rotaback_link2" />
    <axis
      xyz="0 0 0" />
    <dynamics
      damping="0"
      friction="0" />
  </joint>
  <link
    name="left_hand_index_rota_tip">
    <inertial>
      <origin
        xyz="0 -3.15025783237388E-15 -2.77555756156289E-17"
        rpy="0 0 0" />
      <mass
        value="0.0001" />
      <inertia
        ixx="0.00000000001"
        ixy="0"
        ixz="0"
        iyy="0.00000000001"
        iyz="0"
        izz="0.00000000001" />
    </inertial>
    <visual>
      <origin
        xyz="0 0 0"
        rpy="0 0 0" />
      <geometry>
        <mesh
          filename="../../meshes/rewr1_1/left_hand_index_rota_tip.STL" />
      </geometry>
      <material
        name="">
        <color
          rgba="0.988235294117647 0.737254901960784 0.517647058823529 1" />
      </material>
    </visual>
    <collision>
      <origin
        xyz="0 0 0"
        rpy="0 0 0" />
      <geometry>
        <mesh
          filename="../../meshes/rewr1_1/left_hand_index_rota_tip.STL" />
      </geometry>
    </collision>
  </link>
  <joint
    name="left_hand_index_rota_joint3"
    type="fixed">
    <origin
      xyz="-0.00285920316139965 0 0.0458891753290683"
      rpy="0 0 0" />
    <parent
      link="left_hand_index_rota_link2" />
    <child
      link="left_hand_index_rota_tip" />
    <axis
      xyz="0 0 0" />
    <dynamics
      damping="0"
      friction="0" />
  </joint>
  <link
    name="left_hand_mid_link1">
    <inertial>
      <origin
        xyz="0.00518323487255029 -8.29857402489011E-05 0.0217248027570402"
        rpy="0 0 0" />
      <mass
        value="0.00783143" />
      <inertia
        ixx="0.00000125"
        ixy="0"
        ixz="-0.00000005"
        iyy="0.0000012"
        iyz="-0.00000003"
        izz="0.00000047" />
    </inertial>
    <visual>
      <origin
        xyz="0 0 0"
        rpy="0 0 0" />
      <geometry>
        <mesh
          filename="../../meshes/rewr1_1/left_hand_mid_link1.STL" />
      </geometry>
      <material
        name="">
        <color
          rgba="0.698039215686274 0.698039215686274 0.698039215686274 1" />
      </material>
    </visual>
    <collision>
      <origin
        xyz="0 0 0"
        rpy="0 0 0" />
      <geometry>
        <mesh
          filename="../../meshes/rewr1_1/left_hand_mid_link1.STL" />
      </geometry>
    </collision>
  </link>
  <joint
    name="left_hand_mid_joint1"
    type="revolute">
    <origin
      xyz="-0.001 -0.01 0.1248"
      rpy="0 0 0" />
    <parent
      link="left_hand_link" />
    <child
      link="left_hand_mid_link1" />
    <axis
      xyz="0 1 0" />
    <limit
      lower="0"
      upper="1.483"
      effort="1.1"
      velocity="8.63" />
    <dynamics
      damping="0"
      friction="0" />
  </joint>
  <link
    name="left_hand_midback_link1">
    <inertial>
      <origin
        xyz="-0.00878538154415416 -0.000333272397289077 -0.0209529104920184"
        rpy="0 0 0" />
      <mass
        value="0.0001" />
      <inertia
        ixx="0.00000000001"
        ixy="0"
        ixz="0"
        iyy="0.00000000001"
        iyz="0"
        izz="0.00000000001" />
    </inertial>
    <visual>
      <origin
        xyz="0 0 0"
        rpy="0 0 0" />
      <geometry>
        <mesh
          filename="../../meshes/rewr1_1/left_hand_midback_link1.STL" />
      </geometry>
      <material
        name="">
        <color
          rgba="0.698039215686274 0.698039215686274 0.698039215686274 1" />
      </material>
    </visual>
    <collision>
      <origin
        xyz="0 0 0"
        rpy="0 0 0" />
      <geometry>
        <mesh
          filename="../../meshes/rewr1_1/left_hand_midback_link1.STL" />
      </geometry>
    </collision>
  </link>
  <joint
    name="left_hand_midback_joint1"
    type="fixed">
    <origin
      xyz="0.00548807468403523 0 0.0318539579371615"
      rpy="0 0 0" />
    <parent
      link="left_hand_mid_link1" />
    <child
      link="left_hand_midback_link1" />
    <axis
      xyz="0 0 0" />
    <dynamics
      damping="0"
      friction="0" />
  </joint>
  <link
    name="left_hand_mid_link2">
    <inertial>
      <origin
        xyz="-0.000833622758662209 1.97150380222555E-07 0.0252943324554426"
        rpy="0 0 0" />
      <mass
        value="0.01329645" />
      <inertia
        ixx="0.00000307"
        ixy="0"
        ixz="-0.00000023"
        iyy="0.00000311"
        iyz="0"
        izz="0.00000029" />
    </inertial>
    <visual>
      <origin
        xyz="0 0 0"
        rpy="0 0 0" />
      <geometry>
        <mesh
          filename="../../meshes/rewr1_1/left_hand_mid_link2.STL" />
      </geometry>
      <material
        name="">
        <color
          rgba="0.698039215686274 0.698039215686274 0.698039215686274 1" />
      </material>
    </visual>
    <collision>
      <origin
        xyz="0 0 0"
        rpy="0 0 0" />
      <geometry>
        <mesh
          filename="../../meshes/rewr1_1/left_hand_mid_link2.STL" />
      </geometry>
    </collision>
  </link>
  <joint
    name="left_hand_mid_joint2"
    type="revolute">
    <origin
      xyz="0.00548807468403523 0 0.0318539579371615"
      rpy="0 0 0" />
    <parent
      link="left_hand_mid_link1" />
    <child
      link="left_hand_mid_link2" />
    <axis
      xyz="0 1 0" />
    <limit
      lower="0"
      upper="1.919"
      effort="1.1"
      velocity="8.63" />
    <dynamics
      damping="0"
      friction="0" />
  </joint>
  <link
    name="left_hand_midback_link2">
    <inertial>
      <origin
        xyz="-0.00250519041366765 -1.13801021391254E-06 -0.0321618549557232"
        rpy="0 0 0" />
      <mass
        value="0.0001" />
      <inertia
        ixx="0.00000000001"
        ixy="0"
        ixz="0"
        iyy="0.00000000001"
        iyz="0"
        izz="0.00000000001" />
    </inertial>
    <visual>
      <origin
        xyz="0 0 0"
        rpy="0 0 0" />
      <geometry>
        <mesh
          filename="../../meshes/rewr1_1/left_hand_midback_link2.STL" />
      </geometry>
      <material
        name="">
        <color
          rgba="0.698039215686274 0.698039215686274 0.698039215686274 1" />
      </material>
    </visual>
    <collision>
      <origin
        xyz="0 0 0"
        rpy="0 0 0" />
      <geometry>
        <mesh
          filename="../../meshes/rewr1_1/left_hand_midback_link2.STL" />
      </geometry>
    </collision>
  </link>
  <joint
    name="left_hand_midback_joint2"
    type="fixed">
    <origin
      xyz="-0.00331112647710495 0 0.0512921461779707"
      rpy="0 0 0" />
    <parent
      link="left_hand_mid_link2" />
    <child
      link="left_hand_midback_link2" />
    <axis
      xyz="0 0 0" />
    <dynamics
      damping="0"
      friction="0" />
  </joint>
  <link
    name="left_hand_mid_tip">
    <inertial>
      <origin
        xyz="-1.58293517182884E-17 -2.0643209364124E-15 2.77555756156289E-17"
        rpy="0 0 0" />
      <mass
        value="0.0001" />
      <inertia
        ixx="0.00000000001"
        ixy="0"
        ixz="0"
        iyy="0.00000000001"
        iyz="0"
        izz="0.00000000001" />
    </inertial>
    <visual>
      <origin
        xyz="0 0 0"
        rpy="0 0 0" />
      <geometry>
        <mesh
          filename="../../meshes/rewr1_1/left_hand_mid_tip.STL" />
      </geometry>
      <material
        name="">
        <color
          rgba="0.988235294117647 0.737254901960784 0.517647058823529 1" />
      </material>
    </visual>
    <collision>
      <origin
        xyz="0 0 0"
        rpy="0 0 0" />
      <geometry>
        <mesh
          filename="../../meshes/rewr1_1/left_hand_mid_tip.STL" />
      </geometry>
    </collision>
  </link>
  <joint
    name="left_hand_mid_joint3"
    type="fixed">
    <origin
      xyz="-0.00331112647710495 0 0.0512921461779707"
      rpy="0 0 0" />
    <parent
      link="left_hand_mid_link2" />
    <child
      link="left_hand_mid_tip" />
    <axis
      xyz="0 0 0" />
    <dynamics
      damping="0"
      friction="0" />
  </joint>
  <link
    name="left_hand_ring_link1">
    <inertial>
      <origin
        xyz="0.00525903644346468 -8.29823920398386E-05 0.0217065867237396"
        rpy="0 0 0" />
      <mass
        value="0.00783143" />
      <inertia
        ixx="0.00000125"
        ixy="0"
        ixz="-0.00000005"
        iyy="0.0000012"
        iyz="-0.00000003"
        izz="0.00000047" />
    </inertial>
    <visual>
      <origin
        xyz="0 0 0"
        rpy="0 0 0" />
      <geometry>
        <mesh
          filename="../../meshes/rewr1_1/left_hand_ring_link1.STL" />
      </geometry>
      <material
        name="">
        <color
          rgba="0.698039215686274 0.698039215686274 0.698039215686274 1" />
      </material>
    </visual>
    <collision>
      <origin
        xyz="0 0 0"
        rpy="0 0 0" />
      <geometry>
        <mesh
          filename="../../meshes/rewr1_1/left_hand_ring_link1.STL" />
      </geometry>
    </collision>
  </link>
  <joint
    name="left_hand_ring_joint1"
    type="revolute">
    <origin
      xyz="-0.001 0.009 0.1228"
      rpy="0 0 0" />
    <parent
      link="left_hand_link" />
    <child
      link="left_hand_ring_link1" />
    <axis
      xyz="0 1 0" />
    <limit
      lower="0"
      upper="1.483"
      effort="1.1"
      velocity="8.63" />
    <dynamics
      damping="0"
      friction="0" />
  </joint>
  <link
    name="left_hand_ringback_link1">
    <inertial>
      <origin
        xyz="-0.00885840743682408 -0.000333469389501535 -0.0209216532079816"
        rpy="0 0 0" />
      <mass
        value="0.0001" />
      <inertia
        ixx="0.00000000001"
        ixy="0"
        ixz="0"
        iyy="0.00000000001"
        iyz="0"
        izz="0.00000000001" />
    </inertial>
    <visual>
      <origin
        xyz="0 0 0"
        rpy="0 0 0" />
      <geometry>
        <mesh
          filename="../../meshes/rewr1_1/left_hand_ringback_link1.STL" />
      </geometry>
      <material
        name="">
        <color
          rgba="0.698039215686274 0.698039215686274 0.698039215686274 1" />
      </material>
    </visual>
    <collision>
      <origin
        xyz="0 0 0"
        rpy="0 0 0" />
      <geometry>
        <mesh
          filename="../../meshes/rewr1_1/left_hand_ringback_link1.STL" />
      </geometry>
    </collision>
  </link>
  <joint
    name="left_hand_ringback_joint1"
    type="fixed">
    <origin
      xyz="0.00559923231215986 0 0.0318346069162863"
      rpy="0 0 0" />
    <parent
      link="left_hand_ring_link1" />
    <child
      link="left_hand_ringback_link1" />
    <axis
      xyz="0 0 0" />
    <dynamics
      damping="0"
      friction="0" />
  </joint>
  <link
    name="left_hand_ring_link2">
    <inertial>
      <origin
        xyz="-0.000996603613114529 1.57352231227453E-08 0.0226341248087296"
        rpy="0 0 0" />
      <mass
        value="0.01179339" />
      <inertia
        ixx="0.00000227"
        ixy="0"
        ixz="-0.00000018"
        iyy="0.0000023"
        iyz="0"
        izz="0.00000025" />
    </inertial>
    <visual>
      <origin
        xyz="0 0 0"
        rpy="0 0 0" />
      <geometry>
        <mesh
          filename="../../meshes/rewr1_1/left_hand_ring_link2.STL" />
      </geometry>
      <material
        name="">
        <color
          rgba="0.698039215686274 0.698039215686274 0.698039215686274 1" />
      </material>
    </visual>
    <collision>
      <origin
        xyz="0 0 0"
        rpy="0 0 0" />
      <geometry>
        <mesh
          filename="../../meshes/rewr1_1/left_hand_ring_link2.STL" />
      </geometry>
    </collision>
  </link>
  <joint
    name="left_hand_ring_joint2"
    type="revolute">
    <origin
      xyz="0.00559923231215986 0 0.0318346069162863"
      rpy="0 0 0" />
    <parent
      link="left_hand_ring_link1" />
    <child
      link="left_hand_ring_link2" />
    <axis
      xyz="0 1 0" />
    <limit
      lower="0"
      upper="1.919"
      effort="1.1"
      velocity="8.63" />
    <dynamics
      damping="0"
      friction="0" />
  </joint>
  <link
    name="left_hand_ringback_link2">
    <inertial>
      <origin
        xyz="-0.00308560988865921 -1.26561971207015E-06 -0.0293349913376543"
        rpy="0 0 0" />
      <mass
        value="0.0001" />
      <inertia
        ixx="0.00000000001"
        ixy="0"
        ixz="0"
        iyy="0.00000000001"
        iyz="0"
        izz="0.00000000001" />
    </inertial>
    <visual>
      <origin
        xyz="0 0 0"
        rpy="0 0 0" />
      <geometry>
        <mesh
          filename="../../meshes/rewr1_1/left_hand_ringback_link2.STL" />
      </geometry>
      <material
        name="">
        <color
          rgba="0.698039215686274 0.698039215686274 0.698039215686274 1" />
      </material>
    </visual>
    <collision>
      <origin
        xyz="0 0 0"
        rpy="0 0 0" />
      <geometry>
        <mesh
          filename="../../meshes/rewr1_1/left_hand_ringback_link2.STL" />
      </geometry>
    </collision>
  </link>
  <joint
    name="left_hand_ringback_joint2"
    type="fixed">
    <origin
      xyz="-0.0028111465704212 0 0.0458921443175165"
      rpy="0 0 0" />
    <parent
      link="left_hand_ring_link2" />
    <child
      link="left_hand_ringback_link2" />
    <axis
      xyz="0 0 0" />
    <dynamics
      damping="0"
      friction="0" />
  </joint>
  <link
    name="left_hand_ring_tip">
    <inertial>
      <origin
        xyz="0 -3.02709246557953E-15 0"
        rpy="0 0 0" />
      <mass
        value="0.0001" />
      <inertia
        ixx="0.00000000001"
        ixy="0"
        ixz="0"
        iyy="0.00000000001"
        iyz="0"
        izz="0.00000000001" />
    </inertial>
    <visual>
      <origin
        xyz="0 0 0"
        rpy="0 0 0" />
      <geometry>
        <mesh
          filename="../../meshes/rewr1_1/left_hand_ring_tip.STL" />
      </geometry>
      <material
        name="">
        <color
          rgba="0.988235294117647 0.737254901960784 0.517647058823529 1" />
      </material>
    </visual>
    <collision>
      <origin
        xyz="0 0 0"
        rpy="0 0 0" />
      <geometry>
        <mesh
          filename="../../meshes/rewr1_1/left_hand_ring_tip.STL" />
      </geometry>
    </collision>
  </link>
  <joint
    name="left_hand_ring_joint3"
    type="fixed">
    <origin
      xyz="-0.0028111465704212 0 0.0458921443175165"
      rpy="0 0 0" />
    <parent
      link="left_hand_ring_link2" />
    <child
      link="left_hand_ring_tip" />
    <axis
      xyz="0 0 0" />
    <dynamics
      damping="0"
      friction="0" />
  </joint>
  <link
    name="left_hand_pinky_link1">
    <inertial>
      <origin
        xyz="0.00518323483748218 -8.29857400051516E-05 0.0217248027077089"
        rpy="0 0 0" />
      <mass
        value="0.00783143" />
      <inertia
        ixx="0.00000125"
        ixy="0"
        ixz="-0.00000005"
        iyy="0.0000012"
        iyz="-0.00000003"
        izz="0.00000047" />
    </inertial>
    <visual>
      <origin
        xyz="0 0 0"
        rpy="0 0 0" />
      <geometry>
        <mesh
          filename="../../meshes/rewr1_1/left_hand_pinky_link1.STL" />
      </geometry>
      <material
        name="">
        <color
          rgba="0.698039215686274 0.698039215686274 0.698039215686274 1" />
      </material>
    </visual>
    <collision>
      <origin
        xyz="0 0 0"
        rpy="0 0 0" />
      <geometry>
        <mesh
          filename="../../meshes/rewr1_1/left_hand_pinky_link1.STL" />
      </geometry>
    </collision>
  </link>
  <joint
    name="left_hand_pinky_joint1"
    type="revolute">
    <origin
      xyz="-0.000999999999997922 0.0279999999999996 0.120799999999999"
      rpy="0 0 0" />
    <parent
      link="left_hand_link" />
    <child
      link="left_hand_pinky_link1" />
    <axis
      xyz="0 1 0" />
    <limit
      lower="0"
      upper="1.483"
      effort="1.1"
      velocity="8.63" />
    <dynamics
      damping="0"
      friction="0" />
  </joint>
  <link
    name="left_hand_pinkyback_link1">
    <inertial>
      <origin
        xyz="-0.00878538153537525 -0.00033327242369775 -0.0209529104353413"
        rpy="0 0 0" />
      <mass
        value="0.0001" />
      <inertia
        ixx="0.00000000001"
        ixy="0"
        ixz="0"
        iyy="0.00000000001"
        iyz="0"
        izz="0.00000000001" />
    </inertial>
    <visual>
      <origin
        xyz="0 0 0"
        rpy="0 0 0" />
      <geometry>
        <mesh
          filename="../../meshes/rewr1_1/left_hand_pinkyback_link1.STL" />
      </geometry>
      <material
        name="">
        <color
          rgba="0.698039215686274 0.698039215686274 0.698039215686274 1" />
      </material>
    </visual>
    <collision>
      <origin
        xyz="0 0 0"
        rpy="0 0 0" />
      <geometry>
        <mesh
          filename="../../meshes/rewr1_1/left_hand_pinkyback_link1.STL" />
      </geometry>
    </collision>
  </link>
  <joint
    name="left_hand_pinkyback_joint1"
    type="fixed">
    <origin
      xyz="0.00548807468403523 0 0.0318539579371614"
      rpy="0 0 0" />
    <parent
      link="left_hand_pinky_link1" />
    <child
      link="left_hand_pinkyback_link1" />
    <axis
      xyz="0 0 0" />
    <dynamics
      damping="0"
      friction="0" />
  </joint>
  <link
    name="left_hand_pinky_link2">
    <inertial>
      <origin
        xyz="-0.00124660691106412 1.97291509983211E-07 0.0198996622045618"
        rpy="0 0 0" />
      <mass
        value="0.00959828" />
      <inertia
        ixx="0.00000148"
        ixy="0"
        ixz="-0.00000012"
        iyy="0.00000152"
        iyz="0"
        izz="0.00000020" />
    </inertial>
    <visual>
      <origin
        xyz="0 0 0"
        rpy="0 0 0" />
      <geometry>
        <mesh
          filename="../../meshes/rewr1_1/left_hand_pinky_link2.STL" />
      </geometry>
      <material
        name="">
        <color
          rgba="0.698039215686274 0.698039215686274 0.698039215686274 1" />
      </material>
    </visual>
    <collision>
      <origin
        xyz="0 0 0"
        rpy="0 0 0" />
      <geometry>
        <mesh
          filename="../../meshes/rewr1_1/left_hand_pinky_link2.STL" />
      </geometry>
    </collision>
  </link>
  <joint
    name="left_hand_pinky_joint2"
    type="revolute">
    <origin
      xyz="0.00548807468403523 0 0.0318539579371614"
      rpy="0 0 0" />
    <parent
      link="left_hand_pinky_link1" />
    <child
      link="left_hand_pinky_link2" />
    <axis
      xyz="0 1 0" />
    <limit
      lower="0"
      upper="1.919"
      effort="1.1"
      velocity="8.63" />
    <dynamics
      damping="0"
      friction="0" />
  </joint>
  <link
    name="left_hand_pinkyback_link2">
    <inertial>
      <origin
        xyz="-0.00295016852528958 -1.45977873131781E-06 -0.0270167564044435"
        rpy="0 0 0" />
      <mass
        value="0.0001" />
      <inertia
        ixx="0.00000000001"
        ixy="0"
        ixz="0"
        iyy="0.00000000001"
        iyz="0"
        izz="0.00000000001" />
    </inertial>
    <visual>
      <origin
        xyz="0 0 0"
        rpy="0 0 0" />
      <geometry>
        <mesh
          filename="../../meshes/rewr1_1/left_hand_pinkyback_link2.STL" />
      </geometry>
      <material
        name="">
        <color
          rgba="0.698039215686274 0.698039215686274 0.698039215686274 1" />
      </material>
    </visual>
    <collision>
      <origin
        xyz="0 0 0"
        rpy="0 0 0" />
      <geometry>
        <mesh
          filename="../../meshes/rewr1_1/left_hand_pinkyback_link2.STL" />
      </geometry>
    </collision>
  </link>
  <joint
    name="left_hand_pinkyback_joint2"
    type="fixed">
    <origin
      xyz="-0.0029902518966349 0 0.0401715068587322"
      rpy="0 0 0" />
    <parent
      link="left_hand_pinky_link2" />
    <child
      link="left_hand_pinkyback_link2" />
    <axis
      xyz="0 0 0" />
    <dynamics
      damping="0"
      friction="0" />
  </joint>
  <link
    name="left_hand_pinky_tip">
    <inertial>
      <origin
        xyz="-1.60461921527855E-17 -2.51187959321442E-15 2.77555756156289E-17"
        rpy="0 0 0" />
      <mass
        value="0.0001" />
      <inertia
        ixx="0.00000000001"
        ixy="0"
        ixz="0"
        iyy="0.00000000001"
        iyz="0"
        izz="0.00000000001" />
    </inertial>
    <visual>
      <origin
        xyz="0 0 0"
        rpy="0 0 0" />
      <geometry>
        <mesh
          filename="../../meshes/rewr1_1/left_hand_pinky_tip.STL" />
      </geometry>
      <material
        name="">
        <color
          rgba="0.988235294117647 0.737254901960784 0.517647058823529 1" />
      </material>
    </visual>
    <collision>
      <origin
        xyz="0 0 0"
        rpy="0 0 0" />
      <geometry>
        <mesh
          filename="../../meshes/rewr1_1/left_hand_pinky_tip.STL" />
      </geometry>
    </collision>
  </link>
  <joint
    name="left_hand_pinky_joint3"
    type="fixed">
    <origin
      xyz="-0.0029902518966349 0 0.0401715068587322"
      rpy="0 0 0" />
    <parent
      link="left_hand_pinky_link2" />
    <child
      link="left_hand_pinky_tip" />
    <axis
      xyz="0 0 0" />
    <dynamics
      damping="0"
      friction="0" />
  </joint>






</robot>