<mujoco model="rewr1_1">
  <compiler angle="radian" meshdir="../../meshes/rewr1_1/" />
  <statistic center="-0.012496 0.000424702 0.622672" extent="1.93611" meansize="0.179951" />

  <visual>
    <scale jointwidth="0.1" framelength="0.3" framewidth="0.01" />
  </visual>
  <default>
    <joint damping="0.0" armature="0.01" stiffness="0.0" limited="true" />
  </default>

  <asset>
    <texture builtin="gradient" height="100" rgb1=".4 .5 .6" rgb2="0 0 0" type="skybox" width="100" />
    <texture builtin="checker" height="100" name="texplane" rgb1="1 1 1" rgb2=".8 .9 1" type="2d" width="100" />
    <material name="MatPlane" reflectance="0.5" texrepeat="1 1" texture="texplane" texuniform="true" />
    <material name="black" rgba="0.25 0.25 0.25 1" shininess="0.2" specular="0.05" />

    <mesh name="base_link" content_type="model/stl" file="base_link.STL"/>
    <mesh name="ankle_link" content_type="model/stl" file="ankle_link.STL"/>
    <mesh name="knee_link" content_type="model/stl" file="knee_link.STL"/>
    <mesh name="hip_link" content_type="model/stl" file="hip_link.STL"/>
    <mesh name="waist_yaw_link" content_type="model/stl" file="waist_yaw_link.STL"/>
    <mesh name="neck_yaw_link" content_type="model/stl" file="neck_yaw_link.STL"/>
    <mesh name="neck_pitch_link" content_type="model/stl" file="neck_pitch_link.STL"/>
    <mesh name="head_rs_link" content_type="model/stl" file="head_rs_link.STL"/>
    <mesh name="left_arm_base_link" content_type="model/stl" file="left_arm_base_link.STL"/>
    <mesh name="left_shoulder_pitch_link" content_type="model/stl" file="left_shoulder_pitch_link.STL"/>
    <mesh name="left_shoulder_roll_link" content_type="model/stl" file="left_shoulder_roll_link.STL"/>
    <mesh name="left_arm_yaw_link" content_type="model/stl" file="left_arm_yaw_link.STL"/>
    <mesh name="left_elbow_pitch_link" content_type="model/stl" file="left_elbow_pitch_link.STL"/>
    <mesh name="left_elbow_yaw_link" content_type="model/stl" file="left_elbow_yaw_link.STL"/>
    <mesh name="left_wrist_pitch_link" content_type="model/stl" file="left_wrist_pitch_link.STL"/>
    <mesh name="left_wrist_roll_link" content_type="model/stl" file="left_wrist_roll_link.STL"/>
    <mesh name="left_arm_flange_link" content_type="model/stl" file="left_arm_flange_link.STL"/>
    <mesh name="left_hand_ee_link" content_type="model/stl" file="left_hand_ee_link.STL"/>
    <mesh name="right_arm_base_link" content_type="model/stl" file="right_arm_base_link.STL"/>
    <mesh name="right_shoulder_pitch_link" content_type="model/stl" file="right_shoulder_pitch_link.STL"/>
    <mesh name="right_shoulder_roll_link" content_type="model/stl" file="right_shoulder_roll_link.STL"/>
    <mesh name="right_arm_yaw_link" content_type="model/stl" file="right_arm_yaw_link.STL"/>
    <mesh name="right_elbow_pitch_link" content_type="model/stl" file="right_elbow_pitch_link.STL"/>
    <mesh name="right_elbow_yaw_link" content_type="model/stl" file="right_elbow_yaw_link.STL"/>
    <mesh name="right_wrist_pitch_link" content_type="model/stl" file="right_wrist_pitch_link.STL"/>
    <mesh name="right_wrist_roll_link" content_type="model/stl" file="right_wrist_roll_link.STL"/>
    <mesh name="right_arm_flange_link" content_type="model/stl" file="right_arm_flange_link.STL"/>
    <mesh name="right_hand_ee_link" content_type="model/stl" file="right_hand_ee_link.STL"/>
    <mesh name="mic_link" content_type="model/stl" file="mic_link.STL"/>
    <mesh name="left_drv_hang_link" content_type="model/stl" file="left_drv_hang_link.STL"/>
    <mesh name="left_drv_wheel_link" content_type="model/stl" file="left_drv_wheel_link.STL"/>
    <mesh name="right_drv_hang_link" content_type="model/stl" file="right_drv_hang_link.STL"/>
    <mesh name="right_drv_wheel_link" content_type="model/stl" file="right_drv_wheel_link.STL"/>
    <mesh name="lidar_link" content_type="model/stl" file="lidar_link.STL"/>
    <mesh name="right_hand_link" content_type="model/stl" file="right_hand_link.STL"/>
    <mesh name="right_hand_light_link" content_type="model/stl" file="right_hand_light_link.STL"/>
    <mesh name="right_hand_dorsum_link" content_type="model/stl" file="right_hand_dorsum_link.STL"/>
    <mesh name="right_hand_palm_link" content_type="model/stl" file="right_hand_palm_link.STL"/>
    <mesh name="right_hand_thumb_bend_link" content_type="model/stl" file="right_hand_thumb_bend_link.STL"/>
    <mesh name="right_hand_thumb_rota_link1" content_type="model/stl" file="right_hand_thumb_rota_link1.STL"/>
    <mesh name="right_hand_thumb_rotaback_link1" content_type="model/stl" file="right_hand_thumb_rotaback_link1.STL"/>
    <mesh name="right_hand_thumb_rota_link2" content_type="model/stl" file="right_hand_thumb_rota_link2.STL"/>
    <mesh name="right_hand_thumb_rotaback_link2" content_type="model/stl" file="right_hand_thumb_rotaback_link2.STL"/>
    <mesh name="right_hand_thumb_rota_tip" content_type="model/stl" file="right_hand_thumb_rota_tip.STL"/>
    <mesh name="right_hand_index_rota_link1" content_type="model/stl" file="right_hand_index_rota_link1.STL"/>
    <mesh name="right_hand_index_rotaback_link1" content_type="model/stl" file="right_hand_index_rotaback_link1.STL"/>
    <mesh name="right_hand_index_rota_link2" content_type="model/stl" file="right_hand_index_rota_link2.STL"/>
    <mesh name="right_hand_index_rotaback_link2" content_type="model/stl" file="right_hand_index_rotaback_link2.STL"/>
    <mesh name="right_hand_index_rota_tip" content_type="model/stl" file="right_hand_index_rota_tip.STL"/>
    <mesh name="right_hand_mid_link1" content_type="model/stl" file="right_hand_mid_link1.STL"/>
    <mesh name="right_hand_midback_link1" content_type="model/stl" file="right_hand_midback_link1.STL"/>
    <mesh name="right_hand_mid_link2" content_type="model/stl" file="right_hand_mid_link2.STL"/>
    <mesh name="right_hand_midback_link2" content_type="model/stl" file="right_hand_midback_link2.STL"/>
    <mesh name="right_hand_mid_tip" content_type="model/stl" file="right_hand_mid_tip.STL"/>
    <mesh name="right_hand_ring_link1" content_type="model/stl" file="right_hand_ring_link1.STL"/>
    <mesh name="right_hand_ringback_link1" content_type="model/stl" file="right_hand_ringback_link1.STL"/>
    <mesh name="right_hand_ring_link2" content_type="model/stl" file="right_hand_ring_link2.STL"/>
    <mesh name="right_hand_ringback_link2" content_type="model/stl" file="right_hand_ringback_link2.STL"/>
    <mesh name="right_hand_ring_tip" content_type="model/stl" file="right_hand_ring_tip.STL"/>
    <mesh name="right_hand_pinky_link1" content_type="model/stl" file="right_hand_pinky_link1.STL"/>
    <mesh name="right_hand_pinkyback_link1" content_type="model/stl" file="right_hand_pinkyback_link1.STL"/>
    <mesh name="right_hand_pinky_link2" content_type="model/stl" file="right_hand_pinky_link2.STL"/>
    <mesh name="right_hand_pinkyback_link2" content_type="model/stl" file="right_hand_pinkyback_link2.STL"/>
    <mesh name="right_hand_pinky_tip" content_type="model/stl" file="right_hand_pinky_tip.STL"/>
    <mesh name="left_hand_link" content_type="model/stl" file="left_hand_link.STL"/>
    <mesh name="left_hand_light_link" content_type="model/stl" file="left_hand_light_link.STL"/>
    <mesh name="left_hand_dorsum_link" content_type="model/stl" file="left_hand_dorsum_link.STL"/>
    <mesh name="left_hand_palm_link" content_type="model/stl" file="left_hand_palm_link.STL"/>
    <mesh name="left_hand_thumb_bend_link" content_type="model/stl" file="left_hand_thumb_bend_link.STL"/>
    <mesh name="left_hand_thumb_rota_link1" content_type="model/stl" file="left_hand_thumb_rota_link1.STL"/>
    <mesh name="left_hand_thumb_rotaback_link1" content_type="model/stl" file="left_hand_thumb_rotaback_link1.STL"/>
    <mesh name="left_hand_thumb_rota_link2" content_type="model/stl" file="left_hand_thumb_rota_link2.STL"/>
    <mesh name="left_hand_thumb_rotaback_link2" content_type="model/stl" file="left_hand_thumb_rotaback_link2.STL"/>
    <mesh name="left_hand_thumb_rota_tip" content_type="model/stl" file="left_hand_thumb_rota_tip.STL"/>
    <mesh name="left_hand_index_rota_link1" content_type="model/stl" file="left_hand_index_rota_link1.STL"/>
    <mesh name="left_hand_index_rotaback_link1" content_type="model/stl" file="left_hand_index_rotaback_link1.STL"/>
    <mesh name="left_hand_index_rota_link2" content_type="model/stl" file="left_hand_index_rota_link2.STL"/>
    <mesh name="left_hand_index_rotaback_link2" content_type="model/stl" file="left_hand_index_rotaback_link2.STL"/>
    <mesh name="left_hand_index_rota_tip" content_type="model/stl" file="left_hand_index_rota_tip.STL"/>
    <mesh name="left_hand_mid_link1" content_type="model/stl" file="left_hand_mid_link1.STL"/>
    <mesh name="left_hand_midback_link1" content_type="model/stl" file="left_hand_midback_link1.STL"/>
    <mesh name="left_hand_mid_link2" content_type="model/stl" file="left_hand_mid_link2.STL"/>
    <mesh name="left_hand_midback_link2" content_type="model/stl" file="left_hand_midback_link2.STL"/>
    <mesh name="left_hand_mid_tip" content_type="model/stl" file="left_hand_mid_tip.STL"/>
    <mesh name="left_hand_ring_link1" content_type="model/stl" file="left_hand_ring_link1.STL"/>
    <mesh name="left_hand_ringback_link1" content_type="model/stl" file="left_hand_ringback_link1.STL"/>
    <mesh name="left_hand_ring_link2" content_type="model/stl" file="left_hand_ring_link2.STL"/>
    <mesh name="left_hand_ringback_link2" content_type="model/stl" file="left_hand_ringback_link2.STL"/>
    <mesh name="left_hand_ring_tip" content_type="model/stl" file="left_hand_ring_tip.STL"/>
    <mesh name="left_hand_pinky_link1" content_type="model/stl" file="left_hand_pinky_link1.STL"/>
    <mesh name="left_hand_pinkyback_link1" content_type="model/stl" file="left_hand_pinkyback_link1.STL"/>
    <mesh name="left_hand_pinky_link2" content_type="model/stl" file="left_hand_pinky_link2.STL"/>
    <mesh name="left_hand_pinkyback_link2" content_type="model/stl" file="left_hand_pinkyback_link2.STL"/>
    <mesh name="left_hand_pinky_tip" content_type="model/stl" file="left_hand_pinky_tip.STL"/>
  </asset>

  <worldbody>
    <geom name="floor" conaffinity="1" condim="3" contype="1" friction="1 .1 .1" group="2" material="MatPlane" pos="0 0 -0.07" size="500 500 0.125" type="plane" />
    <light castshadow="false" cutoff="100" diffuse="1 1 1" dir="-0 0 -1.3" directional="true" exponent="1" pos="0 0 1.3" specular=".1 .1 .1" />
    <body name="base_link" pos="0 0 0">
      <geom type="mesh" contype="0" conaffinity="0" group="1" density="0" rgba="0.79216 0.81961 0.93333 1" mesh="base_link"/>
      <geom type="mesh" rgba="0.79216 0.81961 0.93333 1" mesh="base_link"/>
      <geom pos="0.1875 0.1145 0.1089" quat="1 0 0 0" type="mesh" contype="0" conaffinity="0" group="1" density="0" rgba="0.866667 0.866667 0.890196 1" mesh="lidar_link"/>
      <geom pos="0.1875 0.1145 0.1089" quat="1 0 0 0" type="mesh" rgba="0.866667 0.866667 0.890196 1" mesh="lidar_link"/>
      <body name="ankle_link" pos="-0.085 0 0.155">
        <inertial pos="-0.00047994 0.0023115 0.21619" quat="0.999952 0.000983258 0.00206901 -0.0095169" mass="7.3164" diaginertia="0.290335 0.289321 0.0148842"/>
        <joint name="ankle_joint" pos="0 0 0" axis="0 1 0" range="0 1.61" actuatorfrcrange="-240 240"/>
        <geom type="mesh" contype="0" conaffinity="0" group="1" density="0" rgba="0.69804 0.69804 0.69804 1" mesh="ankle_link"/>
        <geom type="mesh" rgba="0.69804 0.69804 0.69804 1" mesh="ankle_link"/>
        <body name="knee_link" pos="0 0 0.43">
          <inertial pos="0.0026878 0.00070792 0.17911" quat="0.999953 0.00588102 -0.000444847 -0.00766973" mass="2.474" diaginertia="0.0401736 0.0334704 0.011862"/>
          <joint name="knee_joint" pos="0 0 0" axis="0 1 0" range="-2.53 0.52" actuatorfrcrange="-240 240"/>
          <geom type="mesh" contype="0" conaffinity="0" group="1" density="0" rgba="0.69804 0.69804 0.69804 1" mesh="knee_link"/>
          <geom type="mesh" rgba="0.69804 0.69804 0.69804 1" mesh="knee_link"/>
          <body name="hip_link" pos="0 0 0.34">
            <inertial pos="-0.00103764 0.00304417 0.00598232" quat="0.699519 -0.184387 0.0774715 0.686056" mass="3.02067" diaginertia="0.00756354 0.00753781 0.00701269"/>
            <joint name="hip_joint" pos="0 0 0" axis="0 1 0" range="-0.52 1.57" actuatorfrcrange="-240 240"/>
            <geom type="mesh" contype="0" conaffinity="0" group="1" density="0" rgba="1 1 1 1" mesh="hip_link"/>
            <geom type="mesh" rgba="1 1 1 1" mesh="hip_link"/>
            <body name="waist_yaw_link" pos="0 0 0.225">
              <inertial pos="-0.0146592 -0.0427764 0.00363646" quat="0.97422 0.21336 -0.0559128 -0.0474015" mass="5.9292" diaginertia="0.0865131 0.0510595 0.0443781"/>
              <joint name="waist_yaw_joint" pos="0 0 0" axis="0 0 1" range="-1.57 1.57" actuatorfrcrange="-95 95"/>
              <geom type="mesh" contype="0" conaffinity="0" group="1" density="0" rgba="0.86667 0.86667 0.86667 1" mesh="waist_yaw_link"/>
              <geom type="mesh" rgba="0.86667 0.86667 0.86667 1" mesh="waist_yaw_link"/>
              <geom pos="-0.0385 0 0.128" quat="1 0 0 0" type="mesh" contype="0" conaffinity="0" group="1" density="0" rgba="0.86667 0.86667 0.8902 1" mesh="left_arm_base_link"/>
              <geom pos="-0.0385 0 0.128" quat="1 0 0 0" type="mesh" rgba="0.86667 0.86667 0.8902 1" mesh="left_arm_base_link"/>
              <geom pos="-0.0385 0 0.128" quat="1 0 0 0" type="mesh" contype="0" conaffinity="0" group="1" density="0" rgba="0.86667 0.86667 0.8902 1" mesh="right_arm_base_link"/>
              <geom pos="-0.0385 0 0.128" quat="1 0 0 0" type="mesh" rgba="0.86667 0.86667 0.8902 1" mesh="right_arm_base_link"/>
              <geom pos="0.0206233 0 0.147423" quat="-0.127927 0 -0.991784 0" type="mesh" contype="0" conaffinity="0" group="1" density="0" rgba="0.698039 0.698039 0.698039 1" mesh="mic_link"/>
              <geom pos="0.0206233 0 0.147423" quat="-0.127927 0 -0.991784 0" type="mesh" rgba="0.698039 0.698039 0.698039 1" mesh="mic_link"/>
              <body name="neck_yaw_link" pos="-0.042 0 0.217">
                <inertial pos="0.0130712 -0.00282636 0.0574798" quat="0.989189 0.0568118 0.135064 -0.00595826" mass="0.323373" diaginertia="0.000257854 0.000197522 0.000148053"/>
                <joint name="neck_yaw_joint" pos="0 0 0" axis="0 0 1" range="-0.79 0.79" actuatorfrcrange="-7.5 7.5"/>
                <geom type="mesh" contype="0" conaffinity="0" group="1" density="0" rgba="0.42745 0.45882 0.49412 1" mesh="neck_yaw_link"/>
                <geom type="mesh" rgba="0.42745 0.45882 0.49412 1" mesh="neck_yaw_link"/>
                <body name="neck_pitch_link" pos="0.015 0 0.0625">
                  <inertial pos="0.013213 -0.00209378 0.0602102" quat="-0.00862862 0.835974 -0.00527624 0.548675" mass="0.347398" diaginertia="0.00157411 0.00148456 0.00108971"/>
                  <joint name="neck_pitch_joint" pos="0 0 0" axis="0 1 0" range="-0.26 0.7" actuatorfrcrange="-7.5 7.5"/>
                  <geom type="mesh" contype="0" conaffinity="0" group="1" density="0" rgba="0.79216 0.81961 0.93333 1" mesh="neck_pitch_link"/>
                  <geom type="mesh" rgba="0.79216 0.81961 0.93333 1" mesh="neck_pitch_link"/>
                  <geom pos="0.059257 0 0.065296" quat="0.997317 0 0.0732094 0" type="mesh" contype="0" conaffinity="0" group="1" density="0" rgba="0.79216 0.81961 0.93333 1" mesh="head_rs_link"/>
                  <geom pos="0.059257 0 0.065296" quat="0.997317 0 0.0732094 0" type="mesh" rgba="0.79216 0.81961 0.93333 1" mesh="head_rs_link"/>
                </body>
              </body>
              <body name="left_shoulder_pitch_link" pos="-0.0385 0.09 0.128">
                <inertial pos="-0.0050043 0.0689444 -0.0013023" quat="0.901938 0.42684 0.0558386 0.0345991" mass="0.64146" diaginertia="0.00051767 0.000497022 0.000415388"/>
                <joint name="left_shoulder_pitch_joint" pos="0 0 0" axis="0 1 0" range="-2.79 2.79" actuatorfrcrange="-95 95"/>
                <geom type="mesh" contype="0" conaffinity="0" group="1" density="0" rgba="0.86667 0.86667 0.8902 1" mesh="left_shoulder_pitch_link"/>
                <geom type="mesh" rgba="0.86667 0.86667 0.8902 1" mesh="left_shoulder_pitch_link"/>
                <body name="left_shoulder_roll_link" pos="0 0.0725 -0.004">
                  <inertial pos="-0.00211885 -0.00158378 -0.0353422" quat="0.673028 0.190592 0.168161 0.694572" mass="0.172263" diaginertia="0.000250499 0.000206967 0.000178453"/>
                  <joint name="left_shoulder_roll_joint" pos="0 0 0" axis="1 0 0" range="-0.24 1.83" actuatorfrcrange="-32 32"/>
                  <geom type="mesh" contype="0" conaffinity="0" group="1" density="0" rgba="0.86667 0.86667 0.8902 1" mesh="left_shoulder_roll_link"/>
                  <geom type="mesh" rgba="0.86667 0.86667 0.8902 1" mesh="left_shoulder_roll_link"/>
                  <body name="left_arm_yaw_link" pos="0 0.002 -0.0635">
                    <inertial pos="-0.00113597 -0.0016386 -0.11233" quat="0.999639 -0.0105291 0.0059536 0.0240015" mass="1.2101" diaginertia="0.0085338 0.00849573 0.000766381"/>
                    <joint name="left_arm_yaw_joint" pos="0 0 0" axis="0 0 1" range="-2.62 2.62" actuatorfrcrange="-32 32"/>
                    <geom type="mesh" contype="0" conaffinity="0" group="1" density="0" rgba="0.86667 0.86667 0.8902 1" mesh="left_arm_yaw_link"/>
                    <geom type="mesh" rgba="0.86667 0.86667 0.8902 1" mesh="left_arm_yaw_link"/>
                    <body name="left_elbow_pitch_link" pos="-0.001 0 -0.1965">
                      <inertial pos="-0.00880355 -0.00323495 -0.0334867" quat="0.947561 0.312748 0.0656554 0.00253776" mass="0.1807" diaginertia="0.000276032 0.000232865 0.000160432"/>
                      <joint name="left_elbow_pitch_joint" pos="0 0 0" axis="0 1 0" range="-2.27 0.09" actuatorfrcrange="-32 32"/>
                      <geom type="mesh" contype="0" conaffinity="0" group="1" density="0" rgba="0.86667 0.86667 0.8902 1" mesh="left_elbow_pitch_link"/>
                      <geom type="mesh" rgba="0.86667 0.86667 0.8902 1" mesh="left_elbow_pitch_link"/>
                      <body name="left_elbow_yaw_link" pos="-0.0055 0 -0.0723">
                        <inertial pos="-0.00025009 -0.000948427 -0.0609878" quat="0.998933 -0.0193821 0.00931745 -0.0408687" mass="0.661734" diaginertia="0.00129318 0.00124203 0.00034156"/>
                        <joint name="left_elbow_yaw_joint" pos="0 0 0" axis="0 0 1" range="-2.62 2.62" actuatorfrcrange="-7.5 7.5"/>
                        <geom type="mesh" contype="0" conaffinity="0" group="1" density="0" rgba="0.86667 0.86667 0.8902 1" mesh="left_elbow_yaw_link"/>
                        <geom type="mesh" rgba="0.86667 0.86667 0.8902 1" mesh="left_elbow_yaw_link"/>
                        <body name="left_wrist_pitch_link" pos="0 0 -0.1492">
                          <inertial pos="0.0034386 -0.00062599 -5.68e-06" quat="-0.0130848 0.656165 0.128708 0.743445" mass="0.27757" diaginertia="0.000102214 9.92238e-05 9.20821e-05"/>
                          <joint name="left_wrist_pitch_joint" pos="0 0 0" axis="0 1 0" range="-1.05 1.05" actuatorfrcrange="-7.5 7.5"/>
                          <geom type="mesh" contype="0" conaffinity="0" group="1" density="0" rgba="1 1 1 1" mesh="left_wrist_pitch_link"/>
                          <geom type="mesh" rgba="1 1 1 1" mesh="left_wrist_pitch_link"/>
                          <body name="left_wrist_roll_link">
                            <inertial pos="0.00336135 -0.000205209 0.0324135" quat="0.999459 0.00390705 -0.0323705 0.00427045" mass="0.529002" diaginertia="0.00098289 0.000817945 0.000262299"/>
                            <joint name="left_wrist_roll_joint" pos="0 0 0" axis="1 0 0" range="-1.05 1.05" actuatorfrcrange="-7.5 7.5"/>
                            <geom type="mesh" contype="0" conaffinity="0" group="1" density="0" rgba="0.8902 0.8902 0.91373 1" mesh="left_wrist_roll_link"/>
                            <!-- <geom type="mesh" rgba="0.8902 0.8902 0.91373 1" mesh="left_wrist_roll_link"/> -->
                            <geom pos="0 0 -0.039" quat="-3.67321e-06 -1 0 0" type="mesh" contype="0" conaffinity="0" group="1" density="0" rgba="0.79216 0.81961 0.93333 1" mesh="left_arm_flange_link"/>
                            <geom pos="0 0 -0.039" quat="-3.67321e-06 -1 0 0" type="mesh" rgba="0.79216 0.81961 0.93333 1" mesh="left_arm_flange_link"/>
                            <geom pos="0 0 -0.039" quat="-2.59838e-06 -0.707388 0.706825 -2.59631e-06" type="mesh" contype="0" conaffinity="0" group="1" density="0" rgba="0.698039 0.698039 0.698039 1" mesh="left_hand_link"/>
                            <geom pos="0 0 -0.039" quat="-2.59838e-06 -0.707388 0.706825 -2.59631e-06" type="mesh" rgba="0.698039 0.698039 0.698039 1" mesh="left_hand_link"/>
                            <geom pos="0 -4.40785e-07 -0.099" quat="-2.59838e-06 -0.707388 0.706825 -2.59631e-06" type="mesh" contype="0" conaffinity="0" group="1" density="0" rgba="0.698039 0.698039 0.698039 1" mesh="left_hand_light_link"/>
                            <geom pos="0 -4.40785e-07 -0.099" quat="-2.59838e-06 -0.707388 0.706825 -2.59631e-06" type="mesh" rgba="0.698039 0.698039 0.698039 1" mesh="left_hand_light_link"/>
                            <geom pos="0 -4.40785e-07 -0.099" quat="-2.59838e-06 -0.707388 0.706825 -2.59631e-06" type="mesh" contype="0" conaffinity="0" group="1" density="0" rgba="0.698039 0.698039 0.698039 1" mesh="left_hand_dorsum_link"/>
                            <geom pos="0 -4.40785e-07 -0.099" quat="-2.59838e-06 -0.707388 0.706825 -2.59631e-06" type="mesh" rgba="0.698039 0.698039 0.698039 1" mesh="left_hand_dorsum_link"/>
                            <geom pos="0 -4.40785e-07 -0.099" quat="-2.59838e-06 -0.707388 0.706825 -2.59631e-06" type="mesh" contype="0" conaffinity="0" group="1" density="0" rgba="0.698039 0.698039 0.698039 1" mesh="left_hand_palm_link"/>
                            <geom pos="0 -4.40785e-07 -0.099" quat="-2.59838e-06 -0.707388 0.706825 -2.59631e-06" type="mesh" rgba="0.698039 0.698039 0.698039 1" mesh="left_hand_palm_link"/>
                            <geom pos="0 0 -0.103" quat="-3.67321e-06 1 0 0" type="mesh" contype="0" conaffinity="0" group="1" density="0" rgba="0.79216 0.81961 0.93333 1" mesh="left_hand_ee_link"/>
                            <geom pos="0 0 -0.103" quat="-3.67321e-06 1 0 0" type="mesh" rgba="0.79216 0.81961 0.93333 1" mesh="left_hand_ee_link"/>
                            <body name="left_hand_thumb_bend_link" pos="0.0260692 -0.0109796 -0.0866679" quat="-0.0616555 -0.704696 0.704136 0.0616013">
                              <inertial pos="-0.000597617 -0.01304 -2.46959e-05" quat="0.701583 0.711654 -0.0346175 0.0114929" mass="0.0131039" diaginertia="1.8523e-06 1.53882e-06 9.2888e-07"/>
                              <joint name="left_hand_thumb_bend_joint" pos="0 0 0" axis="0 0 1" range="0 1.919" actuatorfrcrange="-1.1 1.1"/>
                              <geom type="mesh" contype="0" conaffinity="0" group="1" density="0" rgba="0.698039 0.698039 0.698039 1" mesh="left_hand_thumb_bend_link"/>
                              <geom type="mesh" rgba="0.698039 0.698039 0.698039 1" mesh="left_hand_thumb_bend_link"/>
                              <body name="left_hand_thumb_rota_link1" pos="-0.000567853 -0.0290602 -0.00185317" quat="0.98747 0.0881014 0.130913 -0.00155133">
                                <inertial pos="4.75175e-05 -0.0199805 0.00590837" quat="0.773011 0.634041 -0.0137176 0.0160801" mass="0.0726617" diaginertia="1.9385e-05 1.92003e-05 4.95407e-06"/>
                                <joint name="left_hand_thumb_rota_joint1" pos="0 0 0" axis="-1 0 0" range="0 1.291" actuatorfrcrange="-1.1 1.1"/>
                                <geom type="mesh" contype="0" conaffinity="0" group="1" density="0" rgba="0.698039 0.698039 0.698039 1" mesh="left_hand_thumb_rota_link1"/>
                                <geom type="mesh" rgba="0.698039 0.698039 0.698039 1" mesh="left_hand_thumb_rota_link1"/>
                                <geom pos="0 -0.0476373 0.0170892" quat="1 0 0 0" type="mesh" contype="0" conaffinity="0" group="1" density="0" rgba="0.698039 0.698039 0.698039 1" mesh="left_hand_thumb_rotaback_link1"/>
                                <geom pos="0 -0.0476373 0.0170892" quat="1 0 0 0" type="mesh" rgba="0.698039 0.698039 0.698039 1" mesh="left_hand_thumb_rotaback_link1"/>
                                <body name="left_hand_thumb_rota_link2" pos="0 -0.047637 0.017089">
                                  <inertial pos="-7.53552e-07 -0.0127311 0.00750681" quat="0.669621 0.227173 -0.227172 0.669622" mass="0.0116019" diaginertia="1.87784e-06 1.77693e-06 8.09107e-07"/>
                                  <joint name="left_hand_thumb_rota_joint2" pos="0 0 0" axis="-1 0 0" range="0 0.995" actuatorfrcrange="-1.1 1.1"/>
                                  <geom type="mesh" contype="0" conaffinity="0" group="1" density="0" rgba="0.698039 0.698039 0.698039 1" mesh="left_hand_thumb_rota_link2"/>
                                  <geom type="mesh" rgba="0.698039 0.698039 0.698039 1" mesh="left_hand_thumb_rota_link2"/>
                                  <geom pos="0 -0.031299 0.016202" quat="1 0 0 0" type="mesh" contype="0" conaffinity="0" group="1" density="0" rgba="0.698039 0.698039 0.698039 1" mesh="left_hand_thumb_rotaback_link2"/>
                                  <geom pos="0 -0.031299 0.016202" quat="1 0 0 0" type="mesh" rgba="0.698039 0.698039 0.698039 1" mesh="left_hand_thumb_rotaback_link2"/>
                                  <geom pos="0 -0.0312989 0.0162021" type="mesh" contype="0" conaffinity="0" group="1" density="0" rgba="0.988235 0.737255 0.517647 1" mesh="left_hand_thumb_rota_tip"/>
                                  <geom pos="0 -0.0312989 0.0162021" type="mesh" rgba="0.988235 0.737255 0.517647 1" mesh="left_hand_thumb_rota_tip"/>
                                  <site name="left_hand_thumb_fingertip" size="0.003" pos="0 -0.0312989 0.0162021" rgba="1 0 0 1" type="sphere" />
                                </body>
                              </body>
                            </body>
                            <body name="left_hand_index_rota_link1" pos="0.0289992 0.00102219 -0.1618" quat="-2.59838e-06 -0.707388 0.706825 -2.59631e-06">
                              <inertial pos="0.00515164 -8.61405e-05 0.0215705" quat="0.998837 -0.0193499 0.0377504 0.0229237" mass="0.00793143" diaginertia="1.26604e-06 1.21981e-06 4.71535e-07"/>
                              <joint name="left_hand_index_rota_joint1" pos="0 0 0" axis="0 1 0" range="0 1.483" actuatorfrcrange="-1.1 1.1"/>
                              <geom type="mesh" contype="0" conaffinity="0" group="1" density="0" rgba="0.698039 0.698039 0.698039 1" mesh="left_hand_index_rota_link1"/>
                              <geom type="mesh" rgba="0.698039 0.698039 0.698039 1" mesh="left_hand_index_rota_link1"/>
                              <geom pos="0.00559923 0 0.0318346" type="mesh" contype="0" conaffinity="0" group="1" density="0" rgba="0.698039 0.698039 0.698039 1" mesh="left_hand_index_rotaback_link1"/>
                              <geom pos="0.00559923 0 0.0318346" type="mesh" rgba="0.698039 0.698039 0.698039 1" mesh="left_hand_index_rotaback_link1"/>
                              <body name="left_hand_index_rota_link2" pos="0.00559923 0 0.0318346">
                                <inertial pos="-0.00107644 4.5163e-09 0.0227763" quat="0.706463 0.0301614 0.0301614 0.706463" mass="0.0119934" diaginertia="2.36025e-06 2.34285e-06 2.37421e-07"/>
                                <joint name="left_hand_index_rota_joint2" pos="0 0 0" axis="0 1 0" range="0 1.919" actuatorfrcrange="-1.1 1.1"/>
                                <geom type="mesh" contype="0" conaffinity="0" group="1" density="0" rgba="0.698039 0.698039 0.698039 1" mesh="left_hand_index_rota_link2"/>
                                <geom type="mesh" rgba="0.698039 0.698039 0.698039 1" mesh="left_hand_index_rota_link2"/>
                                <geom pos="-0.0028592 0 0.0458892" quat="1 0 0 0" type="mesh" contype="0" conaffinity="0" group="1" density="0" rgba="0.698039 0.698039 0.698039 1" mesh="left_hand_index_rotaback_link2"/>
                                <geom pos="-0.0028592 0 0.0458892" quat="1 0 0 0" type="mesh" rgba="0.698039 0.698039 0.698039 1" mesh="left_hand_index_rotaback_link2"/>
                                <geom pos="-0.0028592 0 0.0458892" type="mesh" contype="0" conaffinity="0" group="1" density="0" rgba="0.988235 0.737255 0.517647 1" mesh="left_hand_index_rota_tip"/>
                                <geom pos="-0.0028592 0 0.0458892" type="mesh" rgba="0.988235 0.737255 0.517647 1" mesh="left_hand_index_rota_tip"/>
                                <site name="left_hand_index_fingertip" size="0.003" pos="-0.0028592 0 0.0458892" rgba="1 0 0 1" type="sphere" />
                              </body>
                            </body>
                            <body name="left_hand_mid_link1" pos="0.0099992 0.00100705 -0.1638" quat="-2.59838e-06 -0.707388 0.706825 -2.59631e-06">
                              <inertial pos="0.00507631 -8.61414e-05 0.0215883" quat="0.998838 -0.0193499 0.0377346 0.0228968" mass="0.00793143" diaginertia="1.2661e-06 1.21981e-06 4.71475e-07"/>
                              <joint name="left_hand_mid_joint1" pos="0 0 0" axis="0 1 0" range="0 1.483" actuatorfrcrange="-1.1 1.1"/>
                              <geom type="mesh" contype="0" conaffinity="0" group="1" density="0" rgba="0.698039 0.698039 0.698039 1" mesh="left_hand_mid_link1"/>
                              <geom type="mesh" rgba="0.698039 0.698039 0.698039 1" mesh="left_hand_mid_link1"/>
                              <geom pos="0.00548807 0 0.031854" type="mesh" contype="0" conaffinity="0" group="1" density="0" rgba="0.698039 0.698039 0.698039 1" mesh="left_hand_midback_link1"/>
                              <geom pos="0.00548807 0 0.031854" type="mesh" rgba="0.698039 0.698039 0.698039 1" mesh="left_hand_midback_link1"/>
                              <body name="left_hand_mid_link2" pos="0.00548807 0 0.031854">
                                <inertial pos="-0.000888898 1.85797e-07 0.0254413" quat="0.706556 0.0279057 0.0279057 0.706556" mass="0.0134964" diaginertia="3.18417e-06 3.15906e-06 2.75137e-07"/>
                                <joint name="left_hand_mid_joint2" pos="0 0 0" axis="0 1 0" range="0 1.919" actuatorfrcrange="-1.1 1.1"/>
                                <geom type="mesh" contype="0" conaffinity="0" group="1" density="0" rgba="0.698039 0.698039 0.698039 1" mesh="left_hand_mid_link2"/>
                                <geom type="mesh" rgba="0.698039 0.698039 0.698039 1" mesh="left_hand_mid_link2"/>
                                <geom pos="-0.00331113 0 0.0512921" quat="1 0 0 0" type="mesh" contype="0" conaffinity="0" group="1" density="0" rgba="0.698039 0.698039 0.698039 1" mesh="left_hand_midback_link2"/>
                                <geom pos="-0.00331113 0 0.0512921" quat="1 0 0 0" type="mesh" rgba="0.698039 0.698039 0.698039 1" mesh="left_hand_midback_link2"/>
                                <geom pos="-0.00331113 0 0.0512921" type="mesh" contype="0" conaffinity="0" group="1" density="0" rgba="0.988235 0.737255 0.517647 1" mesh="left_hand_mid_tip"/>
                                <geom pos="-0.00331113 0 0.0512921" type="mesh" rgba="0.988235 0.737255 0.517647 1" mesh="left_hand_mid_tip"/>
                                <site name="left_hand_mid_fingertip" size="0.003" pos="-0.00331113 0 0.0512921" rgba="1 0 0 1" type="sphere" />
                              </body>
                            </body>
                            <body name="left_hand_ring_link1" pos="-0.00900079 0.000991931 -0.1618" quat="-2.59838e-06 -0.707388 0.706825 -2.59631e-06">
                              <inertial pos="0.00515164 -8.61405e-05 0.0215705" quat="0.998837 -0.0193499 0.0377504 0.0229237" mass="0.00793143" diaginertia="1.26604e-06 1.21981e-06 4.71535e-07"/>
                              <joint name="left_hand_ring_joint1" pos="0 0 0" axis="0 1 0" range="0 1.483" actuatorfrcrange="-1.1 1.1"/>
                              <geom type="mesh" contype="0" conaffinity="0" group="1" density="0" rgba="0.698039 0.698039 0.698039 1" mesh="left_hand_ring_link1"/>
                              <geom type="mesh" rgba="0.698039 0.698039 0.698039 1" mesh="left_hand_ring_link1"/>
                              <geom pos="0.00559923 0 0.0318346" type="mesh" contype="0" conaffinity="0" group="1" density="0" rgba="0.698039 0.698039 0.698039 1" mesh="left_hand_ringback_link1"/>
                              <geom pos="0.00559923 0 0.0318346" type="mesh" rgba="0.698039 0.698039 0.698039 1" mesh="left_hand_ringback_link1"/>
                              <body name="left_hand_ring_link2" pos="0.00559923 0 0.0318346">
                                <inertial pos="-0.00105259 4.92018e-09 0.0227774" quat="0.706463 0.0301708 0.0301708 0.706463" mass="0.0119934" diaginertia="2.36025e-06 2.34286e-06 2.37408e-07"/>
                                <joint name="left_hand_ring_joint2" pos="0 0 0" axis="0 1 0" range="0 1.919" actuatorfrcrange="-1.1 1.1"/>
                                <geom type="mesh" contype="0" conaffinity="0" group="1" density="0" rgba="0.698039 0.698039 0.698039 1" mesh="left_hand_ring_link2"/>
                                <geom type="mesh" rgba="0.698039 0.698039 0.698039 1" mesh="left_hand_ring_link2"/>
                                <geom pos="-0.00281115 0 0.0458921" quat="1 0 0 0" type="mesh" contype="0" conaffinity="0" group="1" density="0" rgba="0.698039 0.698039 0.698039 1" mesh="left_hand_ringback_link2"/>
                                <geom pos="-0.00281115 0 0.0458921" quat="1 0 0 0" type="mesh" rgba="0.698039 0.698039 0.698039 1" mesh="left_hand_ringback_link2"/>
                                <geom pos="-0.00281115 0 0.0458921" type="mesh" contype="0" conaffinity="0" group="1" density="0" rgba="0.988235 0.737255 0.517647 1" mesh="left_hand_ring_tip"/>
                                <geom pos="-0.00281115 0 0.0458921" type="mesh" rgba="0.988235 0.737255 0.517647 1" mesh="left_hand_ring_tip"/>
                                <site name="left_hand_ring_fingertip" size="0.003" pos="-0.00281115 0 0.0458921" rgba="1 0 0 1" type="sphere" />
                              </body>
                            </body>
                            <body name="left_hand_pinky_link1" pos="-0.0280008 0.000976815 -0.1598" quat="-2.59838e-06 -0.707388 0.706825 -2.59631e-06">
                              <inertial pos="0.00507631 -8.61414e-05 0.0215883" quat="0.998838 -0.0193499 0.0377346 0.0228968" mass="0.00793143" diaginertia="1.2661e-06 1.21981e-06 4.71475e-07"/>
                              <joint name="left_hand_pinky_joint1" pos="0 0 0" axis="0 1 0" range="0 1.483" actuatorfrcrange="-1.1 1.1"/>
                              <geom type="mesh" contype="0" conaffinity="0" group="1" density="0" rgba="0.698039 0.698039 0.698039 1" mesh="left_hand_pinky_link1"/>
                              <geom type="mesh" rgba="0.698039 0.698039 0.698039 1" mesh="left_hand_pinky_link1"/>
                              <geom pos="0.00548807 0 0.031854" type="mesh" contype="0" conaffinity="0" group="1" density="0" rgba="0.698039 0.698039 0.698039 1" mesh="left_hand_pinkyback_link1"/>
                              <geom pos="0.00548807 0 0.031854" type="mesh" rgba="0.698039 0.698039 0.698039 1" mesh="left_hand_pinkyback_link1"/>
                              <body name="left_hand_pinky_link2" pos="0.00548807 0 0.031854">
                                <inertial pos="-0.00131231 1.78366e-07 0.0200377" quat="0.706399 0.0316405 0.0316405 0.706399" mass="0.00979828" diaginertia="1.56794e-06 1.53622e-06 1.91739e-07"/>
                                <joint name="left_hand_pinky_joint2" pos="0 0 0" axis="0 1 0" range="0 1.919" actuatorfrcrange="-1.1 1.1"/>
                                <geom type="mesh" contype="0" conaffinity="0" group="1" density="0" rgba="0.698039 0.698039 0.698039 1" mesh="left_hand_pinky_link2"/>
                                <geom type="mesh" rgba="0.698039 0.698039 0.698039 1" mesh="left_hand_pinky_link2"/>
                                <geom pos="-0.00299025 0 0.0401715" quat="1 0 0 0" type="mesh" contype="0" conaffinity="0" group="1" density="0" rgba="0.698039 0.698039 0.698039 1" mesh="left_hand_pinkyback_link2"/>
                                <geom pos="-0.00299025 0 0.0401715" quat="1 0 0 0" type="mesh" rgba="0.698039 0.698039 0.698039 1" mesh="left_hand_pinkyback_link2"/>
                                <geom pos="-0.00299025 0 0.0401715" type="mesh" contype="0" conaffinity="0" group="1" density="0" rgba="0.988235 0.737255 0.517647 1" mesh="left_hand_pinky_tip"/>
                                <geom pos="-0.00299025 0 0.0401715" type="mesh" rgba="0.988235 0.737255 0.517647 1" mesh="left_hand_pinky_tip"/>
                                <site name="left_hand_pinky_fingertip" size="0.003" pos="-0.00299025 0 0.0401715" rgba="1 0 0 1" type="sphere" />
                              </body>
                            </body>
                          </body>
                        </body>
                      </body>
                    </body>
                  </body>
                </body>
              </body>
              <body name="right_shoulder_pitch_link" pos="-0.0385 -0.09 0.128">
                <inertial pos="-0.0050037 -0.068922 -0.0013416" quat="0.429586 0.900407 -0.0483872 -0.0487964" mass="0.64146" diaginertia="0.000517715 0.000496898 0.000415528"/>
                <joint name="right_shoulder_pitch_joint" pos="0 0 0" axis="0 1 0" range="-2.79 2.79" actuatorfrcrange="-95 95"/>
                <geom type="mesh" contype="0" conaffinity="0" group="1" density="0" rgba="0.79216 0.81961 0.93333 1" mesh="right_shoulder_pitch_link"/>
                <geom type="mesh" rgba="0.79216 0.81961 0.93333 1" mesh="right_shoulder_pitch_link"/>
                <body name="right_shoulder_roll_link" pos="0 -0.0725 -0.004">
                  <inertial pos="-0.0021219 -0.0015843 -0.035346" quat="0.681972 -0.191826 -0.167678 0.685566" mass="0.17223" diaginertia="0.000250431 0.000206989 0.00017837"/>
                  <joint name="right_shoulder_roll_joint" pos="0 0 0" axis="1 0 0" range="-1.83 0.24" actuatorfrcrange="-32 32"/>
                  <geom type="mesh" contype="0" conaffinity="0" group="1" density="0" rgba="0.79216 0.81961 0.93333 1" mesh="right_shoulder_roll_link"/>
                  <geom type="mesh" rgba="0.79216 0.81961 0.93333 1" mesh="right_shoulder_roll_link"/>
                  <body name="right_arm_yaw_link" pos="0 -0.002 -0.0635">
                    <inertial pos="-0.0010977 0.0016198 -0.11231" quat="0.99978 0.010707 0.00580288 -0.017095" mass="1.2099" diaginertia="0.00853193 0.00849296 0.000765881"/>
                    <joint name="right_arm_yaw_joint" pos="0 0 0" axis="0 0 1" range="-2.62 2.62" actuatorfrcrange="-32 32"/>
                    <geom type="mesh" contype="0" conaffinity="0" group="1" density="0" rgba="0.79216 0.81961 0.93333 1" mesh="right_arm_yaw_link"/>
                    <geom type="mesh" rgba="0.79216 0.81961 0.93333 1" mesh="right_arm_yaw_link"/>
                    <body name="right_elbow_pitch_link" pos="-0.001 0 -0.1965">
                      <inertial pos="-0.00880547 0.0032133 -0.0334924" quat="0.947935 -0.31162 0.0656026 -0.00277839" mass="0.180668" diaginertia="0.000275639 0.000232563 0.000160318"/>
                      <joint name="right_elbow_pitch_joint" pos="0 0 0" axis="0 1 0" range="-2.27 0.09" actuatorfrcrange="-32 32"/>
                      <geom type="mesh" contype="0" conaffinity="0" group="1" density="0" rgba="0.79216 0.81961 0.93333 1" mesh="right_elbow_pitch_link"/>
                      <geom type="mesh" rgba="0.79216 0.81961 0.93333 1" mesh="right_elbow_pitch_link"/>
                      <body name="right_elbow_yaw_link" pos="-0.0055 0 -0.0723">
                        <inertial pos="-0.00012227 0.0010776 -0.061048" quat="0.998118 0.0181205 0.00770286 0.0580738" mass="0.66172" diaginertia="0.00129548 0.00124372 0.000341622"/>
                        <joint name="right_elbow_yaw_joint" pos="0 0 0" axis="0 0 1" range="-2.62 2.62" actuatorfrcrange="-7.5 7.5"/>
                        <geom type="mesh" contype="0" conaffinity="0" group="1" density="0" rgba="0.79216 0.81961 0.93333 1" mesh="right_elbow_yaw_link"/>
                        <geom type="mesh" rgba="0.79216 0.81961 0.93333 1" mesh="right_elbow_yaw_link"/>
                        <body name="right_wrist_pitch_link" pos="0 0 -0.1492">
                          <inertial pos="0.0034392 0.00095252 0.00011331" quat="0.0437258 0.658445 -0.226605 0.716371" mass="0.27757" diaginertia="0.000101962 0.000100258 9.10005e-05"/>
                          <joint name="right_wrist_pitch_joint" pos="0 0 0" axis="0 1 0" range="-1.05 1.05" actuatorfrcrange="-7.5 7.5"/>
                          <geom type="mesh" contype="0" conaffinity="0" group="1" density="0" rgba="0.79216 0.81961 0.93333 1" mesh="right_wrist_pitch_link"/>
                          <geom type="mesh" rgba="0.79216 0.81961 0.93333 1" mesh="right_wrist_pitch_link"/>
                          <body name="right_wrist_roll_link">
                            <inertial pos="0.00340169 9.60352e-06 0.032319" quat="0.999255 -0.00512172 -0.0379869 -0.00455089" mass="0.530669" diaginertia="0.00098624 0.000819994 0.000261964"/>
                            <joint name="right_wrist_roll_joint" pos="0 0 0" axis="1 0 0" range="-1.05 1.05" actuatorfrcrange="-7.5 7.5"/>
                            <geom type="mesh" contype="0" conaffinity="0" group="1" density="0" rgba="0.8902 0.8902 0.91373 1" mesh="right_wrist_roll_link"/>
                            <!-- <geom type="mesh" rgba="0.8902 0.8902 0.91373 1" mesh="right_wrist_roll_link"/> -->
                            <geom pos="0 0 -0.039" quat="-3.67321e-06 -1 0 0" type="mesh" contype="0" conaffinity="0" group="1" density="0" rgba="0.792157 0.819608 0.933333 1" mesh="right_arm_flange_link"/>
                            <geom pos="0 0 -0.039" quat="-3.67321e-06 -1 0 0" type="mesh" rgba="0.792157 0.819608 0.933333 1" mesh="right_arm_flange_link"/>
                            <geom pos="0 0 -0.039" quat="-2.59838e-06 -0.707388 -0.706825 2.59631e-06" type="mesh" contype="0" conaffinity="0" group="1" density="0" rgba="0.792157 0.819608 0.933333 1" mesh="right_hand_link"/>
                            <geom pos="0 0 -0.039" quat="-2.59838e-06 -0.707388 -0.706825 2.59631e-06" type="mesh" rgba="0.792157 0.819608 0.933333 1" mesh="right_hand_link"/>
                            <geom pos="0 -4.40785e-07 -0.099" quat="-2.59838e-06 -0.707388 -0.706825 2.59631e-06" type="mesh" contype="0" conaffinity="0" group="1" density="0" rgba="0.792157 0.819608 0.933333 1" mesh="right_hand_light_link"/>
                            <geom pos="0 -4.40785e-07 -0.099" quat="-2.59838e-06 -0.707388 -0.706825 2.59631e-06" type="mesh" rgba="0.792157 0.819608 0.933333 1" mesh="right_hand_light_link"/>
                            <geom pos="0 -4.40785e-07 -0.099" quat="-2.59838e-06 -0.707388 -0.706825 2.59631e-06" type="mesh" contype="0" conaffinity="0" group="1" density="0" rgba="0.792157 0.819608 0.933333 1" mesh="right_hand_dorsum_link"/>
                            <geom pos="0 -4.40785e-07 -0.099" quat="-2.59838e-06 -0.707388 -0.706825 2.59631e-06" type="mesh" rgba="0.792157 0.819608 0.933333 1" mesh="right_hand_dorsum_link"/>
                            <geom pos="0 -4.40785e-07 -0.099" quat="-2.59838e-06 -0.707388 -0.706825 2.59631e-06" type="mesh" contype="0" conaffinity="0" group="1" density="0" rgba="0.792157 0.819608 0.933333 1" mesh="right_hand_palm_link"/>
                            <geom pos="0 -4.40785e-07 -0.099" quat="-2.59838e-06 -0.707388 -0.706825 2.59631e-06" type="mesh" rgba="0.792157 0.819608 0.933333 1" mesh="right_hand_palm_link"/>
                            <geom pos="0 0 -0.103" quat="-3.67321e-06 1 0 0" type="mesh" contype="0" conaffinity="0" group="1" density="0" rgba="0.792157 0.819608 0.933333 1" mesh="right_hand_ee_link"/>
                            <geom pos="0 0 -0.103" quat="-3.67321e-06 1 0 0" type="mesh" rgba="0.792157 0.819608 0.933333 1" mesh="right_hand_ee_link"/>
                            <body name="right_hand_thumb_bend_link" pos="0.0260688 0.0109789 -0.0866681" quat="0.0616493 -0.704697 -0.704135 0.0616054">
                              <inertial pos="-0.000338925 0.013154 -0.000118788" quat="0.724382 0.688609 -0.0267529 0.0192917" mass="0.0129899" diaginertia="1.8214e-06 1.52023e-06 9.1837e-07"/>
                              <joint name="right_hand_thumb_bend_joint" pos="0 0 0" axis="0 0 -1" range="0 1.919" actuatorfrcrange="-1.1 1.1"/>
                              <geom type="mesh" contype="0" conaffinity="0" group="1" density="0" rgba="0.792157 0.819608 0.933333 1" mesh="right_hand_thumb_bend_link"/>
                              <geom type="mesh" rgba="0.792157 0.819608 0.933333 1" mesh="right_hand_thumb_bend_link"/>
                              <body name="right_hand_thumb_rota_link1" pos="-0.00056763 0.02906 -0.0018532" quat="0.987762 -0.0847661 0.130918 0.00110906">
                                <inertial pos="-4.75146e-05 0.02002 0.0057733" quat="0.636698 0.770808 0.0164746 -0.0141356" mass="0.0726617" diaginertia="1.9385e-05 1.92033e-05 4.95106e-06"/>
                                <joint name="right_hand_thumb_rota_joint1" pos="0 0 0" axis="1 0 0" range="0 1.291" actuatorfrcrange="-1.1 1.1"/>
                                <geom type="mesh" contype="0" conaffinity="0" group="1" density="0" rgba="0.698039 0.698039 0.698039 1" mesh="right_hand_thumb_rota_link1"/>
                                <geom type="mesh" rgba="0.698039 0.698039 0.698039 1" mesh="right_hand_thumb_rota_link1"/>
                                <geom pos="0 0.0477516 0.0167671" quat="1 0 0 0" type="mesh" contype="0" conaffinity="0" group="1" density="0" rgba="0.698039 0.698039 0.698039 1" mesh="right_hand_thumb_rotaback_link1"/>
                                <geom pos="0 0.0477516 0.0167671" quat="1 0 0 0" type="mesh" rgba="0.698039 0.698039 0.698039 1" mesh="right_hand_thumb_rotaback_link1"/>
                                <body name="right_hand_thumb_rota_link2" pos="0 0.047752 0.016767">
                                  <inertial pos="7.16499e-07 0.0125476 0.00780972" quat="0.669178 -0.228475 0.228475 0.669178" mass="0.0116019" diaginertia="1.88203e-06 1.77693e-06 8.14913e-07"/>
                                  <joint name="right_hand_thumb_rota_joint2" pos="0 0 0" axis="1 0 0" range="0 0.995" actuatorfrcrange="-1.1 1.1"/>
                                  <geom type="mesh" contype="0" conaffinity="0" group="1" density="0" rgba="0.698039 0.698039 0.698039 1" mesh="right_hand_thumb_rota_link2"/>
                                  <geom type="mesh" rgba="0.698039 0.698039 0.698039 1" mesh="right_hand_thumb_rota_link2"/>
                                  <geom pos="0 0.030902 0.016947" quat="1 0 0 0" type="mesh" contype="0" conaffinity="0" group="1" density="0" rgba="0.698039 0.698039 0.698039 1" mesh="right_hand_thumb_rotaback_link2"/>
                                  <geom pos="0 0.030902 0.016947" quat="1 0 0 0" type="mesh" rgba="0.698039 0.698039 0.698039 1" mesh="right_hand_thumb_rotaback_link2"/>
                                  <geom pos="0 0.030902 0.016947" type="mesh" contype="0" conaffinity="0" group="1" density="0" rgba="0.988235 0.737255 0.517647 1" mesh="right_hand_thumb_rota_tip"/>
                                  <geom pos="0 0.030902 0.016947" type="mesh" rgba="0.988235 0.737255 0.517647 1" mesh="right_hand_thumb_rota_tip"/>
                                  <site name="right_hand_thumb_fingertip" size="0.003" pos="0 0.030902 0.016947" rgba="1 0 0 1" type="sphere" />
                                </body>
                              </body>
                            </body>
                            <body name="right_hand_index_rota_link1" pos="0.0289992 -0.001024 -0.1618" quat="-2.59838e-06 -0.707388 -0.706825 2.59631e-06">
                              <inertial pos="0.00340514 -8.61374e-05 0.0219143" quat="0.998868 -0.0193584 0.037317 0.0222675" mass="0.00793143" diaginertia="1.26737e-06 1.21981e-06 4.70197e-07"/>
                              <joint name="right_hand_index_rota_joint1" pos="0 0 0" axis="0 1 0" range="0 1.483" actuatorfrcrange="-1.1 1.1"/>
                              <geom type="mesh" contype="0" conaffinity="0" group="1" density="0" rgba="0.698039 0.698039 0.698039 1" mesh="right_hand_index_rota_link1"/>
                              <geom type="mesh" rgba="0.698039 0.698039 0.698039 1" mesh="right_hand_index_rota_link1"/>
                              <geom pos="0.0030281 0 0.032181" type="mesh" contype="0" conaffinity="0" group="1" density="0" rgba="0.698039 0.698039 0.698039 1" mesh="right_hand_index_rotaback_link1"/>
                              <geom pos="0.0030281 0 0.032181" type="mesh" rgba="0.698039 0.698039 0.698039 1" mesh="right_hand_index_rotaback_link1"/>
                              <body name="right_hand_index_rota_link2" pos="0.0030281 0 0.032181">
                                <inertial pos="-0.00271002 -6.35453e-08 0.0226405" quat="0.70649 0.029526 0.029526 0.70649" mass="0.0119934" diaginertia="2.36025e-06 2.34174e-06 2.38528e-07"/>
                                <joint name="right_hand_index_rota_joint2" pos="0 0 0" axis="0 1 0" range="0 1.919" actuatorfrcrange="-1.1 1.1"/>
                                <geom type="mesh" contype="0" conaffinity="0" group="1" density="0" rgba="0.698039 0.698039 0.698039 1" mesh="right_hand_index_rota_link2"/>
                                <geom type="mesh" rgba="0.698039 0.698039 0.698039 1" mesh="right_hand_index_rota_link2"/>
                                <geom pos="-0.0061488 0 0.045565" quat="1 0 0 0" type="mesh" contype="0" conaffinity="0" group="1" density="0" rgba="0.698039 0.698039 0.698039 1" mesh="right_hand_index_rotaback_link2"/>
                                <geom pos="-0.0061488 0 0.045565" quat="1 0 0 0" type="mesh" rgba="0.698039 0.698039 0.698039 1" mesh="right_hand_index_rotaback_link2"/>
                                <geom pos="-0.0061488 0 0.045565" type="mesh" contype="0" conaffinity="0" group="1" density="0" rgba="0.988235 0.737255 0.517647 1" mesh="right_hand_index_rota_tip"/>
                                <geom pos="-0.0061488 0 0.045565" type="mesh" rgba="0.988235 0.737255 0.517647 1" mesh="right_hand_index_rota_tip"/>
                                <site name="right_hand_index_fingertip" size="0.003" pos="-0.0061488 0 0.045565" rgba="1 0 0 1" type="sphere" />
                              </body>
                            </body>
                            <body name="right_hand_mid_link1" pos="0.0099992 -0.00100888 -0.1638" quat="-2.59838e-06 -0.707388 -0.706825 2.59631e-06">
                              <inertial pos="0.00348161 -8.61374e-05 0.0219023" quat="0.998866 -0.0193579 0.0373386 0.0222958" mass="0.00793143" diaginertia="1.26732e-06 1.21981e-06 4.70253e-07"/>
                              <joint name="right_hand_mid_joint1" pos="0 0 0" axis="0 1 0" range="0 1.483" actuatorfrcrange="-1.1 1.1"/>
                              <geom type="mesh" contype="0" conaffinity="0" group="1" density="0" rgba="0.698039 0.698039 0.698039 1" mesh="right_hand_mid_link1"/>
                              <geom type="mesh" rgba="0.698039 0.698039 0.698039 1" mesh="right_hand_mid_link1"/>
                              <geom pos="0.0031404 0 0.03217" type="mesh" contype="0" conaffinity="0" group="1" density="0" rgba="0.698039 0.698039 0.698039 1" mesh="right_hand_midback_link1"/>
                              <geom pos="0.0031404 0 0.03217" type="mesh" rgba="0.698039 0.698039 0.698039 1" mesh="right_hand_midback_link1"/>
                              <body name="right_hand_mid_link2" pos="0.0031404 0 0.03217">
                                <inertial pos="-0.00274077 2.89335e-07 0.0253097" quat="0.706579 0.0273271 0.0273271 0.706579" mass="0.0134964" diaginertia="3.18417e-06 3.15746e-06 2.76727e-07"/>
                                <joint name="right_hand_mid_joint2" pos="0 0 0" axis="0 1 0" range="0 1.919" actuatorfrcrange="-1.1 1.1"/>
                                <geom type="mesh" contype="0" conaffinity="0" group="1" density="0" rgba="0.698039 0.698039 0.698039 1" mesh="right_hand_mid_link2"/>
                                <geom type="mesh" rgba="0.698039 0.698039 0.698039 1" mesh="right_hand_mid_link2"/>
                                <geom pos="-0.007041 0 0.050914" quat="1 0 0 0" type="mesh" contype="0" conaffinity="0" group="1" density="0" rgba="0.698039 0.698039 0.698039 1" mesh="right_hand_midback_link2"/>
                                <geom pos="-0.007041 0 0.050914" quat="1 0 0 0" type="mesh" rgba="0.698039 0.698039 0.698039 1" mesh="right_hand_midback_link2"/>
                                <geom pos="-0.007041 0 0.050914" type="mesh" contype="0" conaffinity="0" group="1" density="0" rgba="0.988235 0.737255 0.517647 1" mesh="right_hand_mid_tip"/>
                                <geom pos="-0.007041 0 0.050914" type="mesh" rgba="0.988235 0.737255 0.517647 1" mesh="right_hand_mid_tip"/>
                                <site name="right_hand_mid_fingertip" size="0.003" pos="-0.007041 0 0.050914" rgba="1 0 0 1" type="sphere" />
                              </body>
                            </body>
                            <body name="right_hand_ring_link1" pos="-0.00900079 -0.000993735 -0.1618" quat="-2.59838e-06 -0.707388 -0.706825 2.59631e-06">
                              <inertial pos="0.00340514 -8.61374e-05 0.0219143" quat="0.998868 -0.0193584 0.037317 0.0222675" mass="0.00793143" diaginertia="1.26737e-06 1.21981e-06 4.70197e-07"/>
                              <joint name="right_hand_ring_joint1" pos="0 0 0" axis="0 1 0" range="0 1.483" actuatorfrcrange="-1.1 1.1"/>
                              <geom type="mesh" contype="0" conaffinity="0" group="1" density="0" rgba="0.698039 0.698039 0.698039 1" mesh="right_hand_ring_link1"/>
                              <geom type="mesh" rgba="0.698039 0.698039 0.698039 1" mesh="right_hand_ring_link1"/>
                              <geom pos="0.0030281 0 0.032181" type="mesh" contype="0" conaffinity="0" group="1" density="0" rgba="0.698039 0.698039 0.698039 1" mesh="right_hand_ringback_link1"/>
                              <geom pos="0.0030281 0 0.032181" type="mesh" rgba="0.698039 0.698039 0.698039 1" mesh="right_hand_ringback_link1"/>
                              <body name="right_hand_ring_link2" pos="0.0030281 0 0.032181">
                                <inertial pos="-0.00271002 -6.35464e-08 0.0226405" quat="0.70649 0.029526 0.029526 0.70649" mass="0.0119934" diaginertia="2.36025e-06 2.34174e-06 2.38528e-07"/>
                                <joint name="right_hand_ring_joint2" pos="0 0 0" axis="0 1 0" range="0 1.919" actuatorfrcrange="-1.1 1.1"/>
                                <geom type="mesh" contype="0" conaffinity="0" group="1" density="0" rgba="0.698039 0.698039 0.698039 1" mesh="right_hand_ring_link2"/>
                                <geom type="mesh" rgba="0.698039 0.698039 0.698039 1" mesh="right_hand_ring_link2"/>
                                <geom pos="-0.0061488 0 0.045565" quat="1 0 0 0" type="mesh" contype="0" conaffinity="0" group="1" density="0" rgba="0.698039 0.698039 0.698039 1" mesh="right_hand_ringback_link2"/>
                                <geom pos="-0.0061488 0 0.045565" quat="1 0 0 0" type="mesh" rgba="0.698039 0.698039 0.698039 1" mesh="right_hand_ringback_link2"/>
                                <geom pos="-0.0061488 0 0.045565" type="mesh" contype="0" conaffinity="0" group="1" density="0" rgba="0.988235 0.737255 0.517647 1" mesh="right_hand_ring_tip"/>
                                <geom pos="-0.0061488 0 0.045565" type="mesh" rgba="0.988235 0.737255 0.517647 1" mesh="right_hand_ring_tip"/>
                                <site name="right_hand_ring_fingertip" size="0.003" pos="-0.0061488 0 0.045565" rgba="1 0 0 1" type="sphere" />
                              </body>
                            </body>
                            <body name="right_hand_pinky_link1" pos="-0.0280008 -0.00097859 -0.1598" quat="-2.59838e-06 -0.707388 -0.706825 2.59631e-06">
                              <inertial pos="0.00348161 -8.61375e-05 0.0219023" quat="0.998866 -0.0193579 0.0373386 0.0222958" mass="0.00793143" diaginertia="1.26732e-06 1.21981e-06 4.70253e-07"/>
                              <joint name="right_hand_pinky_joint1" pos="0 0 0" axis="0 1 0" range="0 1.483" actuatorfrcrange="-1.1 1.1"/>
                              <geom type="mesh" contype="0" conaffinity="0" group="1" density="0" rgba="0.698039 0.698039 0.698039 1" mesh="right_hand_pinky_link1"/>
                              <geom type="mesh" rgba="0.698039 0.698039 0.698039 1" mesh="right_hand_pinky_link1"/>
                              <geom pos="0.0031404 0 0.03217" type="mesh" contype="0" conaffinity="0" group="1" density="0" rgba="0.698039 0.698039 0.698039 1" mesh="right_hand_pinkyback_link1"/>
                              <geom pos="0.0031404 0 0.03217" type="mesh" rgba="0.698039 0.698039 0.698039 1" mesh="right_hand_pinkyback_link1"/>
                              <body name="right_hand_pinky_link2" pos="0.0031404 0 0.03217">
                                <inertial pos="-0.00276944 1.83216e-07 0.0198887" quat="0.706434 0.0308449 0.0308449 0.706434" mass="0.00979828" diaginertia="1.56794e-06 1.53541e-06 1.92552e-07"/>
                                <joint name="right_hand_pinky_joint2" pos="0 0 0" axis="0 1 0" range="0 1.919" actuatorfrcrange="-1.1 1.1"/>
                                <geom type="mesh" contype="0" conaffinity="0" group="1" density="0" rgba="0.698039 0.698039 0.698039 1" mesh="right_hand_pinky_link2"/>
                                <geom type="mesh" rgba="0.698039 0.698039 0.698039 1" mesh="right_hand_pinky_link2"/>
                                <geom pos="-0.0059104 0 0.039847" quat="1 0 0 0" type="mesh" contype="0" conaffinity="0" group="1" density="0" rgba="0.698039 0.698039 0.698039 1" mesh="right_hand_pinkyback_link2"/>
                                <geom pos="-0.0059104 0 0.039847" quat="1 0 0 0" type="mesh" rgba="0.698039 0.698039 0.698039 1" mesh="right_hand_pinkyback_link2"/>
                                <geom pos="-0.0059104 0 0.039847" type="mesh" contype="0" conaffinity="0" group="1" density="0" rgba="0.988235 0.737255 0.517647 1" mesh="right_hand_pinky_tip"/>
                                <geom pos="-0.0059104 0 0.039847" type="mesh" rgba="0.988235 0.737255 0.517647 1" mesh="right_hand_pinky_tip"/>
                                <site name="right_hand_pinky_fingertip" size="0.003" pos="-0.0059104 0 0.039847" rgba="1 0 0 1" type="sphere" />
                              </body>
                            </body>
                          </body>
                        </body>
                      </body>
                    </body>
                  </body>
                </body>
              </body>
            </body>
          </body>
        </body>
      </body>
      <body name="left_drv_hang_link" pos="0.1 0.166 -0.02975">
        <inertial pos="-0.092969 0 0.035633" quat="0.351775 0.613396 0.613396 0.351775" mass="0.88972" diaginertia="0.0020012 0.00190725 0.000250873"/>
        <joint name="left_drv_hang_joint" pos="0 0 0" axis="0 1 0" range="-0.35 0.35" actuatorfrcrange="-50 50"/>
        <geom type="mesh" contype="0" conaffinity="0" group="1" density="0" rgba="0.77647 0.75686 0.73725 1" mesh="left_drv_hang_link"/>
        <geom type="mesh" rgba="0.77647 0.75686 0.73725 1" mesh="left_drv_hang_link"/>
        <body name="left_drv_wheel_link" pos="-0.1 -0.166 0.02975">
          <inertial pos="1.8792e-06 0.21726 4.2798e-07" quat="0.551594 0.442482 0.44243 0.551552" mass="2.2035" diaginertia="0.0049881 0.0030551 0.0030551"/>
          <joint name="left_drv_wheel_joint" pos="0 0 0" axis="0 1 0" actuatorfrcrange="-15 15"/>
          <geom type="mesh" contype="0" conaffinity="0" group="1" density="0" rgba="0.86667 0.86667 0.8902 1" mesh="left_drv_wheel_link"/>
          <geom type="mesh" rgba="0.86667 0.86667 0.8902 1" mesh="left_drv_wheel_link"/>
        </body>
      </body>
      <body name="right_drv_hang_link" pos="0.1 -0.166 -0.02975">
        <inertial pos="-0.092969 0 0.035633" quat="0.351775 0.613396 0.613396 0.351775" mass="0.88972" diaginertia="0.0020012 0.00190725 0.000250873"/>
        <joint name="right_drv_hang_joint" pos="0 0 0" axis="0 1 0" range="-0.35 0.35" actuatorfrcrange="-50 50"/>
        <geom type="mesh" contype="0" conaffinity="0" group="1" density="0" rgba="0.77647 0.75686 0.73725 1" mesh="right_drv_hang_link"/>
        <geom type="mesh" rgba="0.77647 0.75686 0.73725 1" mesh="right_drv_hang_link"/>
        <body name="right_drv_wheel_link" pos="-0.1 0.166 0.02975">
          <inertial pos="1.4091e-06 -0.21726 1.93e-06" quat="0.707107 -3.47518e-05 3.47518e-05 0.707107" mass="2.2035" diaginertia="0.0049881 0.0030551 0.0030551"/>
          <joint name="right_drv_wheel_joint" pos="0 0 0" axis="0 1 0" actuatorfrcrange="-15 15"/>
          <geom type="mesh" contype="0" conaffinity="0" group="1" density="0" rgba="0.86667 0.86667 0.8902 1" mesh="right_drv_wheel_link"/>
          <geom type="mesh" rgba="0.86667 0.86667 0.8902 1" mesh="right_drv_wheel_link"/>
        </body>
      </body>
    </body>
  </worldbody>
  <actuator>
    <motor forcelimited="true" forcerange="-240 240" joint="ankle_joint" name="ankle_joint" />
    <motor forcelimited="true" forcerange="-240 240" joint="knee_joint" name="knee_joint" />
    <motor forcelimited="true" forcerange="-240 240" joint="hip_joint" name="hip_joint" />
    <motor forcelimited="true" forcerange="-240 240" joint="waist_yaw_joint" name="waist_yaw_joint" />
    <motor forcelimited="true" forcerange="-240 240" joint="neck_yaw_joint" name="neck_yaw_joint" />
    <motor forcelimited="true" forcerange="-240 240" joint="neck_pitch_joint" name="neck_pitch_joint" />
    <motor forcelimited="true" forcerange="-240 240" joint="left_shoulder_pitch_joint" name="left_shoulder_pitch_joint" />
    <motor forcelimited="true" forcerange="-32 32" joint="left_shoulder_roll_joint" name="left_shoulder_roll_joint" />
    <motor forcelimited="true" forcerange="-32 32" joint="left_arm_yaw_joint" name="left_arm_yaw_joint" />
    <motor forcelimited="true" forcerange="-240 240" joint="right_shoulder_pitch_joint" name="right_shoulder_pitch_joint" />
    <motor forcelimited="true" forcerange="-32 32" joint="right_shoulder_roll_joint" name="right_shoulder_roll_joint" />
    <motor forcelimited="true" forcerange="-32 32" joint="right_arm_yaw_joint" name="right_arm_yaw_joint" />
    <motor forcelimited="true" forcerange="-240 240" joint="right_elbow_pitch_joint" name="right_elbow_pitch_joint" />
    <motor forcelimited="true" forcerange="-7.5 7.5" joint="right_elbow_yaw_joint" name="right_elbow_yaw_joint" />
    <motor forcelimited="true" forcerange="-240 240" joint="left_elbow_pitch_joint" name="left_elbow_pitch_joint" />
    <motor forcelimited="true" forcerange="-240 240" joint="left_elbow_yaw_joint" name="left_elbow_yaw_joint" />
    <motor forcelimited="true" forcerange="-7.5 7.5" joint="right_wrist_pitch_joint" name="right_wrist_pitch_joint" />
    <motor forcelimited="true" forcerange="-7.5 7.5" joint="right_wrist_roll_joint" name="right_wrist_roll_joint" />
    <motor forcelimited="true" forcerange="-240 240" joint="left_wrist_pitch_joint" name="left_wrist_pitch_joint" />
    <motor forcelimited="true" forcerange="-240 240" joint="left_wrist_roll_joint" name="left_wrist_roll_joint" />
    <motor forcelimited="true" forcerange="-1.1 1.1" joint="left_hand_thumb_bend_joint" name="left_hand_thumb_bend_joint" />
    <motor forcelimited="true" forcerange="-1.1 1.1" joint="left_hand_thumb_rota_joint1" name="left_hand_thumb_rota_joint1" />
    <motor forcelimited="true" forcerange="-1.1 1.1" joint="left_hand_thumb_rota_joint2" name="left_hand_thumb_rota_joint2" />
    <motor forcelimited="true" forcerange="-1.1 1.1" joint="left_hand_index_rota_joint1" name="left_hand_index_rota_joint1" />
    <motor forcelimited="true" forcerange="-1.1 1.1" joint="left_hand_index_rota_joint2" name="left_hand_index_rota_joint2" />
    <motor forcelimited="true" forcerange="-1.1 1.1" joint="left_hand_mid_joint1" name="left_hand_mid_joint1" />
    <motor forcelimited="true" forcerange="-1.1 1.1" joint="left_hand_mid_joint2" name="left_hand_mid_joint2" />
    <motor forcelimited="true" forcerange="-1.1 1.1" joint="left_hand_ring_joint1" name="left_hand_ring_joint1" />
    <motor forcelimited="true" forcerange="-1.1 1.1" joint="left_hand_ring_joint2" name="left_hand_ring_joint2" />
    <motor forcelimited="true" forcerange="-1.1 1.1" joint="left_hand_pinky_joint1" name="left_hand_pinky_joint1" />
    <motor forcelimited="true" forcerange="-1.1 1.1" joint="left_hand_pinky_joint2" name="left_hand_pinky_joint2" />
    <motor forcelimited="true" forcerange="-1.1 1.1" joint="right_hand_thumb_bend_joint" name="right_hand_thumb_bend_joint" />
    <motor forcelimited="true" forcerange="-1.1 1.1" joint="right_hand_thumb_rota_joint1" name="right_hand_thumb_rota_joint1" />
    <motor forcelimited="true" forcerange="-1.1 1.1" joint="right_hand_thumb_rota_joint2" name="right_hand_thumb_rota_joint2" />
    <motor forcelimited="true" forcerange="-1.1 1.1" joint="right_hand_index_rota_joint1" name="right_hand_index_rota_joint1" />
    <motor forcelimited="true" forcerange="-1.1 1.1" joint="right_hand_index_rota_joint2" name="right_hand_index_rota_joint2" />
    <motor forcelimited="true" forcerange="-1.1 1.1" joint="right_hand_mid_joint1" name="right_hand_mid_joint1" />
    <motor forcelimited="true" forcerange="-1.1 1.1" joint="right_hand_mid_joint2" name="right_hand_mid_joint2" />
    <motor forcelimited="true" forcerange="-1.1 1.1" joint="right_hand_ring_joint1" name="right_hand_ring_joint1" />
    <motor forcelimited="true" forcerange="-1.1 1.1" joint="right_hand_ring_joint2" name="right_hand_ring_joint2" />
    <motor forcelimited="true" forcerange="-1.1 1.1" joint="right_hand_pinky_joint1" name="right_hand_pinky_joint1" />
    <motor forcelimited="true" forcerange="-1.1 1.1" joint="right_hand_pinky_joint2" name="right_hand_pinky_joint2" />
    <motor forcelimited="true" forcerange="-50 50" joint="left_drv_hang_joint" name="left_drv_hang_joint" />
    <motor forcelimited="true" forcerange="-15 15" joint="left_drv_wheel_joint" name="left_drv_wheel_joint" />
    <motor forcelimited="true" forcerange="-50 50" joint="right_drv_hang_joint" name="right_drv_hang_joint" />
    <motor forcelimited="true" forcerange="-15 15" joint="right_drv_wheel_joint" name="right_drv_wheel_joint" />
  </actuator>  
  <contact>
    <exclude body1="left_elbow_yaw_link" body2="left_wrist_roll_link" />
    <exclude body1="right_elbow_yaw_link" body2="right_wrist_roll_link" />
    <exclude body1="waist_yaw_link" body2="neck_pitch_link" />
    <exclude body1="ankle_link" body2="base_link" />
    <exclude body1="base_link" body2="left_drv_hang_link" />
    <exclude body1="base_link" body2="right_drv_hang_link" />
    <exclude body1="base_link" body2="left_drv_wheel_link" />
    <exclude body1="base_link" body2="right_drv_wheel_link" />
  </contact>
</mujoco>
