<mujoco model="xh_tienkung1_1">
  <compiler angle="radian" meshdir="../../meshes/tienkung_1/" />
  <statistic center="-0.012496 0.000424702 0.622672" extent="1.93611" meansize="0.179951" />

  <visual>
    <scale jointwidth="0.1" framelength="0.3" framewidth="0.005" />
  </visual>
  <asset>
    <texture builtin="gradient" height="100" rgb1=".4 .5 .6" rgb2="0 0 0" type="skybox" width="100" />
    <texture builtin="checker" height="100" name="texplane" rgb1="1 1 1" rgb2=".8 .9 1" type="2d" width="100" />
    <material name="MatPlane" reflectance="0.5" texrepeat="1 1" texture="texplane" texuniform="true" />
    <material name="black" rgba="0.25 0.25 0.25 1" shininess="0.2" specular="0.05" />

    <mesh name="pelvis" file="pelvis.STL" />
    <mesh name="hip_roll_l_link" file="hip_roll_l_link.STL" />
    <mesh name="hip_yaw_l_link" file="hip_yaw_l_link.STL" />
    <mesh name="hip_pitch_l_link" file="hip_pitch_l_link.STL" />
    <mesh name="knee_pitch_l_link" file="knee_pitch_l_link.STL" />
    <mesh name="ankle_pitch_l_link" file="ankle_pitch_l_link.STL" />
    <mesh name="ankle_roll_l_link" file="ankle_roll_l_link.STL" />
    <mesh name="hip_roll_r_link" file="hip_roll_r_link.STL" />
    <mesh name="hip_yaw_r_link" file="hip_yaw_r_link.STL" />
    <mesh name="hip_pitch_r_link" file="hip_pitch_r_link.STL" />
    <mesh name="knee_pitch_r_link" file="knee_pitch_r_link.STL" />
    <mesh name="ankle_pitch_r_link" file="ankle_pitch_r_link.STL" />
    <mesh name="ankle_roll_r_link" file="ankle_roll_r_link.STL" />
    <mesh name="waist_link" file="waist_link.STL" />
    <mesh name="link0" file="link0.STL" />
    <mesh name="link1" file="link1.STL" />
    <mesh name="link2" file="link2.STL" />
    <mesh name="link3" file="link3.STL" />
    <mesh name="link4" file="link4.STL" />
    <mesh name="link5" file="link5.STL" />
    <mesh name="link6" file="link6.STL" />
    <mesh name="link7" file="link7.STL" />
    <mesh name="L_hand_base_link" file="L_hand_base_link.STL" />
    <mesh name="Link11_L" file="Link11_L.STL" />
    <mesh name="Link12_L" file="Link12_L.STL" />
    <mesh name="Link13_L" file="Link13_L.STL" />
    <mesh name="Link14_L" file="Link14_L.STL" />
    <mesh name="Link15_L" file="Link15_L.STL" />
    <mesh name="Link16_L" file="Link16_L.STL" />
    <mesh name="Link17_L" file="Link17_L.STL" />
    <mesh name="Link18_L" file="Link18_L.STL" />
    <mesh name="Link19_L" file="Link19_L.STL" />
    <mesh name="Link20_L" file="Link20_L.STL" />
    <mesh name="Link21_L" file="Link21_L.STL" />
    <mesh name="Link22_L" file="Link22_L.STL" />
    <mesh name="R_hand_base_link" file="R_hand_base_link.STL" />
    <mesh name="Link11_R" file="Link11_R.STL" />
    <mesh name="Link12_R" file="Link12_R.STL" />
    <mesh name="Link13_R" file="Link13_R.STL" />
    <mesh name="Link14_R" file="Link14_R.STL" />
    <mesh name="Link15_R" file="Link15_R.STL" />
    <mesh name="Link16_R" file="Link16_R.STL" />
    <mesh name="Link17_R" file="Link17_R.STL" />
    <mesh name="Link18_R" file="Link18_R.STL" />
    <mesh name="Link19_R" file="Link19_R.STL" />
    <mesh name="Link20_R" file="Link20_R.STL" />
    <mesh name="Link21_R" file="Link21_R.STL" />
    <mesh name="Link22_R" file="Link22_R.STL" />
  </asset>

  <worldbody>
    <geom name="floor" conaffinity="1" condim="3" contype="1" friction="1 .1 .1" group="2" material="MatPlane" pos="0 0 -0.84" size="500 500 0.125" type="plane" />
    <light castshadow="false" cutoff="100" diffuse="1 1 1" dir="-0 0 -1.3" directional="true" exponent="1" pos="0 0 1.3" specular=".1 .1 .1" />
    <body name="pelvis" pos="0 0 0">
      <joint name="floating_base_joint" type="free" />
      <geom name="pelvis_visual" type="mesh" contype="0" conaffinity="0" group="1" density="0" mesh="pelvis" material="black" />
      <geom name="pelvis_collision" type="mesh" mesh="pelvis" material="black" />
      <geom name="waist_visual" pos="-0.024 0 0.0062" type="mesh" contype="0" conaffinity="0" group="1" density="0" mesh="waist_link" material="black" />
      <geom name="waist_collision" pos="-0.024 0 0.0062" type="mesh" mesh="waist_link" material="black" />
      <geom name="link0_left_visual" pos="-0.024 0.15911 0.43202" quat="0.561136 -0.430264 0.430264 0.561135" type="mesh" contype="0" conaffinity="0" group="1" density="0" mesh="link0"
        material="black" />
      <geom name="link0_left_collision" pos="-0.024 0.15911 0.43202" quat="0.561136 -0.430264 0.430264 0.561135" type="mesh" mesh="link0" material="black" />
      <geom name="link0_right_visual" pos="-0.024 -0.15911 0.43202" quat="0.561136 0.430264 0.430264 -0.561135" type="mesh" contype="0" conaffinity="0" group="1" density="0" mesh="link0"
        material="black" />
      <geom name="link0_right_collision" pos="-0.024 -0.15911 0.43202" quat="0.561136 0.430264 0.430264 -0.561135" type="mesh" mesh="link0" material="black" />
      <body name="hip_roll_l_link" pos="0 0.13 -0.065923">
        <inertial pos="-0.00048 0.00336 -0.00372" quat="-0.170206 0.686316 -0.170206 0.686316" mass="1.12809" diaginertia="0.00113814 0.000871865 0.00058" />
        <joint name="hip_roll_l_joint" pos="0 0 0" axis="1 0 0" range="-0.97 0.97" actuatorfrcrange="-150 150" />
        <geom name="hip_roll_l_visual" type="mesh" contype="0" conaffinity="0" group="1" density="0" mesh="hip_roll_l_link" material="black" />
        <geom name="hip_roll_l_collision" type="mesh" mesh="hip_roll_l_link" material="black" />
        <body name="hip_yaw_l_link" pos="0 0 -0.116">
          <inertial pos="0.00104 0.00351 0.00968" quat="0.655486 -0.00856532 0.0207067 0.754874" mass="1.91605" diaginertia="0.00271913 0.00236314 0.00151773" />
          <joint name="hip_yaw_l_joint" pos="0 0 0" axis="0 0 1" range="-1.0472 1.0472" actuatorfrcrange="-90 90" />
          <geom name="hip_yaw_l_visual" type="mesh" contype="0" conaffinity="0" group="1" density="0" mesh="hip_yaw_l_link" material="black" />
          <geom name="hip_yaw_l_collision" type="mesh" mesh="hip_yaw_l_link" material="black" />
          <body name="hip_pitch_l_link">
            <inertial pos="0.00823 -0.00853 -0.13551" quat="0.891694 -0.0331991 0.0226408 0.450851" mass="3.37311" diaginertia="0.0231214 0.0223361 0.00626246" />
            <joint name="hip_pitch_l_joint" pos="0 0 0" axis="0 1 0" range="-1.57 0.5236" actuatorfrcrange="-150 150" />
            <geom name="hip_pitch_l_visual" type="mesh" contype="0" conaffinity="0" group="1" density="0" mesh="hip_pitch_l_link" material="black" />
            <geom name="hip_pitch_l_collision" type="mesh" mesh="hip_pitch_l_link" material="black" />
            <body name="knee_pitch_l_link" pos="0 0 -0.3">
              <inertial pos="0.00228 0.00293 -0.12066" quat="0.987279 0.0207788 -0.0159721 0.156825" mass="2.28832" diaginertia="0.0203626 0.0201507 0.000846692" />
              <joint name="knee_pitch_l_joint" pos="0 0 0" axis="0 1 0" range="0 2.443" actuatorfrcrange="-150 150" />
              <geom name="knee_pitch_l_visual" type="mesh" contype="0" conaffinity="0" group="1" density="0" mesh="knee_pitch_l_link" material="black" />
              <geom name="knee_pitch_l_collision" type="mesh" mesh="knee_pitch_l_link" material="black" />
              <body name="ankle_pitch_l_link" pos="0 0 -0.3">
                <inertial pos="0.00027 0 0" quat="0.5 0.5 -0.5 0.5" mass="0.15163" diaginertia="6e-05 3e-05 3e-05" />
                <joint name="ankle_pitch_l_joint" pos="0 0 0" axis="0 1 0" range="-1.22 0.5236" actuatorfrcrange="-60 60" />
                <geom name="ankle_pitch_l_visual" type="mesh" contype="0" conaffinity="0" group="1" density="0" mesh="ankle_pitch_l_link" material="black" />
                <geom name="ankle_pitch_l_collision" type="mesh" mesh="ankle_pitch_l_link" material="black" />
                <body name="ankle_roll_l_link">
                  <inertial pos="0.00229 0 -0.02723" quat="0 0.637136 0 0.770752" mass="0.74118" diaginertia="0.00262512 0.00233 0.000784878" />
                  <joint name="ankle_roll_l_joint" pos="0 0 0" axis="1 0 0" range="-0.4363 0.4363" actuatorfrcrange="-30 30" />
                  <geom name="ankle_roll_l_visual" type="mesh" contype="0" conaffinity="0" group="1" density="0" mesh="ankle_roll_l_link" material="black" />
<!--                  <geom name="ankle_roll_l_collision" type="mesh" mesh="ankle_roll_l_link" material="black" />-->
                </body>
              </body>
            </body>
          </body>
        </body>
      </body>

      <body name="hip_roll_r_link" pos="0 -0.13 -0.065923">
        <inertial pos="-0.00048 -0.00336 -0.00372" quat="0.170206 0.686316 0.170206 0.686316" mass="1.12809" diaginertia="0.00113814 0.000871865 0.00058" />
        <joint name="hip_roll_r_joint" pos="0 0 0" axis="1 0 0" range="-0.97 0.97" actuatorfrcrange="-150 150" />
        <geom name="hip_roll_r_visual" type="mesh" contype="0" conaffinity="0" group="1" density="0" mesh="hip_roll_r_link" material="black" />
        <geom name="hip_roll_r_collision" type="mesh" mesh="hip_roll_r_link" material="black" />
        <body name="hip_yaw_r_link" pos="0 0 -0.116">
          <inertial pos="0.00104 -0.00351 0.00968" quat="0.754874 0.0207067 -0.00856532 0.655486" mass="1.91605" diaginertia="0.00271913 0.00236314 0.00151773" />
          <joint name="hip_yaw_r_joint" pos="0 0 0" axis="0 0 1" range="-1.0472 1.0472" actuatorfrcrange="-90 90" />
          <geom name="hip_yaw_r_visual" type="mesh" contype="0" conaffinity="0" group="1" density="0" mesh="hip_yaw_r_link" material="black" />
          <geom name="hip_yaw_r_collision" type="mesh" mesh="hip_yaw_r_link" material="black" />
          <body name="hip_pitch_r_link">
            <inertial pos="0.00823 0.00853 -0.13551" quat="0.450851 0.0226408 -0.0331991 0.891694" mass="3.37311" diaginertia="0.0231214 0.0223361 0.00626246" />
            <joint name="hip_pitch_r_joint" pos="0 0 0" axis="0 1 0" range="-1.57 0.5236" actuatorfrcrange="-150 150" />
            <geom name="hip_pitch_r_visual" type="mesh" contype="0" conaffinity="0" group="1" density="0" mesh="hip_pitch_r_link" material="black" />
            <geom name="hip_pitch_r_collision" type="mesh" mesh="hip_pitch_r_link" material="black" />
            <body name="knee_pitch_r_link" pos="0 0 -0.3">
              <inertial pos="0.00228 -0.00293 -0.12066" quat="0.987279 -0.0207788 -0.0159721 -0.156825" mass="2.28832" diaginertia="0.0203626 0.0201507 0.000846692" />
              <joint name="knee_pitch_r_joint" pos="0 0 0" axis="0 1 0" range="0 2.443" actuatorfrcrange="-150 150" />
              <geom name="knee_pitch_r_visual" type="mesh" contype="0" conaffinity="0" group="1" density="0" mesh="knee_pitch_r_link" material="black" />
              <geom name="knee_pitch_r_collision" type="mesh" mesh="knee_pitch_r_link" material="black" />
              <body name="ankle_pitch_r_link" pos="0 0 -0.3">
                <inertial pos="0.00027 0 0" quat="0.5 0.5 -0.5 0.5" mass="0.15163" diaginertia="6e-05 3e-05 3e-05" />
                <joint name="ankle_pitch_r_joint" pos="0 0 0" axis="0 1 0" range="-1.22 0.5236" actuatorfrcrange="-60 60" />
                <geom name="ankle_pitch_r_visual" type="mesh" contype="0" conaffinity="0" group="1" density="0" mesh="ankle_pitch_r_link" material="black" />
                <geom name="ankle_pitch_r_collision" type="mesh" mesh="ankle_pitch_r_link" material="black" />
                <body name="ankle_roll_r_link">
                  <inertial pos="0.00229 0 -0.02723" quat="0 0.637136 0 0.770752" mass="0.74118" diaginertia="0.00262512 0.00233 0.000784878" />
                  <joint name="ankle_roll_r_joint" pos="0 0 0" axis="1 0 0" range="-0.4363 0.4363" actuatorfrcrange="-30 30" />
                  <geom name="ankle_roll_r_visual" type="mesh" contype="0" conaffinity="0" group="1" density="0" mesh="ankle_roll_r_link" material="black" />
<!--                  <geom name="ankle_roll_r_collision" type="mesh" mesh="ankle_roll_r_link" material="black" />-->
                </body>
              </body>
            </body>
          </body>
        </body>
      </body>
      <body name="shoulder_roll_l_link" pos="-0.024 0.233183 0.451923" quat="0.561136 -0.430264 0.430264 0.561135">
        <inertial pos="0 0.000725 -0.029524" quat="0.637041 0.77083 0 0" mass="0.222" diaginertia="0.000545 0.000513631 0.000270369" />
        <joint name="left_joint1" pos="0 0 0" axis="0 0 1" range="-3.14159 0.785398" actuatorfrcrange="-40 40" />
        <geom name="shoulder_l_visual" type="mesh" contype="0" conaffinity="0" group="1" density="0" mesh="link1" material="black" />
        <geom name="shoulder_l_collision" type="mesh" mesh="link1" material="black" />
        <body name="left_link2" quat="0.5 0.5 -0.5 0.5">
          <inertial pos="0 -0.000473 0.006864" quat="0.999978 -0.00657738 0 0" mass="1.226" diaginertia="0.001198 0.00118004 0.000951961" />
          <joint name="shoulder_roll_l_joint" pos="0 0 0" axis="0 0 1" range="-0.087 1.74533" actuatorfrcrange="-40 40" />
          <geom name="left_link2_visual" type="mesh" contype="0" conaffinity="0" group="1" density="0" mesh="link2" material="black" />
          <geom name="left_link2_collision" type="mesh" mesh="link2" material="black" />
          <body name="elbow_l_link" pos="0 -0.253 0" quat="0.707107 0.707107 0 0">
            <inertial pos="0.000247 0.003673 -0.081504" quat="0.999747 -0.0215591 0.000754078 0.00640175" mass="1.824" diaginertia="0.0142071 0.0139976 0.00129937" />
            <joint name="left_joint3" pos="0 0 0" axis="0 0 1" range="-2.26893 2.26893" actuatorfrcrange="-22 22" />
            <geom name="elbow_l_visual" type="mesh" contype="0" conaffinity="0" group="1" density="0" mesh="link3" material="black" />
            <geom name="elbow_l_collision" type="mesh" mesh="link3" material="black" />
            <body name="left_link4" quat="0.707107 -0.707107 0 0">
              <inertial pos="0.002765 -0.020714 0.006089" quat="0.997296 -0.0356336 -0.00751368 0.0638332" mass="0.123" diaginertia="0.000241537 0.000210924 0.000124539" />
              <joint name="elbow_l_joint" pos="0 0 0" axis="0 0 1" range="-2.26893 0.1" actuatorfrcrange="-22 22" />
              <geom name="left_link4_visual" type="mesh" contype="0" conaffinity="0" group="1" density="0" mesh="link4" material="black" />
              <geom name="left_link4_collision" type="mesh" mesh="link4" material="black" />
              <body name="left_link5" pos="0 -0.2355 0" quat="0.707107 0.707107 0 0">
                <inertial pos="0.000563 0.005092 -0.108798" quat="0.993172 -0.074755 0.0157112 0.088174" mass="1.01" diaginertia="0.00229232 0.00210921 0.000593467" />
                <joint name="left_joint5" pos="0 0 0" axis="0 0 1" range="-2.26893 2.26893" actuatorfrcrange="-8 8" />
                <geom name="left_link5_visual" type="mesh" contype="0" conaffinity="0" group="1" density="0"  mesh="link5" material="black" />
                <geom name="left_link5_collision" type="mesh"  mesh="link5" material="black" />
                <body name="left_link6" quat="0.5 -0.5 -0.5 -0.5">
                  <inertial pos="0 -0.005048 0.000947" quat="0.609644 0.792675 0 0" mass="0.487" diaginertia="0.00027 0.000253187 0.000204813" />
                  <joint name="left_joint6" pos="0 0 0" axis="0 0 1" range="-1.309 1.309" actuatorfrcrange="-8 8" />
                  <geom name="left_link6_visual" type="mesh" contype="0" conaffinity="0" group="1" density="0"  mesh="link6" material="black" />
                  <geom name="left_link6_collision" type="mesh"  mesh="link6" material="black" />
                  <body name="left_link7" quat="0.5 -0.5 0.5 0.5">
                    <inertial pos="0.000880047 -0.10785 -0.0203838" quat="0.69715 0.716852 0.00650575 0.00789516" mass="0.36943" diaginertia="0.00145253 0.00135498 0.000265192" />
                    <joint name="left_joint7" pos="0 0 0" axis="0 0 1" range="-1.309 1.309" actuatorfrcrange="-8 8" />
                    <geom name="left_link7_visual" type="mesh" contype="0" conaffinity="0" group="1" density="0"  mesh="link7" material="black" />
                    <geom name="left_link7_collision" type="mesh"  mesh="link7" material="black" />
                    <geom name="L_hand_base_visual" pos="0 -0.1115 0" quat="0.707107 0 -0.707107 0" type="mesh" contype="0" conaffinity="0" group="1" density="0" mesh="L_hand_base_link" material="black" />
                    <geom name="L_hand_base_collision" pos="0 -0.1115 0" quat="0.707107 0 -0.707107 0" type="mesh" mesh="L_hand_base_link" material="black" />
                    <body name="L_thumb_proximal_base" pos="-0.02045 -0.1806 -0.01696" quat="-1.29867e-06 -1.29868e-06 -0.707105 0.707108">
                      <inertial pos="0.0048817 0.00038782 -0.00722" quat="0.445981 0.352284 0.495833 0.656617" mass="0.0018869" diaginertia="8.66031e-08 6.87331e-08 4.94199e-08" />
                      <joint name="L_thumb_proximal_yaw_joint" pos="0 0 0" axis="0 0 1" range="-0.1 1.3" actuatorfrcrange="-1 1" />
                      <geom name="L_thumb_proximal_base_visual" type="mesh" contype="0" conaffinity="0" group="1" density="0" mesh="Link11_L" material="black" />
                      <geom name="L_thumb_proximal_base_collision" type="mesh" mesh="Link11_L" material="black" />
                      <body name="L_thumb_proximal" pos="0.0099867 0.0098242 -0.0089" quat="0.704571 -0.704573 -0.0598169 0.0598167">
                        <inertial pos="0.021936 -0.01279 -0.0080386" quat="0.25452 0.660687 -0.251949 0.659723" mass="0.0066101" diaginertia="2.78701e-06 2.44024e-06 8.6466e-07" />
                        <joint name="L_thumb_proximal_pitch_joint" pos="0 0 0" axis="0 0 -1" range="0 0.5" actuatorfrcrange="-1 1" />
                        <geom name="L_thumb_proximal_visual" type="mesh" contype="0" conaffinity="0" group="1" density="0" mesh="Link12_L" />
                        <geom name="L_thumb_proximal_collision" type="mesh" mesh="Link12_L" />
                        <body name="L_thumb_intermediate" pos="0.04407 -0.034553 -0.0008">
                          <inertial pos="0.0095531 0.0016282 -0.0072002" quat="0.30738 0.636732 -0.307526 0.636803" mass="0.0037844" diaginertia="4.6532e-07 4.48114e-07 2.45646e-07" />
                          <joint name="L_thumb_intermediate_joint" pos="0 0 0" axis="0 0 -1" range="0 0.8" actuatorfrcrange="-1 1" />
                          <geom name="L_thumb_intermediate_visual" type="mesh" contype="0" conaffinity="0" group="1" density="0" mesh="Link13_L" />
                          <geom name="L_thumb_intermediate_collision" type="mesh" mesh="Link13_L" />
                          <body name="L_thumb_distal" pos="0.020248 -0.010156 -0.0012">
                            <inertial pos="0.0092888 -0.004953 -0.0060033" quat="0.266264 0.65596 -0.262836 0.655544" mass="0.003344" diaginertia="2.0026e-07 1.95246e-07 8.1594e-08" />
                            <joint name="L_thumb_distal_joint" pos="0 0 0" axis="0 0 -1" range="0 1.2" actuatorfrcrange="-1 1" />
                            <geom name="L_thumb_distal_visual" type="mesh" contype="0" conaffinity="0" group="1" density="0" mesh="Link14_L" />
                            <geom name="L_thumb_distal_collision" type="mesh" mesh="Link14_L" />
                          </body>
                        </body>
                      </body>
                    </body>
                    <body name="L_index_proximal" pos="-0.032268 -0.24803 0.00028533" quat="0.706999 -0.0123409 -0.706999 -0.0123409">
                      <inertial pos="0.0012971 -0.011934 -0.0059998" quat="0.489677 0.510115 -0.489692 0.510099" mass="0.0042405" diaginertia="6.9402e-07 6.62904e-07 2.10916e-07" />
                      <joint name="L_index_proximal_joint" pos="0 0 0" axis="0 0 -1" range="0 1.7" actuatorfrcrange="-1 1" />
                      <geom name="L_index_proximal_visual" type="mesh" contype="0" conaffinity="0" group="1" density="0" mesh="Link15_L" />
                      <geom name="L_index_proximal_collision" type="mesh" mesh="Link15_L" />
                      <body name="L_index_intermediate" pos="-0.0024229 -0.032041 -0.001">
                        <inertial pos="0.0021753 -0.019567 -0.005" quat="0.528694 0.469555 -0.528694 0.469555" mass="0.0045682" diaginertia="7.8176e-07 7.72427e-07 8.47209e-08" />
                        <joint name="L_index_intermediate_joint" pos="0 0 0" axis="0 0 -1" range="0 1.7" actuatorfrcrange="-1 1" />
                        <geom name="L_index_intermediate_visual" type="mesh" contype="0" conaffinity="0" group="1" density="0" mesh="Link16_L" />
                        <geom name="L_index_intermediate_collision" type="mesh" mesh="Link16_L" />
                      </body>
                    </body>
                    <body name="L_middle_proximal" pos="-0.01295 -0.2486 0.00028533" quat="0.707107 0 -0.707107 0">
                      <inertial pos="0.0012971 -0.011934 -0.0059999" quat="0.489677 0.510115 -0.489692 0.510099" mass="0.0042405" diaginertia="6.9402e-07 6.62904e-07 2.10916e-07" />
                      <joint name="L_middle_proximal_joint" pos="0 0 0" axis="0 0 -1" range="0 1.7" actuatorfrcrange="-1 1" />
                      <geom name="L_middle_proximal_visual" type="mesh" contype="0" conaffinity="0" group="1" density="0" mesh="Link17_L" />
                      <geom name="L_middle_proximal_collision" type="mesh" mesh="Link17_L" />
                      <body name="L_middle_intermediate" pos="-0.0024229 -0.032041 -0.001">
                        <inertial pos="0.001921 -0.020796 -0.0049999" quat="0.531603 0.466115 -0.531728 0.466262" mass="0.0050397" diaginertia="9.8385e-07 9.73288e-07 9.14016e-08" />
                        <joint name="L_middle_intermediate_joint" pos="0 0 0" axis="0 0 -1" range="0 1.7" actuatorfrcrange="-1 1" />
                        <geom name="L_middle_intermediate_visual" type="mesh" contype="0" conaffinity="0" group="1" density="0" mesh="Link18_L" />
                        <geom name="L_middle_intermediate_collision" type="mesh" mesh="Link18_L" />
                      </body>
                    </body>
                    <body name="L_ring_proximal" pos="0.0062872 -0.24841 0.00028533" quat="0.706864 0.0185099 -0.706864 0.0185099">
                      <inertial pos="0.0012971 -0.011934 -0.0059999" quat="0.489677 0.510114 -0.489692 0.510099" mass="0.0042405" diaginertia="6.9402e-07 6.62904e-07 2.10916e-07" />
                      <joint name="L_ring_proximal_joint" pos="0 0 0" axis="0 0 -1" range="0 1.7" actuatorfrcrange="-1 1" />
                      <geom name="L_ring_proximal_visual" type="mesh" contype="0" conaffinity="0" group="1" density="0" mesh="Link19_L" />
                      <geom name="L_ring_proximal_collision" type="mesh" mesh="Link19_L" />
                      <body name="L_ring_intermediate" pos="-0.0024229 -0.032041 -0.001">
                        <inertial pos="0.0021753 -0.019567 -0.005" quat="0.528694 0.469556 -0.528694 0.469556" mass="0.0045682" diaginertia="7.8176e-07 7.72437e-07 8.47208e-08" />
                        <joint name="L_ring_intermediate_joint" pos="0 0 0" axis="0 0 -1" range="0 1.7" actuatorfrcrange="-1 1" />
                        <geom name="L_ring_intermediate_visual" type="mesh" contype="0" conaffinity="0" group="1" density="0" mesh="Link20_L" />
                        <geom name="L_ring_intermediate_collision" type="mesh" mesh="Link20_L" />
                      </body>
                    </body>
                    <body name="L_pinky_proximal" pos="0.025488 -0.24721 0.00028533" quat="0.706138 0.0370072 -0.706138 0.0370072">
                      <inertial pos="0.0012971 -0.011934 -0.0059999" quat="0.489677 0.510114 -0.489692 0.510099" mass="0.0042405" diaginertia="6.9402e-07 6.62904e-07 2.10916e-07" />
                      <joint name="L_pinky_proximal_joint" pos="0 0 0" axis="0 0 -1" range="0 1.7" actuatorfrcrange="-1 1" />
                      <geom name="L_pinky_proximal_visual" type="mesh" contype="0" conaffinity="0" group="1" density="0" mesh="Link21_L" />
                      <geom name="L_pinky_proximal_collision" type="mesh" mesh="Link21_L" />
                      <body name="L_pinky_intermediate" pos="-0.0024229 -0.032041 -0.001">
                        <inertial pos="0.0024788 -0.016208 -0.0050001" quat="0.526797 0.471683 -0.526793 0.471687" mass="0.0036036" diaginertia="4.4881e-07 4.43809e-07 6.5736e-08" />
                        <joint name="L_pinky_intermediate_joint" pos="0 0 0" axis="0 0 -1" range="0 1.7" actuatorfrcrange="-1 1" />
                        <geom name="L_pinky_intermediate_visual" type="mesh" contype="0" conaffinity="0" group="1" density="0" mesh="Link22_L" />
                        <geom name="L_pinky_intermediate_collision" type="mesh" mesh="Link22_L" />
                      </body>
                    </body>
                  </body>
                </body>
              </body>
            </body>
          </body>
        </body>
      </body>
      <body name="shoulder_roll_r_link" pos="-0.024 -0.233183 0.451923" quat="0.561136 0.430264 0.430264 -0.561135">
        <inertial pos="0 -0.000725 -0.029524" quat="0.77083 0.637041 0 0" mass="0.222" diaginertia="0.000545 0.000513631 0.000270369" />
        <joint name="right_joint1" pos="0 0 0" axis="0 0 1" range="-0.785398 3.14159" actuatorfrcrange="-40 40" />
        <geom name="shoulder_r_visual" type="mesh" contype="0" conaffinity="0" group="1" density="0" mesh="link1" material="black" />
        <geom name="shoulder_r_collision" type="mesh"  mesh="link1" material="black" />
        <body name="right_link2" quat="0.5 -0.5 -0.5 -0.5">
          <inertial pos="0 0.000473 0.006864" quat="0.999978 0.00657738 0 0" mass="1.226" diaginertia="0.001198 0.00118004 0.000951961" />
          <joint name="shoulder_roll_r_joint" pos="0 0 0" axis="0 0 1" range="-1.74533 0.087" actuatorfrcrange="-40 40" />
          <geom name="right_link2_visual" quat="2.67949e-08 0 0 1" type="mesh" contype="0" conaffinity="0" group="1" density="0"  mesh="link2" material="black" />
          <geom name="right_link2_collision" quat="2.67949e-08 0 0 1" type="mesh"  mesh="link2" material="black" />
          <body name="elbow_r_link" pos="0 0.253 0" quat="0.707107 -0.707107 0 0">
            <inertial pos="0.000247 -0.003673 -0.081504" quat="0.999747 0.0215591 0.000754078 -0.00640175" mass="1.824" diaginertia="0.0142071 0.0139976 0.00129937" />
            <joint name="right_joint3" pos="0 0 0" axis="0 0 1" range="-2.26893 2.26893" actuatorfrcrange="-22 22" />
            <geom name="elbow_r_visual" type="mesh" contype="0" conaffinity="0" group="1" density="0"  mesh="link3" material="black" />
            <geom name="elbow_r_collision" type="mesh"  mesh="link3" material="black" />
            <body name="right_link4" quat="0.707107 0.707107 0 0">
              <inertial pos="0.002765 0.020714 0.006089" quat="0.997296 0.0356336 -0.00751368 -0.0638332" mass="0.123" diaginertia="0.000241537 0.000210924 0.000124539" />
              <joint name="elbow_r_joint" pos="0 0 0" axis="0 0 1" range="-0.1 2.26893" actuatorfrcrange="-22 22" />
              <geom name="right_link4_visual" quat="2.67949e-08 0 0 1" type="mesh" contype="0" conaffinity="0" group="1" density="0"  mesh="link4" material="black" />
              <geom name="right_link4_collision" quat="2.67949e-08 0 0 1" type="mesh"  mesh="link4" material="black" />
              <body name="right_link5" pos="0 0.2355 0" quat="0.707107 -0.707107 0 0">
                <inertial pos="0.000563 -0.005092 -0.108798" quat="0.995124 0.0767573 0.00673248 0.0615803" mass="1.01" diaginertia="0.0022895 0.00211237 0.000593133" />
                <joint name="right_joint5" pos="0 0 0" axis="0 0 1" range="-2.26893 2.26893" actuatorfrcrange="-8 8" />
                <geom name="right_link5_visual" type="mesh" contype="0" conaffinity="0" group="1" density="0"  mesh="link5" material="black" />
                <geom name="right_link5_collision" type="mesh"  mesh="link5" material="black" />
                <body name="right_link6" quat="0.5 0.5 -0.5 0.5">
                  <inertial pos="0 0.005048 0.000947" quat="0.792675 0.609644 0 0" mass="0.487" diaginertia="0.00027 0.000253187 0.000204813" />
                  <joint name="right_joint6" pos="0 0 0" axis="0 0 1" range="-1.309 1.309" actuatorfrcrange="-8 8" />
                  <geom name="right_link6_visual" quat="2.67949e-08 1 0 0" type="mesh" contype="0" conaffinity="0" group="1" density="0"  mesh="link6" material="black" />
                  <geom name="right_link6_collision" quat="2.67949e-08 1 0 0" type="mesh"  mesh="link6" material="black" />
                  <body name="right_link7" quat="0.5 0.5 -0.5 0.5">
                    <inertial pos="0.000910985 -0.107947 0.000854094" quat="0.832683 0.552109 -0.0152628 0.0397589" mass="0.36943" diaginertia="0.00160195 0.00156502 0.000204173" />
                    <joint name="right_joint7" pos="0 0 0" axis="0 0 1" range="-1.309 1.309" actuatorfrcrange="-8 8" />
                    <geom name="right_link7_visual" type="mesh" contype="0" conaffinity="0" group="1" density="0"  mesh="link7" material="black" />
                    <geom name="right_link7_collision" type="mesh"  mesh="link7" material="black" />
                    <geom name="R_hand_base_visual" pos="0 -0.1115 0" quat="0.707107 0 -0.707107 0" type="mesh" contype="0" conaffinity="0" group="1" density="0" mesh="R_hand_base_link" material="black" />
                    <geom name="R_hand_base_collision" pos="0 -0.1115 0" quat="0.707107 0 -0.707107 0" type="mesh" mesh="R_hand_base_link" material="black" />
                    <body name="R_thumb_proximal_base" pos="0.02045 -0.1806 -0.01696" quat="-1.29867e-06 -1.29868e-06 -0.707105 0.707108">
                      <inertial pos="-0.0048064 0.0009382 -0.00757" quat="0.515015 0.680854 0.408023 0.323596" mass="0.0018869" diaginertia="8.66026e-08 6.8732e-08 4.94194e-08" />
                      <joint name="R_thumb_proximal_yaw_joint" pos="0 0 0" axis="0 0 -1" range="-0.1 1.3" actuatorfrcrange="-1 1" />
                      <geom name="R_thumb_proximal_base_visual" type="mesh" contype="0" conaffinity="0" group="1" density="0" mesh="Link11_R" />
                      <geom name="R_thumb_proximal_base_collision" type="mesh" mesh="Link11_R" />
                      <body name="R_thumb_proximal" pos="-0.0088099 0.010892 -0.00925" quat="0.0996843 0.0996847 0.700046 0.700044">
                        <inertial pos="0.021932 0.012785 -0.0080386" quat="-0.254474 0.660716 0.251893 0.659733" mass="0.0066075" diaginertia="2.78601e-06 2.43933e-06 8.64566e-07" />
                        <joint name="R_thumb_proximal_pitch_joint" pos="0 0 0" axis="0 0 1" range="0 0.5" actuatorfrcrange="-1 1" />
                        <geom name="R_thumb_proximal_visual" type="mesh" contype="0" conaffinity="0" group="1" density="0" mesh="Link12_R" />
                        <geom name="R_thumb_proximal_collision" type="mesh" mesh="Link12_R" />
                        <body name="R_thumb_intermediate" pos="0.04407 0.034553 -0.0008">
                          <inertial pos="0.0095544 -0.0016282 -0.0071997" quat="0.636718 0.307389 -0.636802 0.307548" mass="0.0037847" diaginertia="4.6531e-07 4.48089e-07 2.45661e-07" />
                          <joint name="R_thumb_intermediate_joint" pos="0 0 0" axis="0 0 1" range="0 0.8" actuatorfrcrange="-1 1" />
                          <geom name="R_thumb_intermediate_visual" type="mesh" contype="0" conaffinity="0" group="1" density="0" mesh="Link13_R" />
                          <geom name="R_thumb_intermediate_collision" type="mesh" mesh="Link13_R" />
                          <body name="R_thumb_distal" pos="0.020248 0.010156 -0.0012">
                            <inertial pos="0.0092888 0.0049529 -0.0060033" quat="-0.266294 0.655967 0.262806 0.655537" mass="0.0033441" diaginertia="2.0026e-07 1.95247e-07 8.1593e-08" />
                            <joint name="R_thumb_distal_joint" pos="0 0 0" axis="0 0 1" range="0 1.2" actuatorfrcrange="-1 1" />
                            <geom name="R_thumb_distal_visual" type="mesh" contype="0" conaffinity="0" group="1" density="0" mesh="Link14_R" />
                            <geom name="R_thumb_distal_collision" type="mesh" mesh="Link14_R" />
                          </body>
                        </body>
                      </body>
                    </body>
                    <body name="R_index_proximal" pos="0.032268 -0.24803 0.00028533" quat="0.0123358 -0.706999 -0.0123358 -0.706999">
                      <inertial pos="0.0012259 0.011942 -0.0060001" quat="0.50867 0.49121 -0.508643 0.491172" mass="0.0042403" diaginertia="6.9398e-07 6.62871e-07 2.10909e-07" />
                      <joint name="R_index_proximal_joint" pos="0 0 0" axis="0 0 1" range="0 1.7" actuatorfrcrange="-1 1" />
                      <geom name="R_index_proximal_visual" type="mesh" contype="0" conaffinity="0" group="1" density="0" mesh="Link15_R" />
                      <geom name="R_index_proximal_collision" type="mesh" mesh="Link15_R" />
                      <body name="R_index_intermediate" pos="-0.0026138 0.032026 -0.001">
                        <inertial pos="0.0019697 0.019589 -0.005" quat="0.466773 0.531152 -0.466773 0.531153" mass="0.0045683" diaginertia="7.8179e-07 7.72465e-07 8.47212e-08" />
                        <joint name="R_index_intermediate_joint" pos="0 0 0" axis="0 0 1" range="0 1.7" actuatorfrcrange="-1 1" />
                        <geom name="R_index_intermediate_visual" type="mesh" contype="0" conaffinity="0" group="1" density="0" mesh="Link16_R" />
                        <geom name="R_index_intermediate_collision" type="mesh" mesh="Link16_R" />
                      </body>
                    </body>
                    <body name="R_middle_proximal" pos="0.01295 -0.2486 0.00028533" quat="-2.59735e-06 -0.707107 2.59735e-06 -0.707107">
                      <inertial pos="0.001297 0.011934 -0.0060001" quat="0.510131 0.489693 -0.510105 0.489653" mass="0.0042403" diaginertia="6.9397e-07 6.62865e-07 2.10915e-07" />
                      <joint name="R_middle_proximal_joint" pos="0 0 0" axis="0 0 1" range="0 1.7" actuatorfrcrange="-1 1" />
                      <geom name="R_middle_proximal_visual" type="mesh" contype="0" conaffinity="0" group="1" density="0" mesh="Link17_R" />
                      <geom name="R_middle_proximal_collision" type="mesh" mesh="Link17_R" />
                      <body name="R_middle_intermediate" pos="-0.0024229 0.032041 -0.001">
                        <inertial pos="0.001921 0.020796 -0.005" quat="0.466148 0.531627 -0.466229 0.531705" mass="0.0050396" diaginertia="9.8384e-07 9.73279e-07 9.14014e-08" />
                        <joint name="R_middle_intermediate_joint" pos="0 0 0" axis="0 0 1" range="0 1.7" actuatorfrcrange="-1 1" />
                        <geom name="R_middle_intermediate_visual" type="mesh" contype="0" conaffinity="0" group="1" density="0" mesh="Link18_R" />
                        <geom name="R_middle_intermediate_collision" type="mesh" mesh="Link18_R" />
                      </body>
                    </body>
                    <body name="R_ring_proximal" pos="-0.0062872 -0.24841 0.00028533" quat="0.0185215 0.706864 -0.0185215 0.706864">
                      <inertial pos="0.001297 0.011934 -0.0060002" quat="0.510129 0.489691 -0.510107 0.489654" mass="0.0042403" diaginertia="6.9397e-07 6.62865e-07 2.10915e-07" />
                      <joint name="R_ring_proximal_joint" pos="0 0 0" axis="0 0 1" range="0 1.7" actuatorfrcrange="-1 1" />
                      <geom name="R_ring_proximal_visual" type="mesh" contype="0" conaffinity="0" group="1" density="0" mesh="Link19_R" />
                      <geom name="R_ring_proximal_collision" type="mesh" mesh="Link19_R" />
                      <body name="R_ring_intermediate" pos="-0.0024229 0.032041 -0.001">
                        <inertial pos="0.0021753 0.019567 -0.005" quat="0.469554 0.528695 -0.469554 0.528695" mass="0.0045683" diaginertia="7.8177e-07 7.72448e-07 8.4722e-08" />
                        <joint name="R_ring_intermediate_joint" pos="0 0 0" axis="0 0 1" range="0 1.7" actuatorfrcrange="-1 1" />
                        <geom name="R_ring_intermediate_visual" type="mesh" contype="0" conaffinity="0" group="1" density="0" mesh="Link20_R" />
                        <geom name="R_ring_intermediate_collision" type="mesh" mesh="Link20_R" />
                      </body>
                    </body>
                    <body name="R_pinky_proximal" pos="-0.025488 -0.24721 0.00028533" quat="0.0369975 0.706138 -0.0369975 0.706138">
                      <inertial pos="0.001297 0.011934 -0.0060001" quat="0.51013 0.489693 -0.510106 0.489653" mass="0.0042403" diaginertia="6.9397e-07 6.62865e-07 2.10915e-07" />
                      <joint name="R_pinky_proximal_joint" pos="0 0 0" axis="0 0 1" range="0 1.7" actuatorfrcrange="-1 1" />
                      <geom name="R_pinky_proximal_visual" type="mesh" contype="0" conaffinity="0" group="1" density="0" mesh="Link21_R" />
                      <geom name="R_pinky_proximal_collision" type="mesh" mesh="Link21_R" />
                      <body name="R_pinky_intermediate" pos="-0.0024229 0.032041 -0.001">
                        <inertial pos="0.0024748 0.016203 -0.0050031" quat="0.47398 0.528862 -0.469291 0.524799" mass="0.0035996" diaginertia="4.4867e-07 4.43723e-07 6.56538e-08" />
                        <joint name="R_pinky_intermediate_joint" pos="0 0 0" axis="0 0 1" range="0 1.7" actuatorfrcrange="-1 1" />
                        <geom name="R_pinky_intermediate_visual" type="mesh" contype="0" conaffinity="0" group="1" density="0" mesh="Link22_R" />
                        <geom name="R_pinky_intermediate_collision" type="mesh" mesh="Link22_R" />
                      </body>
                    </body>
                  </body>
                </body>
              </body>
            </body>
          </body>
        </body>
      </body>
    </body>
  </worldbody>
  <actuator>
    <motor name="hip_roll_l_joint" joint="hip_roll_l_joint" gear="1" />
    <motor name="hip_yaw_l_joint" joint="hip_yaw_l_joint" gear="1" />
    <motor name="hip_pitch_l_joint" joint="hip_pitch_l_joint" gear="1" />
    <motor name="knee_pitch_l_joint" joint="knee_pitch_l_joint" gear="1" />
    <motor name="ankle_pitch_l_joint" joint="ankle_pitch_l_joint" gear="1" />
    <motor name="ankle_roll_l_joint" joint="ankle_roll_l_joint" gear="1" />
    <motor name="hip_roll_r_joint" joint="hip_roll_r_joint" gear="1" />
    <motor name="hip_yaw_r_joint" joint="hip_yaw_r_joint" gear="1" />
    <motor name="hip_pitch_r_joint" joint="hip_pitch_r_joint" gear="1" />
    <motor name="knee_pitch_r_joint" joint="knee_pitch_r_joint" gear="1" />
    <motor name="ankle_pitch_r_joint" joint="ankle_pitch_r_joint" gear="1" />
    <motor name="ankle_roll_r_joint" joint="ankle_roll_r_joint" gear="1" />
    <motor name="left_joint1" joint="left_joint1" gear="1" />
    <motor name="shoulder_roll_l_joint" joint="shoulder_roll_l_joint" gear="1" />
    <motor name="left_joint3" joint="left_joint3" gear="1" />
    <motor name="right_joint1" joint="right_joint1" gear="1" />
    <motor name="shoulder_roll_r_joint" joint="shoulder_roll_r_joint" gear="1" />
    <motor name="right_joint3" joint="right_joint3" gear="1" />
    <motor name="elbow_l_joint" joint="elbow_l_joint" gear="1" />
    <motor name="elbow_r_joint" joint="elbow_r_joint" gear="1" />
    <motor name="left_joint5" joint="left_joint5" gear="1" />
    <motor name="left_joint6" joint="left_joint6" gear="1" />
    <motor name="left_joint7" joint="left_joint7" gear="1" />
    <motor name="right_joint5" joint="right_joint5" gear="1" />
    <motor name="right_joint6" joint="right_joint6" gear="1" />
    <motor name="right_joint7" joint="right_joint7" gear="1" />
    <motor name="L_thumb_proximal_yaw_joint" joint="L_thumb_proximal_yaw_joint" gear="1" />
    <motor name="L_thumb_proximal_pitch_joint" joint="L_thumb_proximal_pitch_joint" gear="1" />
    <motor name="R_thumb_proximal_yaw_joint" joint="R_thumb_proximal_yaw_joint" gear="1" />
    <motor name="R_thumb_proximal_pitch_joint" joint="R_thumb_proximal_pitch_joint" gear="1" />
    <motor name="R_index_proximal_joint" joint="R_index_proximal_joint" gear="1" />
    <motor name="R_index_intermediate_joint" joint="R_index_intermediate_joint" gear="1" />
    <motor name="R_middle_proximal_joint" joint="R_middle_proximal_joint" gear="1" />
    <motor name="R_middle_intermediate_joint" joint="R_middle_intermediate_joint" gear="1" />
    <motor name="R_ring_proximal_joint" joint="R_ring_proximal_joint" gear="1" />
    <motor name="R_ring_intermediate_joint" joint="R_ring_intermediate_joint" gear="1" />
    <motor name="R_pinky_proximal_joint" joint="R_pinky_proximal_joint" gear="1" />
    <motor name="R_pinky_intermediate_joint" joint="R_pinky_intermediate_joint" gear="1" />
    <motor name="L_thumb_intermediate_joint" joint="L_thumb_intermediate_joint" gear="1" />
    <motor name="L_thumb_distal_joint" joint="L_thumb_distal_joint" gear="1" />
    <motor name="L_index_proximal_joint" joint="L_index_proximal_joint" gear="1" />
    <motor name="L_index_intermediate_joint" joint="L_index_intermediate_joint" gear="1" />
    <motor name="L_middle_proximal_joint" joint="L_middle_proximal_joint" gear="1" />
    <motor name="L_middle_intermediate_joint" joint="L_middle_intermediate_joint" gear="1" />
    <motor name="L_ring_proximal_joint" joint="L_ring_proximal_joint" gear="1" />
    <motor name="L_ring_intermediate_joint" joint="L_ring_intermediate_joint" gear="1" />
    <motor name="L_pinky_proximal_joint" joint="L_pinky_proximal_joint" gear="1" />
    <motor name="L_pinky_intermediate_joint" joint="L_pinky_intermediate_joint" gear="1" />
    <motor name="R_thumb_intermediate_joint" joint="R_thumb_intermediate_joint" gear="1" />
    <motor name="R_thumb_distal_joint" joint="R_thumb_distal_joint" gear="1" />
  </actuator>
  <contact>
    <exclude body1="pelvis" body2="hip_roll_l_link" />
    <exclude body1="pelvis" body2="hip_roll_r_link" />
    <exclude body1="pelvis" body2="hip_yaw_l_link" />
    <exclude body1="pelvis" body2="hip_yaw_r_link" />
    <exclude body1="pelvis" body2="shoulder_roll_l_link" />
    <exclude body1="pelvis" body2="shoulder_roll_r_link" />
    <exclude body1="hip_roll_l_link" body2="hip_yaw_l_link" />
    <exclude body1="hip_roll_r_link" body2="hip_yaw_r_link" />
    <exclude body1="hip_roll_l_link" body2="hip_pitch_l_link" />
    <exclude body1="hip_roll_r_link" body2="hip_pitch_r_link" />
    <exclude body1="hip_yaw_l_link" body2="hip_pitch_l_link" />
    <exclude body1="hip_yaw_r_link" body2="hip_pitch_r_link" />
    <exclude body1="hip_pitch_l_link" body2="knee_pitch_l_link" />
    <exclude body1="hip_pitch_r_link" body2="knee_pitch_r_link" />
    <exclude body1="knee_pitch_l_link" body2="ankle_pitch_l_link" />
    <exclude body1="knee_pitch_r_link" body2="ankle_pitch_r_link" />
    <exclude body1="knee_pitch_l_link" body2="ankle_roll_l_link" />
    <exclude body1="knee_pitch_r_link" body2="ankle_roll_r_link" />
    <exclude body1="ankle_pitch_l_link" body2="ankle_roll_l_link" />
    <exclude body1="ankle_pitch_r_link" body2="ankle_roll_r_link" />
    <exclude body1="left_link4" body2="left_link5" />
    <exclude body1="right_link4" body2="right_link5" />
    <exclude body1="left_link5" body2="left_link7" />
    <exclude body1="right_link5" body2="right_link7" />
    <exclude body1="left_link7" body2="L_thumb_proximal_base" />
    <exclude body1="L_thumb_proximal_base" body2="L_thumb_proximal" />
    <exclude body1="L_thumb_proximal_base" body2="L_thumb_proximal" />
    <exclude body1="R_thumb_proximal_base" body2="R_thumb_proximal" />
  </contact>
</mujoco>